Workbook
Name Lst_Categoria: 'CATEGORIAS'!$C$5:$C$1004
Name Lst_Cuenta: 'CUENTAS'!$B$5:$B$504
Name Lst_EstadoDocumento: "Validado,Pendiente,Error,Revision Manual,Duplicado"
Name Lst_EstadoMovimiento: "Pendiente,Pagado,Anulado"
Name Lst_EstadoPagoCobro: "Pendiente,Aplicado,Anulado"
Name Lst_MedioPago: MEDIOS_PAGO!$B$5:$B$1004
Name Lst_MetodoExtraccion: "XML,PDF,OCR,Manual,IA"
Name Lst_TerceroNombre: TERCEROS!$C$5:$C$2004
Name Lst_TipoArchivo: "PDF,JPG,PNG,XML,CSV,Otro"
Name Lst_TipoDocumentoNombre: TIPOS_DOCUMENTOS!$B$5:$B$1004
Name Lst_TipoMovimiento: "Ingreso,Gasto,Compra,Venta,Otro"
Name Lst_TipoTercero: "Cliente,Proveedor,Empleado,Socio,Entidad publica,Otro"

Sheet INICIO
A1: SISTEMA FINANCIERO · DEMO — DATOS FICTICIOS
A2: LIBRO DE SIMULACIÓN. No usar para registrar operaciones reales ni como liquidación tributaria.
A4: TAREAS FRECUENTES
A6: 1. CONFIGURAR EMPRESA | F6: 2. REGISTRAR MOVIMIENTO
A7: Actualice datos, moneda y parámetros. | F7: Capture ingreso, gasto, compra o venta.
A10: 3. ASISTENTE LOCAL | F10: 4. REVISAR DOCUMENTOS
A11: Reciba una sugerencia y revísela. | F11: Consulte soportes y complete datos.
A14: 5. VER INDICADORES | F14: 6. ABRIR REPORTES
A15: Filtre ingresos, gastos y pendientes. | F15: Consulte periodos mensual y anual.
A18: PRIMEROS PASOS
A19: 1. Configure empresa, categorías, cuentas y terceros.
A20: 2. Registre una operación o use el asistente para clasificar el concepto.
A21: 3. Revise los indicadores y conserve el soporte relacionado.
A23: El libro XLSX permite captura, fórmulas y sugerencias locales. La importación de archivos, lectura XML y altas automáticas requieren la copia XLSM con los módulos VBA instalados.
A26: Ver todos los módulos | F26: Editar reglas del asistente

Sheet DASHBOARD
A1: DASHBOARD
A2: Indicadores financieros - se actualiza automaticamente desde MOVIMIENTOS y DOCUMENTOS
A4: FILTROS
A5: Anio (vacio = todos) | B5: 2026
A6: Mes (1-12, vacio = todos) | B6: 9
A7: Tipo (vacio = todos)
A8: Categoria (vacio = todos)
A9: Tercero (vacio = todos)
A10: Cuenta (vacio = todos)
A11: Estado (vacio = todos)
A13: INDICADORES
A14: Ingresos | B14: =SUMPRODUCT(((MOVIMIENTOS!$C$5:$C$10004="Ingreso")+(MOVIMIENTOS!$C$5:$C$10004="Venta"))*((($B$11="")*(MOVIMIENTOS!$P$5:$P$10004="Pagado"))+(($B$11<>"")*(MOVIMIENTOS!$P$5:$P$10004=$B$11)))*(($B$5="")+(YEAR(MOVIMIENTOS!$B$5:$B$10004)=$B$5))*(($B$6="")+(MONTH(MOVIMIENTOS!$B$5:$B$10004)=$B$6))*(($B$7="")+(MOVIMIENTOS!$C$5:$C$10004=$B$7))*(($B$8="")+(MOVIMIENTOS!$H$5:$H$10004=$B$8))*(($B$9="")+(MOVIMIENTOS!$E$5:$E$10004=$B$9))*(($B$10="")+(MOVIMIENTOS!$K$5:$K$10004=$B$10))*MOVIMIENTOS!$O$5:$O$10004)
A15: Gastos | B15: =SUMPRODUCT(((MOVIMIENTOS!$C$5:$C$10004="Gasto")+(MOVIMIENTOS!$C$5:$C$10004="Compra"))*((($B$11="")*(MOVIMIENTOS!$P$5:$P$10004="Pagado"))+(($B$11<>"")*(MOVIMIENTOS!$P$5:$P$10004=$B$11)))*(($B$5="")+(YEAR(MOVIMIENTOS!$B$5:$B$10004)=$B$5))*(($B$6="")+(MONTH(MOVIMIENTOS!$B$5:$B$10004)=$B$6))*(($B$7="")+(MOVIMIENTOS!$C$5:$C$10004=$B$7))*(($B$8="")+(MOVIMIENTOS!$H$5:$H$10004=$B$8))*(($B$9="")+(MOVIMIENTOS!$E$5:$E$10004=$B$9))*(($B$10="")+(MOVIMIENTOS!$K$5:$K$10004=$B$10))*MOVIMIENTOS!$O$5:$O$10004)
A16: Flujo Neto | B16: =B14-B15
A17: Cuentas por Cobrar | B17: =SUMPRODUCT(((MOVIMIENTOS!$C$5:$C$10004="Ingreso")+(MOVIMIENTOS!$C$5:$C$10004="Venta"))*(($B$5="")+(YEAR(MOVIMIENTOS!$B$5:$B$10004)=$B$5))*(($B$6="")+(MONTH(MOVIMIENTOS!$B$5:$B$10004)=$B$6))*(($B$7="")+(MOVIMIENTOS!$C$5:$C$10004=$B$7))*(($B$8="")+(MOVIMIENTOS!$H$5:$H$10004=$B$8))*(($B$9="")+(MOVIMIENTOS!$E$5:$E$10004=$B$9))*(($B$10="")+(MOVIMIENTOS!$K$5:$K$10004=$B$10))*((($B$11="")+($B$11="Pendiente"))*(MOVIMIENTOS!$P$5:$P$10004="Pendiente"))*MOVIMIENTOS!$O$5:$O$10004)
A18: Cuentas por Pagar | B18: =SUMPRODUCT(((MOVIMIENTOS!$C$5:$C$10004="Gasto")+(MOVIMIENTOS!$C$5:$C$10004="Compra"))*(($B$5="")+(YEAR(MOVIMIENTOS!$B$5:$B$10004)=$B$5))*(($B$6="")+(MONTH(MOVIMIENTOS!$B$5:$B$10004)=$B$6))*(($B$7="")+(MOVIMIENTOS!$C$5:$C$10004=$B$7))*(($B$8="")+(MOVIMIENTOS!$H$5:$H$10004=$B$8))*(($B$9="")+(MOVIMIENTOS!$E$5:$E$10004=$B$9))*(($B$10="")+(MOVIMIENTOS!$K$5:$K$10004=$B$10))*((($B$11="")+($B$11="Pendiente"))*(MOVIMIENTOS!$P$5:$P$10004="Pendiente"))*MOVIMIENTOS!$O$5:$O$10004)
A19: Impuestos Recaudados/Pagados | B19: =SUMPRODUCT(((($B$11="")*(MOVIMIENTOS!$P$5:$P$10004="Pagado"))+(($B$11<>"")*(MOVIMIENTOS!$P$5:$P$10004=$B$11)))*(($B$5="")+(YEAR(MOVIMIENTOS!$B$5:$B$10004)=$B$5))*(($B$6="")+(MONTH(MOVIMIENTOS!$B$5:$B$10004)=$B$6))*(($B$7="")+(MOVIMIENTOS!$C$5:$C$10004=$B$7))*(($B$8="")+(MOVIMIENTOS!$H$5:$H$10004=$B$8))*(($B$9="")+(MOVIMIENTOS!$E$5:$E$10004=$B$9))*(($B$10="")+(MOVIMIENTOS!$K$5:$K$10004=$B$10))*MOVIMIENTOS!$M$5:$M$10004)
A20: Documentos Registrados | B20: =SUMPRODUCT((($B$5="")+(YEAR(DOCUMENTOS!$B$5:$B$10004)=$B$5))*(($B$6="")+(MONTH(DOCUMENTOS!$B$5:$B$10004)=$B$6))*(($B$9="")+(DOCUMENTOS!$E$5:$E$10004=$B$9))*(DOCUMENTOS!$L$5:$L$10004="Validado"))
A21: Documentos Pendientes | B21: =SUMPRODUCT((($B$5="")+(YEAR(DOCUMENTOS!$B$5:$B$10004)=$B$5))*(($B$6="")+(MONTH(DOCUMENTOS!$B$5:$B$10004)=$B$6))*(($B$9="")+(DOCUMENTOS!$E$5:$E$10004=$B$9))*(((DOCUMENTOS!$L$5:$L$10004="Pendiente")+(DOCUMENTOS!$L$5:$L$10004="Revision Manual"))))
A22: Documentos con Error | B22: =SUMPRODUCT((($B$5="")+(YEAR(DOCUMENTOS!$B$5:$B$10004)=$B$5))*(($B$6="")+(MONTH(DOCUMENTOS!$B$5:$B$10004)=$B$6))*(($B$9="")+(DOCUMENTOS!$E$5:$E$10004=$B$9))*(((DOCUMENTOS!$L$5:$L$10004="Error")+(DOCUMENTOS!$L$5:$L$10004="Duplicado"))))
A24: Tipo/Categoria/Cuenta filtran movimientos; los conteos de documentos usan Año, Mes y Tercero.
A25: Para Anio/Mes vacios se muestran todos los periodos.

Sheet MENU
A1: SISTEMA FINANCIERO EMPRESARIAL
A2: Plataforma configurable de gestion financiera - Colombia
A4: Navegacion rapida (Ctrl+clic en Excel Desktop, o clic simple segun version):
A6: INICIO
A7: CONFIGURAR EMPRESA
A8: PARAMETROS
A9: CATEGORIAS
A10: IMPUESTOS
A11: CUENTAS
A12: TIPOS DE DOCUMENTO
A13: TERCEROS
A14: ASISTENTE DE CLASIFICACION
... A27: Ejecutar con Alt+F8, o asignar a un boton: Insertar > Formularios > Boton, dibujar, elegir el macro y pulsar Aceptar.
A29: Macro | B29: Que hace
A30: Menu_ImportarDocumento | B30: Copia el soporte y extrae campos estructurados si es XML UBL
A31: Menu_ExtraerXMLDocumentoActivo | B31: Relee el XML UBL de la fila DOCUMENTOS seleccionada
A32: Menu_ConfirmarRevisionXMLDocumentoActivo | B32: Confirma la revisión humana del XML seleccionado
A33: Menu_RenombrarArchivoDocumentoActivo | B33: Renombra en disco el archivo de la fila DOCUMENTOS donde este el cursor
A34: Menu_NuevoMovimiento | B34: Inserta una fila nueva en MOVIMIENTOS con ID y fecha automaticos
A35: Menu_NuevoDocumento | B35: Inserta una fila nueva en DOCUMENTOS con ID automatico
A36: Menu_NuevoTercero | B36: Inserta una fila nueva en TERCEROS con ID automatico
A37: Menu_NuevoPago | B37: Inserta una fila nueva en PAGOS con ID automatico
A38: Menu_NuevoCobro | B38: Inserta una fila nueva en COBROS con ID automatico
A39: Menu_ValidarTodo | B39: Valida MOVIMIENTOS, DOCUMENTOS (incl. duplicados) y TERCEROS (NIT duplicado)
A40: Menu_ActualizarReportes | B40: Recalcula el libro y repuebla CXC/CXP desde MOVIMIENTOS pendientes

Sheet EMPRESA
A1: EMPRESA
A2: Datos de la empresa - editar libremente, no usar en formulas de otras hojas
A4: Campo | B4: Valor
A5: NombreEmpresa | B5: Comercial Andina Demo S.A.S.
A6: NIT | B6: 900000000-1 (FICTICIO)
A7: RegimenTributario | B7: DEMO — validar y configurar para cada empresa
A8: ActividadEconomica | B8: Comercio y servicios (ejemplo)
A9: ResponsableIVA | B9: Configurar
A10: DireccionPrincipal
A11: Ciudad
A12: Telefono
A13: Email
A14: MonedaPrincipal | B14: COP
A15: AnioFiscalInicioMes | B15: Enero
A16: RutaRaizArchivos
A17: LogoRuta

Sheet PARAMETROS
A1: PARAMETROS
A2: Parametros generales del sistema - configurables sin tocar formulas
A4: Codigo | B4: Parametro | C4: Valor | D4: Tipo | E4: Descripcion
A5: PAR-001 | B5: DECIMALES_MONEDA | C5: 0 | D5: Numero | E5: Decimales para valores monetarios
A6: PAR-002 | B6: FORMATO_FECHA | C6: dd/mm/aaaa | D6: Texto | E6: Formato de fecha estandar
A7: PAR-003 | B7: PREFIJO_MOVIMIENTO | C7: MOV- | D7: Texto | E7: Prefijo para ID de movimientos
A8: PAR-004 | B8: PREFIJO_DOCUMENTO | C8: DOC- | D8: Texto | E8: Prefijo para ID de documentos
A9: PAR-005 | B9: UMBRAL_DIAS_DUPLICADO | C9: 5 | D9: Numero | E9: Dias de tolerancia para sugerir posible duplicado
A10: PAR-006 | B10: RUTA_DOCUMENTOS | C10: Documentos | D10: Texto | E10: Ruta relativa a la carpeta del libro o ruta absoluta de soportes
A11: PAR-007 | B11: MODO_COMPATIBILIDAD | C11: COMPATIBLE | D11: Texto | E11: COMPATIBLE (Excel 2019) o MODERNO

Sheet CATEGORIAS
A1: CATEGORIAS
A2: Clasificacion financiera - editable, no ligada a formulas ni VBA
A4: Codigo | B4: Tipo | C4: Categoria | D4: Subcategoria | E4: Activa | F4: Descripcion
A5: ING-001 | B5: Ingreso | C5: Ventas | D5: Productos | E5: Si
A6: ING-002 | B6: Ingreso | C6: Ventas | D6: Servicios | E6: Si
A7: ING-003 | B7: Ingreso | C7: Financiero | D7: Rendimientos | E7: Si
A8: GAS-001 | B8: Gasto | C8: Operacion | D8: Servicios publicos | E8: Si
A9: GAS-002 | B9: Gasto | C9: Operacion | D9: Suministros | E9: Si
A10: GAS-003 | B10: Gasto | C10: Administracion | D10: Software | E10: Si
A11: GAS-004 | B11: Gasto | C11: Administracion | D11: Arriendo | E11: Si
A12: GAS-005 | B12: Gasto | C12: Nomina | D12: Salarios | E12: Si
A13: COM-001 | B13: Compra | C13: Inventario | D13: Mercancia | E13: Si
A14: COM-002 | B14: Compra | C14: Activos | D14: Tecnologia | E14: Si
A15: VEN-001 | B15: Venta | C15: Productos | D15: General | E15: Si
A16: OTR-001 | B16: Otro | C16: Sin clasificar | D16: Sin clasificar | E16: Si | F16: Usar temporalmente y reclasificar

Sheet IMPUESTOS
A1: IMPUESTOS
A2: Impuestos y retenciones - VERIFICAR PORCENTAJES VIGENTES ANTES DE USAR
A4: Codigo | B4: Impuesto | C4: Porcentaje | D4: Tipo | E4: Base | F4: CuentaAsociada | G4: Activo | H4: Observaciones
A5: IVA-001 | B5: IVA general | C5: 0 | D5: Impuesto | E5: Subtotal | G5: Si | H5: Configurar segun normativa DIAN/municipal vigente
A6: RET-001 | B6: Retencion en la fuente - Servicios | C6: 0 | D6: Retencion | E6: Subtotal | G6: Si | H6: Configurar segun normativa DIAN/municipal vigente
A7: RET-002 | B7: Retencion en la fuente - Compras | C7: 0 | D7: Retencion | E7: Subtotal | G7: Si | H7: Configurar segun normativa DIAN/municipal vigente
A8: RET-003 | B8: ReteICA | C8: 0 | D8: Retencion | E8: Subtotal | G8: Si | H8: Configurar segun normativa DIAN/municipal vigente
A9: IC-001 | B9: Impuesto de Industria y Comercio (ICA) | C9: 0 | D9: Impuesto | E9: Ingresos | G9: Si | H9: Configurar segun normativa DIAN/municipal vigente

Sheet TIPOS_DOCUMENTOS
A1: TIPOS_DOCUMENTOS
A2: Tipos de documento soportados - ampliable
A4: Codigo | B4: TipoDocumento | C4: Prefijo | D4: RequiereCUFE | E4: Activo | F4: Descripcion
A5: TD-01 | B5: Factura electronica | C5: FE | D5: Si | E5: Si
A6: TD-02 | B6: Documento equivalente | C6: DE | D6: No | E6: Si
A7: TD-03 | B7: Documento soporte | C7: DS | D7: No | E7: Si | F7: Compras a no obligados a facturar
A8: TD-04 | B8: Nota credito | C8: NC | D8: Si | E8: Si
A9: TD-05 | B9: Nota debito | C9: ND | D9: Si | E9: Si
A10: TD-06 | B10: Recibo | C10: RC | D10: No | E10: Si
A11: TD-07 | B11: Comprobante | C11: CO | D11: No | E11: Si
A12: TD-08 | B12: Extracto bancario | C12: EB | D12: No | E12: Si
A13: TD-09 | B13: Nomina | C13: NM | D13: No | E13: Si
A14: TD-10 | B14: Contrato | C14: CT | D14: No | E14: Si
A15: TD-11 | B15: Otro | C15: OT | D15: No | E15: Si

Sheet ESTADOS
A1: ESTADOS
A2: Catalogo de estados por ambito - referencia; los desplegables usan listas fijas por ambito
A4: Codigo | B4: Estado | C4: Ambito | D4: Activo | E4: Descripcion
A5: EST-01 | B5: Pendiente | C5: Movimiento | D5: Si
A6: EST-02 | B6: Pagado | C6: Movimiento | D6: Si
A7: EST-03 | B7: Anulado | C7: Movimiento | D7: Si
A8: EST-04 | B8: Validado | C8: Documento | D8: Si
A9: EST-05 | B9: Pendiente | C9: Documento | D9: Si
A10: EST-06 | B10: Error | C10: Documento | D10: Si
A11: EST-07 | B11: Revision Manual | C11: Documento | D11: Si
A12: EST-08 | B12: Duplicado | C12: Documento | D12: Si
A13: EST-09 | B13: Pendiente | C13: Pago/Cobro | D13: Si
A14: EST-10 | B14: Aplicado | C14: Pago/Cobro | D14: Si
A15: EST-11 | B15: Anulado | C15: Pago/Cobro | D15: Si

Sheet MEDIOS_PAGO
A1: MEDIOS_PAGO
A4: Codigo | B4: MedioPago | C4: Activo | D4: Descripcion
A5: MP-01 | B5: Efectivo | C5: Si
A6: MP-02 | B6: Transferencia bancaria | C6: Si
A7: MP-03 | B7: Tarjeta debito | C7: Si
A8: MP-04 | B8: Tarjeta credito | C8: Si
A9: MP-05 | B9: Cheque | C9: Si
A10: MP-06 | B10: Billetera digital | C10: Si
A11: MP-07 | B11: Otro | C11: Si

Sheet USUARIOS_ROLES
A1: USUARIOS_ROLES
A2: Administracion de usuarios - control de acceso logico (no reemplaza proteccion de Excel)
A4: ID | B4: Usuario | C4: Rol | D4: Email | E4: Activo | F4: Observaciones
A5: USR-001 | B5: Administrador | C5: Administrador | E5: Si | F5: Acceso total
A6: USR-002 | B6: Contador | C6: Contador | E6: Si | F6: Registro y validacion contable
A7: USR-003 | B7: Auxiliar | C7: Auxiliar | E7: Si | F7: Digitacion y digitalizacion
A8: USR-004 | B8: Consulta | C8: Consulta | E8: Si | F8: Solo lectura de reportes

Sheet TERCEROS
A1: TERCEROS
A2: Base unica de clientes, proveedores, empleados, socios y entidades
A4: ID | B4: Tipo | C4: NombreRazonSocial | D4: NIT_ID | E4: Contacto | F4: Email | G4: Telefono | H4: Direccion | I4: Ciudad | J4: Estado | K4: Observaciones | L4: ClaveDuplicado
A5: TER-DEMO-001 | B5: Cliente | C5: Cliente Aurora Demo S.A.S. | D5: 900000001-2 (FICTICIO) | E5: Contacto de demostración | F5: cliente.demo@example.invalid | G5: 0000000000 | H5: Dirección ficticia | I5: Bogotá D.C. | J5: Activo | K5: Registro ficticio para simulación; no usar como tercero real. | L5: =IF(D5="","",TRIM(UPPER(D5)))
A6: TER-DEMO-002 | B6: Proveedor | C6: Suministros Pacífico Demo S.A.S. | D6: 900000002-3 (FICTICIO) | E6: Contacto de demostración | F6: proveedor.demo@example.invalid | G6: 0000000000 | H6: Dirección ficticia | I6: Medellín | J6: Activo | K6: Registro ficticio para simulación; no usar como tercero real. | L6: =IF(D6="","",TRIM(UPPER(D6)))
A7: TER-DEMO-003 | B7: Proveedor | C7: Nube Clara Demo S.A.S. | D7: 900000003-4 (FICTICIO) | E7: Contacto de demostración | F7: nube.demo@example.invalid | G7: 0000000000 | H7: Dirección ficticia | I7: Cali | J7: Activo | K7: Registro ficticio para simulación; no usar como tercero real. | L7: =IF(D7="","",TRIM(UPPER(D7)))
J8: Activo | L8: =IF(D8="","",TRIM(UPPER(D8)))
J9: Activo | L9: =IF(D9="","",TRIM(UPPER(D9)))
J10: Activo | L10: =IF(D10="","",TRIM(UPPER(D10)))
J11: Activo | L11: =IF(D11="","",TRIM(UPPER(D11)))
J12: Activo | L12: =IF(D12="","",TRIM(UPPER(D12)))
J13: Activo | L13: =IF(D13="","",TRIM(UPPER(D13)))
J14: Activo | L14: =IF(D14="","",TRIM(UPPER(D14)))
J15: Activo | L15: =IF(D15="","",TRIM(UPPER(D15)))
J16: Activo | L16: =IF(D16="","",TRIM(UPPER(D16)))
J17: Activo | L17: =IF(D17="","",TRIM(UPPER(D17)))
J18: Activo | L18: =IF(D18="","",TRIM(UPPER(D18)))
J19: Activo | L19: =IF(D19="","",TRIM(UPPER(D19)))
... J34: Activo | L34: =IF(D34="","",TRIM(UPPER(D34)))

Sheet DOCUMENTOS
A1: DOCUMENTOS
A2: Soportes digitalizados: facturas, recibos, extractos y demas documentos
A4: ID | B4: Fecha | C4: TipoDocumento | D4: Numero | E4: Tercero | F4: Identificacion | G4: Subtotal | H4: Impuestos | I4: Retenciones | J4: Total | K4: CUFE_Referencia | L4: Estado | M4: RutaArchivo | N4: NombreArchivo | O4: TipoArchivo | P4: FechaExtraccion | Q4: MetodoExtraccion | R4: Confianza | S4: Observaciones
A5: DOC-DEMO-001 | B5: 46273 | C5: Factura electronica | D5: FV-DEMO-001 | E5: Cliente Aurora Demo S.A.S. | F5: 900000001-2 (FICTICIO) | G5: 4800000 | H5: 0 | I5: 0 | J5: 4800000 | K5: CUFE-FICTICIO-DEMO-001 | L5: Validado | M5: DEMO://documentos/FACTURA_DEMO_001.xml | N5: FACTURA_DEMO_001.xml | O5: XML | P5: 46273.385 | Q5: XML | R5: 1 | S5: XML estructurado ficticio; campos y sumas de ejemplo.
A6: DOC-DEMO-002 | B6: 46277 | C6: Factura electronica | D6: FV-DEMO-002 | E6: Cliente Aurora Demo S.A.S. | F6: 900000001-2 (FICTICIO) | G6: 2150000 | H6: 0 | I6: 0 | J6: 2150000 | K6: CUFE-FICTICIO-DEMO-002 | L6: Validado | M6: DEMO://documentos/FACTURA_DEMO_002.xml | N6: FACTURA_DEMO_002.xml | O6: XML | P6: 46277.42 | Q6: XML | R6: 1 | S6: Factura ficticia relacionada con una cuenta pendiente de cobro.
A7: DOC-DEMO-003 | B7: 46275 | C7: Factura electronica | D7: FC-DEMO-003 | E7: Suministros Pacífico Demo S.A.S. | F7: 900000002-3 (FICTICIO) | G7: 850000 | H7: 0 | I7: 0 | J7: 850000 | K7: CUFE-FICTICIO-DEMO-003 | L7: Validado | M7: DEMO://documentos/FACTURA_DEMO_003.xml | N7: FACTURA_DEMO_003.xml | O7: XML | P7: 46275.479 | Q7: XML | R7: 1 | S7: Factura ficticia estructurada; validación aritmética de ejemplo.
A8: DOC-DEMO-004 | B8: 46283 | C8: Factura electronica | D8: FC-DEMO-004 | E8: Suministros Pacífico Demo S.A.S. | F8: 900000002-3 (FICTICIO) | G8: 420000 | H8: 0 | I8: 0 | J8: 420000 | K8: CUFE-FICTICIO-DEMO-004 | L8: Validado | M8: DEMO://documentos/FACTURA_DEMO_004.xml | N8: FACTURA_DEMO_004.xml | O8: XML | P8: 46283.59 | Q8: XML | R8: 1 | S8: Factura ficticia de compra de activo.
A9: DOC-DEMO-005 | B9: 46286 | C9: Factura electronica | D9: FE-DEMO-005 | E9: Nube Clara Demo S.A.S. | F9: 900000003-4 (FICTICIO) | G9: 620000 | H9: 0 | I9: 0 | J9: 620000 | K9: CUFE-FICTICIO-DEMO-005 | L9: Validado | M9: DEMO://documentos/FACTURA_DEMO_005.xml | N9: FACTURA_DEMO_005.xml | O9: XML | P9: 46286.365 | Q9: XML | R9: 1 | S9: Factura ficticia relacionada con cuenta pendiente de pago.
A10: DOC-DEMO-006 | B10: 46288 | C10: Recibo | D10: RC-DEMO-006 | E10: Nube Clara Demo S.A.S. | F10: 900000003-4 (FICTICIO) | G10: 185000 | H10: 0 | I10: 0 | J10: 185000 | L10: Revision Manual | M10: DEMO://documentos/RECIBO_DEMO_006.jpg | N10: RECIBO_DEMO_006.jpg | O10: JPG | P10: 46288.681 | Q10: OCR simulado | R10: 0.64 | S10: Confianza baja en fecha y tercero: revisar el soporte antes de registrarlo.

Sheet MOVIMIENTOS
A1: MOVIMIENTOS
A2: Tabla principal: ingresos, gastos, compras, ventas y otros movimientos
A4: ID | B4: Fecha | C4: Tipo | D4: Documento | E4: Tercero | F4: NIT_ID | G4: Concepto | H4: Categoria | I4: Subcategoria | J4: MedioPago | K4: Cuenta | L4: Subtotal | M4: Impuestos | N4: Retenciones | O4: Total | P4: Estado | Q4: SoporteID | R4: Observaciones
A5: MOV-DEMO-001 | B5: 46273 | C5: Ingreso | D5: FV-DEMO-001 | E5: Cliente Aurora Demo S.A.S. | F5: 900000001-2 (FICTICIO) | G5: Servicio mensual de demostración | H5: Ventas | I5: Servicios | J5: Transferencia | K5: Banco Principal | L5: 4800000 | M5: 0 | N5: 0 | O5: =IF(L5="",0,L5+M5-N5) | P5: Pagado | Q5: DOC-DEMO-001 | R5: Operación completamente ficticia; valores sin cálculo tributario.
A6: MOV-DEMO-002 | B6: 46277 | C6: Venta | D6: FV-DEMO-002 | E6: Cliente Aurora Demo S.A.S. | F6: 900000001-2 (FICTICIO) | G6: Venta de productos de demostración | H6: Productos | I6: General | J6: Transferencia | K6: Cuentas por Cobrar | L6: 2150000 | M6: 0 | N6: 0 | O6: =IF(L6="",0,L6+M6-N6) | P6: Pendiente | Q6: DOC-DEMO-002 | R6: Saldo por cobrar de ejemplo.
A7: MOV-DEMO-003 | B7: 46275 | C7: Compra | D7: FC-DEMO-003 | E7: Suministros Pacífico Demo S.A.S. | F7: 900000002-3 (FICTICIO) | G7: Suministros de oficina de demostración | H7: Inventario | I7: Mercancia | J7: Transferencia | K7: Banco Principal | L7: 850000 | M7: 0 | N7: 0 | O7: =IF(L7="",0,L7+M7-N7) | P7: Pagado | Q7: DOC-DEMO-003 | R7: Operación completamente ficticia; valores sin cálculo tributario.
A8: MOV-DEMO-004 | B8: 46283 | C8: Compra | D8: FC-DEMO-004 | E8: Suministros Pacífico Demo S.A.S. | F8: 900000002-3 (FICTICIO) | G8: Equipo tecnológico de demostración | H8: Activos | I8: Tecnologia | J8: Transferencia | K8: Banco Principal | L8: 420000 | M8: 0 | N8: 0 | O8: =IF(L8="",0,L8+M8-N8) | P8: Pagado | Q8: DOC-DEMO-004 | R8: Operación completamente ficticia; valores sin cálculo tributario.
A9: MOV-DEMO-005 | B9: 46286 | C9: Gasto | D9: FE-DEMO-005 | E9: Nube Clara Demo S.A.S. | F9: 900000003-4 (FICTICIO) | G9: Suscripción de software de demostración | H9: Administracion | I9: Software | J9: Transferencia | K9: Cuentas por Pagar | L9: 620000 | M9: 0 | N9: 0 | O9: =IF(L9="",0,L9+M9-N9) | P9: Pendiente | Q9: DOC-DEMO-005 | R9: Saldo por pagar de ejemplo.
O10: =IF(L10="",0,L10+M10-N10)
O11: =IF(L11="",0,L11+M11-N11)
O12: =IF(L12="",0,L12+M12-N12)
O13: =IF(L13="",0,L13+M13-N13)
O14: =IF(L14="",0,L14+M14-N14)
O15: =IF(L15="",0,L15+M15-N15)
O16: =IF(L16="",0,L16+M16-N16)
O17: =IF(L17="",0,L17+M17-N17)
O18: =IF(L18="",0,L18+M18-N18)
O19: =IF(L19="",0,L19+M19-N19)
O20: =IF(L20="",0,L20+M20-N20)
O21: =IF(L21="",0,L21+M21-N21)
... O64: =IF(L64="",0,L64+M64-N64)

Sheet PAGOS
A1: PAGOS
A2: Salidas de caja aplicadas contra movimientos de Gasto/Compra (permite pagos parciales)
A4: ID | B4: Fecha | C4: MovimientoID | D4: Tercero | E4: Cuenta | F4: MedioPago | G4: ValorPagado | H4: Estado | I4: Observaciones
A5: PAG-DEMO-001 | B5: 46275 | C5: MOV-DEMO-003 | D5: Suministros Pacífico Demo S.A.S. | E5: Banco Principal | F5: Transferencia | G5: 850000 | H5: Aplicado | I5: Pago ficticio aplicado al movimiento de compra.
A6: PAG-DEMO-002 | B6: 46283 | C6: MOV-DEMO-004 | D6: Suministros Pacífico Demo S.A.S. | E6: Banco Principal | F6: Transferencia | G6: 420000 | H6: Aplicado | I6: Pago ficticio aplicado al movimiento de compra.

Sheet COBROS
A1: COBROS
A2: Entradas de caja aplicadas contra movimientos de Ingreso/Venta (permite cobros parciales)
A4: ID | B4: Fecha | C4: MovimientoID | D4: Tercero | E4: Cuenta | F4: MedioPago | G4: ValorCobrado | H4: Estado | I4: Observaciones
A5: COB-DEMO-001 | B5: 46273 | C5: MOV-DEMO-001 | D5: Cliente Aurora Demo S.A.S. | E5: Banco Principal | F5: Transferencia | G5: 4800000 | H5: Aplicado | I5: Cobro ficticio aplicado al movimiento de ingreso.

Sheet CUENTAS
A1: CUENTAS
A2: Cuentas de la empresa - el saldo actual se calcula automaticamente
A4: ID | B4: Cuenta | C4: Tipo | D4: Entidad | E4: NumeroReferencia | F4: SaldoInicial | G4: SaldoActual | H4: Activa | I4: Observaciones
A5: CTA-001 | B5: Caja General | C5: Caja | F5: 0 | G5: =$F5+SUMIFS(MOVIMIENTOS!$O$5:$O$10004,MOVIMIENTOS!$K$5:$K$10004,$B5,MOVIMIENTOS!$C$5:$C$10004,"Ingreso",MOVIMIENTOS!$P$5:$P$10004,"Pagado")+SUMIFS(MOVIMIENTOS!$O$5:$O$10004,MOVIMIENTOS!$K$5:$K$10004,$B5,MOVIMIENTOS!$C$5:$C$10004,"Venta",MOVIMIENTOS!$P$5:$P$10004,"Pagado")-SUMIFS(MOVIMIENTOS!$O$5:$O$10004,MOVIMIENTOS!$K$5:$K$10004,$B5,MOVIMIENTOS!$C$5:$C$10004,"Gasto",MOVIMIENTOS!$P$5:$P$10004,"Pagado")-SUMIFS(MOVIMIENTOS!$O$5:$O$10004,MOVIMIENTOS!$K$5:$K$10004,$B5,MOVIMIENTOS!$C$5:$C$10004,"Compra",MOVIMIENTOS!$P$5:$P$10004,"Pagado") | H5: Si
A6: CTA-002 | B6: Banco Principal | C6: Banco | D6: Configurar entidad | F6: 0 | G6: =$F6+SUMIFS(MOVIMIENTOS!$O$5:$O$10004,MOVIMIENTOS!$K$5:$K$10004,$B6,MOVIMIENTOS!$C$5:$C$10004,"Ingreso",MOVIMIENTOS!$P$5:$P$10004,"Pagado")+SUMIFS(MOVIMIENTOS!$O$5:$O$10004,MOVIMIENTOS!$K$5:$K$10004,$B6,MOVIMIENTOS!$C$5:$C$10004,"Venta",MOVIMIENTOS!$P$5:$P$10004,"Pagado")-SUMIFS(MOVIMIENTOS!$O$5:$O$10004,MOVIMIENTOS!$K$5:$K$10004,$B6,MOVIMIENTOS!$C$5:$C$10004,"Gasto",MOVIMIENTOS!$P$5:$P$10004,"Pagado")-SUMIFS(MOVIMIENTOS!$O$5:$O$10004,MOVIMIENTOS!$K$5:$K$10004,$B6,MOVIMIENTOS!$C$5:$C$10004,"Compra",MOVIMIENTOS!$P$5:$P$10004,"Pagado") | H6: Si
A7: CTA-003 | B7: Cuentas por Cobrar | C7: Cuenta por cobrar | F7: 0 | G7: =$F7+SUMIFS(MOVIMIENTOS!$O$5:$O$10004,MOVIMIENTOS!$K$5:$K$10004,$B7,MOVIMIENTOS!$C$5:$C$10004,"Ingreso",MOVIMIENTOS!$P$5:$P$10004,"Pagado")+SUMIFS(MOVIMIENTOS!$O$5:$O$10004,MOVIMIENTOS!$K$5:$K$10004,$B7,MOVIMIENTOS!$C$5:$C$10004,"Venta",MOVIMIENTOS!$P$5:$P$10004,"Pagado")-SUMIFS(MOVIMIENTOS!$O$5:$O$10004,MOVIMIENTOS!$K$5:$K$10004,$B7,MOVIMIENTOS!$C$5:$C$10004,"Gasto",MOVIMIENTOS!$P$5:$P$10004,"Pagado")-SUMIFS(MOVIMIENTOS!$O$5:$O$10004,MOVIMIENTOS!$K$5:$K$10004,$B7,MOVIMIENTOS!$C$5:$C$10004,"Compra",MOVIMIENTOS!$P$5:$P$10004,"Pagado") | H7: Si
A8: CTA-004 | B8: Cuentas por Pagar | C8: Cuenta por pagar | F8: 0 | G8: =$F8+SUMIFS(MOVIMIENTOS!$O$5:$O$10004,MOVIMIENTOS!$K$5:$K$10004,$B8,MOVIMIENTOS!$C$5:$C$10004,"Ingreso",MOVIMIENTOS!$P$5:$P$10004,"Pagado")+SUMIFS(MOVIMIENTOS!$O$5:$O$10004,MOVIMIENTOS!$K$5:$K$10004,$B8,MOVIMIENTOS!$C$5:$C$10004,"Venta",MOVIMIENTOS!$P$5:$P$10004,"Pagado")-SUMIFS(MOVIMIENTOS!$O$5:$O$10004,MOVIMIENTOS!$K$5:$K$10004,$B8,MOVIMIENTOS!$C$5:$C$10004,"Gasto",MOVIMIENTOS!$P$5:$P$10004,"Pagado")-SUMIFS(MOVIMIENTOS!$O$5:$O$10004,MOVIMIENTOS!$K$5:$K$10004,$B8,MOVIMIENTOS!$C$5:$C$10004,"Compra",MOVIMIENTOS!$P$5:$P$10004,"Pagado") | H8: Si

Sheet ASISTENTE
A1: ASISTENTE LOCAL
A2: Sugerencias por reglas editables; revise cada resultado antes de registrarlo
A4: DATOS DE LA OPERACIÓN
A5: Tercero o proveedor
A6: Concepto o descripción
A8: SUGERENCIA
A9: Estado | B9: =IF($B$6="","Escriba un concepto",IF(MAX('REGLAS_IA'!$K$5:$K$104)=0,"Sin coincidencia",IF(COUNTIF('REGLAS_IA'!$K$5:$K$104,MAX('REGLAS_IA'!$K$5:$K$104))>1,"Conflicto: ajuste prioridad","Sugerencia lista para revisar")))
A10: Tipo | B10: =IF($B$9<>"Sugerencia lista para revisar","",IFERROR(INDEX('REGLAS_IA'!$D$5:$D$104,MATCH(MAX('REGLAS_IA'!$K$5:$K$104),'REGLAS_IA'!$K$5:$K$104,0)),""))
A11: Categoría | B11: =IF($B$9<>"Sugerencia lista para revisar","",IFERROR(INDEX('REGLAS_IA'!$E$5:$E$104,MATCH(MAX('REGLAS_IA'!$K$5:$K$104),'REGLAS_IA'!$K$5:$K$104,0)),""))
A12: Subcategoría | B12: =IF($B$9<>"Sugerencia lista para revisar","",IFERROR(INDEX('REGLAS_IA'!$F$5:$F$104,MATCH(MAX('REGLAS_IA'!$K$5:$K$104),'REGLAS_IA'!$K$5:$K$104,0)),""))
A13: Medio de pago | B13: =IF($B$9<>"Sugerencia lista para revisar","",IFERROR(INDEX('REGLAS_IA'!$G$5:$G$104,MATCH(MAX('REGLAS_IA'!$K$5:$K$104),'REGLAS_IA'!$K$5:$K$104,0)),""))
A14: Cuenta | B14: =IF($B$9<>"Sugerencia lista para revisar","",IFERROR(INDEX('REGLAS_IA'!$H$5:$H$104,MATCH(MAX('REGLAS_IA'!$K$5:$K$104),'REGLAS_IA'!$K$5:$K$104,0)),""))
A15: Regla coincidente | B15: =IF($B$9<>"Sugerencia lista para revisar","",IFERROR(INDEX('REGLAS_IA'!$C$5:$C$104,MATCH(MAX('REGLAS_IA'!$K$5:$K$104),'REGLAS_IA'!$K$5:$K$104,0)),""))
A16: Prioridad de regla | B16: =IF($B$9<>"Sugerencia lista para revisar","",IFERROR(INDEX('REGLAS_IA'!$J$5:$J$104,MATCH(MAX('REGLAS_IA'!$K$5:$K$104),'REGLAS_IA'!$K$5:$K$104,0)),""))
A18: CÓMO USARLO
A19: 1. Escriba el tercero y el concepto. El tercero es opcional.
A20: 2. Revise la regla, el tipo y la categoría sugeridos.
A21: 3. Confirme los datos y regístrelos en MOVIMIENTOS.
A23: Funciona sin internet ni servicios pagos. La prioridad ordena reglas, no es una probabilidad de acierto. No calcula impuestos ni registra datos automáticamente.
A26: Editar las reglas y crear patrones propios
A27: Volver al inicio

Sheet REGLAS_IA
A1: REGLAS DEL ASISTENTE
A2: Catálogo editable de patrones; agregue reglas aprobadas por su empresa
A3: Las reglas solo proponen clasificación. Prioridad mayor gana; si hay empate, el asistente muestra conflicto. Ajuste palabras y prioridad según sus operaciones.
A4: ID | B4: Activa | C4: PalabraClave | D4: Tipo | E4: Categoria | F4: Subcategoria | G4: MedioPago | H4: Cuenta | I4: TerceroOpcional | J4: Prioridad | K4: Coincidencia | L4: Observaciones
A5: IA-001 | B5: Sí | C5: arriendo | D5: Gasto | E5: Administracion | F5: Arriendo | J5: 20 | K5: =IF(OR(B5<>"Sí",C5="",ASISTENTE!$B$6=""),0,IFERROR(IF(AND(OR(I5="",ISNUMBER(SEARCH(I5,ASISTENTE!$B$5))),ISNUMBER(SEARCH(C5,ASISTENTE!$B$5&" "&ASISTENTE!$B$6))),J5,0),0)) | L5: Ejemplo editable
A6: IA-002 | B6: Sí | C6: servicios publicos | D6: Gasto | E6: Operacion | F6: Servicios publicos | J6: 20 | K6: =IF(OR(B6<>"Sí",C6="",ASISTENTE!$B$6=""),0,IFERROR(IF(AND(OR(I6="",ISNUMBER(SEARCH(I6,ASISTENTE!$B$5))),ISNUMBER(SEARCH(C6,ASISTENTE!$B$5&" "&ASISTENTE!$B$6))),J6,0),0)) | L6: Ejemplo sin tilde
A7: IA-003 | B7: Sí | C7: servicios públicos | D7: Gasto | E7: Operacion | F7: Servicios publicos | J7: 20 | K7: =IF(OR(B7<>"Sí",C7="",ASISTENTE!$B$6=""),0,IFERROR(IF(AND(OR(I7="",ISNUMBER(SEARCH(I7,ASISTENTE!$B$5))),ISNUMBER(SEARCH(C7,ASISTENTE!$B$5&" "&ASISTENTE!$B$6))),J7,0),0)) | L7: Variante con tilde
A8: IA-004 | B8: Sí | C8: suministros | D8: Gasto | E8: Operacion | F8: Suministros | J8: 20 | K8: =IF(OR(B8<>"Sí",C8="",ASISTENTE!$B$6=""),0,IFERROR(IF(AND(OR(I8="",ISNUMBER(SEARCH(I8,ASISTENTE!$B$5))),ISNUMBER(SEARCH(C8,ASISTENTE!$B$5&" "&ASISTENTE!$B$6))),J8,0),0)) | L8: Ejemplo editable
A9: IA-005 | B9: Sí | C9: software | D9: Gasto | E9: Administracion | F9: Software | J9: 20 | K9: =IF(OR(B9<>"Sí",C9="",ASISTENTE!$B$6=""),0,IFERROR(IF(AND(OR(I9="",ISNUMBER(SEARCH(I9,ASISTENTE!$B$5))),ISNUMBER(SEARCH(C9,ASISTENTE!$B$5&" "&ASISTENTE!$B$6))),J9,0),0)) | L9: Ejemplo editable
A10: IA-006 | B10: Sí | C10: nomina | D10: Gasto | E10: Nomina | F10: Salarios | J10: 20 | K10: =IF(OR(B10<>"Sí",C10="",ASISTENTE!$B$6=""),0,IFERROR(IF(AND(OR(I10="",ISNUMBER(SEARCH(I10,ASISTENTE!$B$5))),ISNUMBER(SEARCH(C10,ASISTENTE!$B$5&" "&ASISTENTE!$B$6))),J10,0),0)) | L10: Ejemplo sin tilde
A11: IA-007 | B11: Sí | C11: nómina | D11: Gasto | E11: Nomina | F11: Salarios | J11: 20 | K11: =IF(OR(B11<>"Sí",C11="",ASISTENTE!$B$6=""),0,IFERROR(IF(AND(OR(I11="",ISNUMBER(SEARCH(I11,ASISTENTE!$B$5))),ISNUMBER(SEARCH(C11,ASISTENTE!$B$5&" "&ASISTENTE!$B$6))),J11,0),0)) | L11: Variante con tilde
A12: IA-008 | B12: Sí | C12: venta de productos | D12: Ingreso | E12: Ventas | F12: Productos | J12: 30 | K12: =IF(OR(B12<>"Sí",C12="",ASISTENTE!$B$6=""),0,IFERROR(IF(AND(OR(I12="",ISNUMBER(SEARCH(I12,ASISTENTE!$B$5))),ISNUMBER(SEARCH(C12,ASISTENTE!$B$5&" "&ASISTENTE!$B$6))),J12,0),0)) | L12: Frase específica
A13: IA-009 | B13: Sí | C13: venta productos | D13: Ingreso | E13: Ventas | F13: Productos | J13: 25 | K13: =IF(OR(B13<>"Sí",C13="",ASISTENTE!$B$6=""),0,IFERROR(IF(AND(OR(I13="",ISNUMBER(SEARCH(I13,ASISTENTE!$B$5))),ISNUMBER(SEARCH(C13,ASISTENTE!$B$5&" "&ASISTENTE!$B$6))),J13,0),0)) | L13: Frase breve
A14: IA-010 | B14: Sí | C14: venta de servicios | D14: Ingreso | E14: Ventas | F14: Servicios | J14: 30 | K14: =IF(OR(B14<>"Sí",C14="",ASISTENTE!$B$6=""),0,IFERROR(IF(AND(OR(I14="",ISNUMBER(SEARCH(I14,ASISTENTE!$B$5))),ISNUMBER(SEARCH(C14,ASISTENTE!$B$5&" "&ASISTENTE!$B$6))),J14,0),0)) | L14: Frase específica
A15: IA-011 | B15: Sí | C15: venta servicios | D15: Ingreso | E15: Ventas | F15: Servicios | J15: 25 | K15: =IF(OR(B15<>"Sí",C15="",ASISTENTE!$B$6=""),0,IFERROR(IF(AND(OR(I15="",ISNUMBER(SEARCH(I15,ASISTENTE!$B$5))),ISNUMBER(SEARCH(C15,ASISTENTE!$B$5&" "&ASISTENTE!$B$6))),J15,0),0)) | L15: Frase breve
A16: IA-012 | B16: Sí | C16: rendimientos | D16: Ingreso | E16: Financiero | F16: Rendimientos | J16: 20 | K16: =IF(OR(B16<>"Sí",C16="",ASISTENTE!$B$6=""),0,IFERROR(IF(AND(OR(I16="",ISNUMBER(SEARCH(I16,ASISTENTE!$B$5))),ISNUMBER(SEARCH(C16,ASISTENTE!$B$5&" "&ASISTENTE!$B$6))),J16,0),0)) | L16: Ejemplo editable
... A20: IA-016 | B20: Sí | C20: tecnología | D20: Compra | E20: Activos | F20: Tecnologia | J20: 20 | K20: =IF(OR(B20<>"Sí",C20="",ASISTENTE!$B$6=""),0,IFERROR(IF(AND(OR(I20="",ISNUMBER(SEARCH(I20,ASISTENTE!$B$5))),ISNUMBER(SEARCH(C20,ASISTENTE!$B$5&" "&ASISTENTE!$B$6))),J20,0),0)) | L20: Variante con tilde
K21: =IF(OR(B21<>"Sí",C21="",ASISTENTE!$B$6=""),0,IFERROR(IF(AND(OR(I21="",ISNUMBER(SEARCH(I21,ASISTENTE!$B$5))),ISNUMBER(SEARCH(C21,ASISTENTE!$B$5&" "&ASISTENTE!$B$6))),J21,0),0))
K22: =IF(OR(B22<>"Sí",C22="",ASISTENTE!$B$6=""),0,IFERROR(IF(AND(OR(I22="",ISNUMBER(SEARCH(I22,ASISTENTE!$B$5))),ISNUMBER(SEARCH(C22,ASISTENTE!$B$5&" "&ASISTENTE!$B$6))),J22,0),0))
K23: =IF(OR(B23<>"Sí",C23="",ASISTENTE!$B$6=""),0,IFERROR(IF(AND(OR(I23="",ISNUMBER(SEARCH(I23,ASISTENTE!$B$5))),ISNUMBER(SEARCH(C23,ASISTENTE!$B$5&" "&ASISTENTE!$B$6))),J23,0),0))
K24: =IF(OR(B24<>"Sí",C24="",ASISTENTE!$B$6=""),0,IFERROR(IF(AND(OR(I24="",ISNUMBER(SEARCH(I24,ASISTENTE!$B$5))),ISNUMBER(SEARCH(C24,ASISTENTE!$B$5&" "&ASISTENTE!$B$6))),J24,0),0))
K25: =IF(OR(B25<>"Sí",C25="",ASISTENTE!$B$6=""),0,IFERROR(IF(AND(OR(I25="",ISNUMBER(SEARCH(I25,ASISTENTE!$B$5))),ISNUMBER(SEARCH(C25,ASISTENTE!$B$5&" "&ASISTENTE!$B$6))),J25,0),0))
K26: =IF(OR(B26<>"Sí",C26="",ASISTENTE!$B$6=""),0,IFERROR(IF(AND(OR(I26="",ISNUMBER(SEARCH(I26,ASISTENTE!$B$5))),ISNUMBER(SEARCH(C26,ASISTENTE!$B$5&" "&ASISTENTE!$B$6))),J26,0),0))
K27: =IF(OR(B27<>"Sí",C27="",ASISTENTE!$B$6=""),0,IFERROR(IF(AND(OR(I27="",ISNUMBER(SEARCH(I27,ASISTENTE!$B$5))),ISNUMBER(SEARCH(C27,ASISTENTE!$B$5&" "&ASISTENTE!$B$6))),J27,0),0))
K28: =IF(OR(B28<>"Sí",C28="",ASISTENTE!$B$6=""),0,IFERROR(IF(AND(OR(I28="",ISNUMBER(SEARCH(I28,ASISTENTE!$B$5))),ISNUMBER(SEARCH(C28,ASISTENTE!$B$5&" "&ASISTENTE!$B$6))),J28,0),0))
K29: =IF(OR(B29<>"Sí",C29="",ASISTENTE!$B$6=""),0,IFERROR(IF(AND(OR(I29="",ISNUMBER(SEARCH(I29,ASISTENTE!$B$5))),ISNUMBER(SEARCH(C29,ASISTENTE!$B$5&" "&ASISTENTE!$B$6))),J29,0),0))
K30: =IF(OR(B30<>"Sí",C30="",ASISTENTE!$B$6=""),0,IFERROR(IF(AND(OR(I30="",ISNUMBER(SEARCH(I30,ASISTENTE!$B$5))),ISNUMBER(SEARCH(C30,ASISTENTE!$B$5&" "&ASISTENTE!$B$6))),J30,0),0))
K31: =IF(OR(B31<>"Sí",C31="",ASISTENTE!$B$6=""),0,IFERROR(IF(AND(OR(I31="",ISNUMBER(SEARCH(I31,ASISTENTE!$B$5))),ISNUMBER(SEARCH(C31,ASISTENTE!$B$5&" "&ASISTENTE!$B$6))),J31,0),0))
K32: =IF(OR(B32<>"Sí",C32="",ASISTENTE!$B$6=""),0,IFERROR(IF(AND(OR(I32="",ISNUMBER(SEARCH(I32,ASISTENTE!$B$5))),ISNUMBER(SEARCH(C32,ASISTENTE!$B$5&" "&ASISTENTE!$B$6))),J32,0),0))
... K104: =IF(OR(B104<>"Sí",C104="",ASISTENTE!$B$6=""),0,IFERROR(IF(AND(OR(I104="",ISNUMBER(SEARCH(I104,ASISTENTE!$B$5))),ISNUMBER(SEARCH(C104,ASISTENTE!$B$5&" "&ASISTENTE!$B$6))),J104,0),0))

Sheet INGRESOS
A1: INGRESOS
A2: Detalle de Ingreso/Venta agrupado por categoria y mes
A3: Año del reporte | B3: 2026
A4: Categoria | B4: Ene | C4: Feb | D4: Mar | E4: Abr | F4: May | G4: Jun | H4: Jul | I4: Ago | J4: Sep | K4: Oct | L4: Nov | M4: Dic | N4: Total
A5: Ventas | B5: =SUMPRODUCT((MOVIMIENTOS!$H$5:$H$10004=$A5)*((MOVIMIENTOS!$C$5:$C$10004="Ingreso")+(MOVIMIENTOS!$C$5:$C$10004="Venta"))*(YEAR(MOVIMIENTOS!$B$5:$B$10004)=$B$3)*(MONTH(MOVIMIENTOS!$B$5:$B$10004)=1)*(MOVIMIENTOS!$P$5:$P$10004="Pagado")*MOVIMIENTOS!$O$5:$O$10004) | C5: =SUMPRODUCT((MOVIMIENTOS!$H$5:$H$10004=$A5)*((MOVIMIENTOS!$C$5:$C$10004="Ingreso")+(MOVIMIENTOS!$C$5:$C$10004="Venta"))*(YEAR(MOVIMIENTOS!$B$5:$B$10004)=$B$3)*(MONTH(MOVIMIENTOS!$B$5:$B$10004)=2)*(MOVIMIENTOS!$P$5:$P$10004="Pagado")*MOVIMIENTOS!$O$5:$O$10004) | D5: =SUMPRODUCT((MOVIMIENTOS!$H$5:$H$10004=$A5)*((MOVIMIENTOS!$C$5:$C$10004="Ingreso")+(MOVIMIENTOS!$C$5:$C$10004="Venta"))*(YEAR(MOVIMIENTOS!$B$5:$B$10004)=$B$3)*(MONTH(MOVIMIENTOS!$B$5:$B$10004)=3)*(MOVIMIENTOS!$P$5:$P$10004="Pagado")*MOVIMIENTOS!$O$5:$O$10004) | E5: =SUMPRODUCT((MOVIMIENTOS!$H$5:$H$10004=$A5)*((MOVIMIENTOS!$C$5:$C$10004="Ingreso")+(MOVIMIENTOS!$C$5:$C$10004="Venta"))*(YEAR(MOVIMIENTOS!$B$5:$B$10004)=$B$3)*(MONTH(MOVIMIENTOS!$B$5:$B$10004)=4)*(MOVIMIENTOS!$P$5:$P$10004="Pagado")*MOVIMIENTOS!$O$5:$O$10004) | F5: =SUMPRODUCT((MOVIMIENTOS!$H$5:$H$10004=$A5)*((MOVIMIENTOS!$C$5:$C$10004="Ingreso")+(MOVIMIENTOS!$C$5:$C$10004="Venta"))*(YEAR(MOVIMIENTOS!$B$5:$B$10004)=$B$3)*(MONTH(MOVIMIENTOS!$B$5:$B$10004)=5)*(MOVIMIENTOS!$P$5:$P$10004="Pagado")*MOVIMIENTOS!$O$5:$O$10004) | G5: =SUMPRODUCT((MOVIMIENTOS!$H$5:$H$10004=$A5)*((MOVIMIENTOS!$C$5:$C$10004="Ingreso")+(MOVIMIENTOS!$C$5:$C$10004="Venta"))*(YEAR(MOVIMIENTOS!$B$5:$B$10004)=$B$3)*(MONTH(MOVIMIENTOS!$B$5:$B$10004)=6)*(MOVIMIENTOS!$P$5:$P$10004="Pagado")*MOVIMIENTOS!$O$5:$O$10004) | H5: =SUMPRODUCT((MOVIMIENTOS!$H$5:$H$10004=$A5)*((MOVIMIENTOS!$C$5:$C$10004="Ingreso")+(MOVIMIENTOS!$C$5:$C$10004="Venta"))*(YEAR(MOVIMIENTOS!$B$5:$B$10004)=$B$3)*(MONTH(MOVIMIENTOS!$B$5:$B$10004)=7)*(MOVIMIENTOS!$P$5:$P$10004="Pagado")*MOVIMIENTOS!$O$5:$O$10004) | I5: =SUMPRODUCT((MOVIMIENTOS!$H$5:$H$10004=$A5)*((MOVIMIENTOS!$C$5:$C$10004="Ingreso")+(MOVIMIENTOS!$C$5:$C$10004="Venta"))*(YEAR(MOVIMIENTOS!$B$5:$B$10004)=$B$3)*(MONTH(MOVIMIENTOS!$B$5:$B$10004)=8)*(MOVIMIENTOS!$P$5:$P$10004="Pagado")*MOVIMIENTOS!$O$5:$O$10004) | J5: =SUMPRODUCT((MOVIMIENTOS!$H$5:$H$10004=$A5)*((MOVIMIENTOS!$C$5:$C$10004="Ingreso")+(MOVIMIENTOS!$C$5:$C$10004="Venta"))*(YEAR(MOVIMIENTOS!$B$5:$B$10004)=$B$3)*(MONTH(MOVIMIENTOS!$B$5:$B$10004)=9)*(MOVIMIENTOS!$P$5:$P$10004="Pagado")*MOVIMIENTOS!$O$5:$O$10004) | K5: =SUMPRODUCT((MOVIMIENTOS!$H$5:$H$10004=$A5)*((MOVIMIENTOS!$C$5:$C$10004="Ingreso")+(MOVIMIENTOS!$C$5:$C$10004="Venta"))*(YEAR(MOVIMIENTOS!$B$5:$B$10004)=$B$3)*(MONTH(MOVIMIENTOS!$B$5:$B$10004)=10)*(MOVIMIENTOS!$P$5:$P$10004="Pagado")*MOVIMIENTOS!$O$5:$O$10004) | L5: =SUMPRODUCT((MOVIMIENTOS!$H$5:$H$10004=$A5)*((MOVIMIENTOS!$C$5:$C$10004="Ingreso")+(MOVIMIENTOS!$C$5:$C$10004="Venta"))*(YEAR(MOVIMIENTOS!$B$5:$B$10004)=$B$3)*(MONTH(MOVIMIENTOS!$B$5:$B$10004)=11)*(MOVIMIENTOS!$P$5:$P$10004="Pagado")*MOVIMIENTOS!$O$5:$O$10004) | M5: =SUMPRODUCT((MOVIMIENTOS!$H$5:$H$10004=$A5)*((MOVIMIENTOS!$C$5:$C$10004="Ingreso")+(MOVIMIENTOS!$C$5:$C$10004="Venta"))*(YEAR(MOVIMIENTOS!$B$5:$B$10004)=$B$3)*(MONTH(MOVIMIENTOS!$B$5:$B$10004)=12)*(MOVIMIENTOS!$P$5:$P$10004="Pagado")*MOVIMIENTOS!$O$5:$O$10004) | N5: =SUM(B5:M5)
A6: Financiero | B6: =SUMPRODUCT((MOVIMIENTOS!$H$5:$H$10004=$A6)*((MOVIMIENTOS!$C$5:$C$10004="Ingreso")+(MOVIMIENTOS!$C$5:$C$10004="Venta"))*(YEAR(MOVIMIENTOS!$B$5:$B$10004)=$B$3)*(MONTH(MOVIMIENTOS!$B$5:$B$10004)=1)*(MOVIMIENTOS!$P$5:$P$10004="Pagado")*MOVIMIENTOS!$O$5:$O$10004) | C6: =SUMPRODUCT((MOVIMIENTOS!$H$5:$H$10004=$A6)*((MOVIMIENTOS!$C$5:$C$10004="Ingreso")+(MOVIMIENTOS!$C$5:$C$10004="Venta"))*(YEAR(MOVIMIENTOS!$B$5:$B$10004)=$B$3)*(MONTH(MOVIMIENTOS!$B$5:$B$10004)=2)*(MOVIMIENTOS!$P$5:$P$10004="Pagado")*MOVIMIENTOS!$O$5:$O$10004) | D6: =SUMPRODUCT((MOVIMIENTOS!$H$5:$H$10004=$A6)*((MOVIMIENTOS!$C$5:$C$10004="Ingreso")+(MOVIMIENTOS!$C$5:$C$10004="Venta"))*(YEAR(MOVIMIENTOS!$B$5:$B$10004)=$B$3)*(MONTH(MOVIMIENTOS!$B$5:$B$10004)=3)*(MOVIMIENTOS!$P$5:$P$10004="Pagado")*MOVIMIENTOS!$O$5:$O$10004) | E6: =SUMPRODUCT((MOVIMIENTOS!$H$5:$H$10004=$A6)*((MOVIMIENTOS!$C$5:$C$10004="Ingreso")+(MOVIMIENTOS!$C$5:$C$10004="Venta"))*(YEAR(MOVIMIENTOS!$B$5:$B$10004)=$B$3)*(MONTH(MOVIMIENTOS!$B$5:$B$10004)=4)*(MOVIMIENTOS!$P$5:$P$10004="Pagado")*MOVIMIENTOS!$O$5:$O$10004) | F6: =SUMPRODUCT((MOVIMIENTOS!$H$5:$H$10004=$A6)*((MOVIMIENTOS!$C$5:$C$10004="Ingreso")+(MOVIMIENTOS!$C$5:$C$10004="Venta"))*(YEAR(MOVIMIENTOS!$B$5:$B$10004)=$B$3)*(MONTH(MOVIMIENTOS!$B$5:$B$10004)=5)*(MOVIMIENTOS!$P$5:$P$10004="Pagado")*MOVIMIENTOS!$O$5:$O$10004) | G6: =SUMPRODUCT((MOVIMIENTOS!$H$5:$H$10004=$A6)*((MOVIMIENTOS!$C$5:$C$10004="Ingreso")+(MOVIMIENTOS!$C$5:$C$10004="Venta"))*(YEAR(MOVIMIENTOS!$B$5:$B$10004)=$B$3)*(MONTH(MOVIMIENTOS!$B$5:$B$10004)=6)*(MOVIMIENTOS!$P$5:$P$10004="Pagado")*MOVIMIENTOS!$O$5:$O$10004) | H6: =SUMPRODUCT((MOVIMIENTOS!$H$5:$H$10004=$A6)*((MOVIMIENTOS!$C$5:$C$10004="Ingreso")+(MOVIMIENTOS!$C$5:$C$10004="Venta"))*(YEAR(MOVIMIENTOS!$B$5:$B$10004)=$B$3)*(MONTH(MOVIMIENTOS!$B$5:$B$10004)=7)*(MOVIMIENTOS!$P$5:$P$10004="Pagado")*MOVIMIENTOS!$O$5:$O$10004) | I6: =SUMPRODUCT((MOVIMIENTOS!$H$5:$H$10004=$A6)*((MOVIMIENTOS!$C$5:$C$10004="Ingreso")+(MOVIMIENTOS!$C$5:$C$10004="Venta"))*(YEAR(MOVIMIENTOS!$B$5:$B$10004)=$B$3)*(MONTH(MOVIMIENTOS!$B$5:$B$10004)=8)*(MOVIMIENTOS!$P$5:$P$10004="Pagado")*MOVIMIENTOS!$O$5:$O$10004) | J6: =SUMPRODUCT((MOVIMIENTOS!$H$5:$H$10004=$A6)*((MOVIMIENTOS!$C$5:$C$10004="Ingreso")+(MOVIMIENTOS!$C$5:$C$10004="Venta"))*(YEAR(MOVIMIENTOS!$B$5:$B$10004)=$B$3)*(MONTH(MOVIMIENTOS!$B$5:$B$10004)=9)*(MOVIMIENTOS!$P$5:$P$10004="Pagado")*MOVIMIENTOS!$O$5:$O$10004) | K6: =SUMPRODUCT((MOVIMIENTOS!$H$5:$H$10004=$A6)*((MOVIMIENTOS!$C$5:$C$10004="Ingreso")+(MOVIMIENTOS!$C$5:$C$10004="Venta"))*(YEAR(MOVIMIENTOS!$B$5:$B$10004)=$B$3)*(MONTH(MOVIMIENTOS!$B$5:$B$10004)=10)*(MOVIMIENTOS!$P$5:$P$10004="Pagado")*MOVIMIENTOS!$O$5:$O$10004) | L6: =SUMPRODUCT((MOVIMIENTOS!$H$5:$H$10004=$A6)*((MOVIMIENTOS!$C$5:$C$10004="Ingreso")+(MOVIMIENTOS!$C$5:$C$10004="Venta"))*(YEAR(MOVIMIENTOS!$B$5:$B$10004)=$B$3)*(MONTH(MOVIMIENTOS!$B$5:$B$10004)=11)*(MOVIMIENTOS!$P$5:$P$10004="Pagado")*MOVIMIENTOS!$O$5:$O$10004) | M6: =SUMPRODUCT((MOVIMIENTOS!$H$5:$H$10004=$A6)*((MOVIMIENTOS!$C$5:$C$10004="Ingreso")+(MOVIMIENTOS!$C$5:$C$10004="Venta"))*(YEAR(MOVIMIENTOS!$B$5:$B$10004)=$B$3)*(MONTH(MOVIMIENTOS!$B$5:$B$10004)=12)*(MOVIMIENTOS!$P$5:$P$10004="Pagado")*MOVIMIENTOS!$O$5:$O$10004) | N6: =SUM(B6:M6)
A7: Productos | B7: =SUMPRODUCT((MOVIMIENTOS!$H$5:$H$10004=$A7)*((MOVIMIENTOS!$C$5:$C$10004="Ingreso")+(MOVIMIENTOS!$C$5:$C$10004="Venta"))*(YEAR(MOVIMIENTOS!$B$5:$B$10004)=$B$3)*(MONTH(MOVIMIENTOS!$B$5:$B$10004)=1)*(MOVIMIENTOS!$P$5:$P$10004="Pagado")*MOVIMIENTOS!$O$5:$O$10004) | C7: =SUMPRODUCT((MOVIMIENTOS!$H$5:$H$10004=$A7)*((MOVIMIENTOS!$C$5:$C$10004="Ingreso")+(MOVIMIENTOS!$C$5:$C$10004="Venta"))*(YEAR(MOVIMIENTOS!$B$5:$B$10004)=$B$3)*(MONTH(MOVIMIENTOS!$B$5:$B$10004)=2)*(MOVIMIENTOS!$P$5:$P$10004="Pagado")*MOVIMIENTOS!$O$5:$O$10004) | D7: =SUMPRODUCT((MOVIMIENTOS!$H$5:$H$10004=$A7)*((MOVIMIENTOS!$C$5:$C$10004="Ingreso")+(MOVIMIENTOS!$C$5:$C$10004="Venta"))*(YEAR(MOVIMIENTOS!$B$5:$B$10004)=$B$3)*(MONTH(MOVIMIENTOS!$B$5:$B$10004)=3)*(MOVIMIENTOS!$P$5:$P$10004="Pagado")*MOVIMIENTOS!$O$5:$O$10004) | E7: =SUMPRODUCT((MOVIMIENTOS!$H$5:$H$10004=$A7)*((MOVIMIENTOS!$C$5:$C$10004="Ingreso")+(MOVIMIENTOS!$C$5:$C$10004="Venta"))*(YEAR(MOVIMIENTOS!$B$5:$B$10004)=$B$3)*(MONTH(MOVIMIENTOS!$B$5:$B$10004)=4)*(MOVIMIENTOS!$P$5:$P$10004="Pagado")*MOVIMIENTOS!$O$5:$O$10004) | F7: =SUMPRODUCT((MOVIMIENTOS!$H$5:$H$10004=$A7)*((MOVIMIENTOS!$C$5:$C$10004="Ingreso")+(MOVIMIENTOS!$C$5:$C$10004="Venta"))*(YEAR(MOVIMIENTOS!$B$5:$B$10004)=$B$3)*(MONTH(MOVIMIENTOS!$B$5:$B$10004)=5)*(MOVIMIENTOS!$P$5:$P$10004="Pagado")*MOVIMIENTOS!$O$5:$O$10004) | G7: =SUMPRODUCT((MOVIMIENTOS!$H$5:$H$10004=$A7)*((MOVIMIENTOS!$C$5:$C$10004="Ingreso")+(MOVIMIENTOS!$C$5:$C$10004="Venta"))*(YEAR(MOVIMIENTOS!$B$5:$B$10004)=$B$3)*(MONTH(MOVIMIENTOS!$B$5:$B$10004)=6)*(MOVIMIENTOS!$P$5:$P$10004="Pagado")*MOVIMIENTOS!$O$5:$O$10004) | H7: =SUMPRODUCT((MOVIMIENTOS!$H$5:$H$10004=$A7)*((MOVIMIENTOS!$C$5:$C$10004="Ingreso")+(MOVIMIENTOS!$C$5:$C$10004="Venta"))*(YEAR(MOVIMIENTOS!$B$5:$B$10004)=$B$3)*(MONTH(MOVIMIENTOS!$B$5:$B$10004)=7)*(MOVIMIENTOS!$P$5:$P$10004="Pagado")*MOVIMIENTOS!$O$5:$O$10004) | I7: =SUMPRODUCT((MOVIMIENTOS!$H$5:$H$10004=$A7)*((MOVIMIENTOS!$C$5:$C$10004="Ingreso")+(MOVIMIENTOS!$C$5:$C$10004="Venta"))*(YEAR(MOVIMIENTOS!$B$5:$B$10004)=$B$3)*(MONTH(MOVIMIENTOS!$B$5:$B$10004)=8)*(MOVIMIENTOS!$P$5:$P$10004="Pagado")*MOVIMIENTOS!$O$5:$O$10004) | J7: =SUMPRODUCT((MOVIMIENTOS!$H$5:$H$10004=$A7)*((MOVIMIENTOS!$C$5:$C$10004="Ingreso")+(MOVIMIENTOS!$C$5:$C$10004="Venta"))*(YEAR(MOVIMIENTOS!$B$5:$B$10004)=$B$3)*(MONTH(MOVIMIENTOS!$B$5:$B$10004)=9)*(MOVIMIENTOS!$P$5:$P$10004="Pagado")*MOVIMIENTOS!$O$5:$O$10004) | K7: =SUMPRODUCT((MOVIMIENTOS!$H$5:$H$10004=$A7)*((MOVIMIENTOS!$C$5:$C$10004="Ingreso")+(MOVIMIENTOS!$C$5:$C$10004="Venta"))*(YEAR(MOVIMIENTOS!$B$5:$B$10004)=$B$3)*(MONTH(MOVIMIENTOS!$B$5:$B$10004)=10)*(MOVIMIENTOS!$P$5:$P$10004="Pagado")*MOVIMIENTOS!$O$5:$O$10004) | L7: =SUMPRODUCT((MOVIMIENTOS!$H$5:$H$10004=$A7)*((MOVIMIENTOS!$C$5:$C$10004="Ingreso")+(MOVIMIENTOS!$C$5:$C$10004="Venta"))*(YEAR(MOVIMIENTOS!$B$5:$B$10004)=$B$3)*(MONTH(MOVIMIENTOS!$B$5:$B$10004)=11)*(MOVIMIENTOS!$P$5:$P$10004="Pagado")*MOVIMIENTOS!$O$5:$O$10004) | M7: =SUMPRODUCT((MOVIMIENTOS!$H$5:$H$10004=$A7)*((MOVIMIENTOS!$C$5:$C$10004="Ingreso")+(MOVIMIENTOS!$C$5:$C$10004="Venta"))*(YEAR(MOVIMIENTOS!$B$5:$B$10004)=$B$3)*(MONTH(MOVIMIENTOS!$B$5:$B$10004)=12)*(MOVIMIENTOS!$P$5:$P$10004="Pagado")*MOVIMIENTOS!$O$5:$O$10004) | N7: =SUM(B7:M7)
A8: TOTAL | B8: =SUM(B5:B7) | C8: =SUM(C5:C7) | D8: =SUM(D5:D7) | E8: =SUM(E5:E7) | F8: =SUM(F5:F7) | G8: =SUM(G5:G7) | H8: =SUM(H5:H7) | I8: =SUM(I5:I7) | ... N8: =SUM(N5:N7)

Sheet GASTOS
A1: GASTOS
A2: Detalle de Gasto/Compra agrupado por categoria y mes
A3: Año del reporte | B3: 2026
A4: Categoria | B4: Ene | C4: Feb | D4: Mar | E4: Abr | F4: May | G4: Jun | H4: Jul | I4: Ago | J4: Sep | K4: Oct | L4: Nov | M4: Dic | N4: Total
A5: Operacion | B5: =SUMPRODUCT((MOVIMIENTOS!$H$5:$H$10004=$A5)*((MOVIMIENTOS!$C$5:$C$10004="Gasto")+(MOVIMIENTOS!$C$5:$C$10004="Compra"))*(YEAR(MOVIMIENTOS!$B$5:$B$10004)=$B$3)*(MONTH(MOVIMIENTOS!$B$5:$B$10004)=1)*(MOVIMIENTOS!$P$5:$P$10004="Pagado")*MOVIMIENTOS!$O$5:$O$10004) | C5: =SUMPRODUCT((MOVIMIENTOS!$H$5:$H$10004=$A5)*((MOVIMIENTOS!$C$5:$C$10004="Gasto")+(MOVIMIENTOS!$C$5:$C$10004="Compra"))*(YEAR(MOVIMIENTOS!$B$5:$B$10004)=$B$3)*(MONTH(MOVIMIENTOS!$B$5:$B$10004)=2)*(MOVIMIENTOS!$P$5:$P$10004="Pagado")*MOVIMIENTOS!$O$5:$O$10004) | D5: =SUMPRODUCT((MOVIMIENTOS!$H$5:$H$10004=$A5)*((MOVIMIENTOS!$C$5:$C$10004="Gasto")+(MOVIMIENTOS!$C$5:$C$10004="Compra"))*(YEAR(MOVIMIENTOS!$B$5:$B$10004)=$B$3)*(MONTH(MOVIMIENTOS!$B$5:$B$10004)=3)*(MOVIMIENTOS!$P$5:$P$10004="Pagado")*MOVIMIENTOS!$O$5:$O$10004) | E5: =SUMPRODUCT((MOVIMIENTOS!$H$5:$H$10004=$A5)*((MOVIMIENTOS!$C$5:$C$10004="Gasto")+(MOVIMIENTOS!$C$5:$C$10004="Compra"))*(YEAR(MOVIMIENTOS!$B$5:$B$10004)=$B$3)*(MONTH(MOVIMIENTOS!$B$5:$B$10004)=4)*(MOVIMIENTOS!$P$5:$P$10004="Pagado")*MOVIMIENTOS!$O$5:$O$10004) | F5: =SUMPRODUCT((MOVIMIENTOS!$H$5:$H$10004=$A5)*((MOVIMIENTOS!$C$5:$C$10004="Gasto")+(MOVIMIENTOS!$C$5:$C$10004="Compra"))*(YEAR(MOVIMIENTOS!$B$5:$B$10004)=$B$3)*(MONTH(MOVIMIENTOS!$B$5:$B$10004)=5)*(MOVIMIENTOS!$P$5:$P$10004="Pagado")*MOVIMIENTOS!$O$5:$O$10004) | G5: =SUMPRODUCT((MOVIMIENTOS!$H$5:$H$10004=$A5)*((MOVIMIENTOS!$C$5:$C$10004="Gasto")+(MOVIMIENTOS!$C$5:$C$10004="Compra"))*(YEAR(MOVIMIENTOS!$B$5:$B$10004)=$B$3)*(MONTH(MOVIMIENTOS!$B$5:$B$10004)=6)*(MOVIMIENTOS!$P$5:$P$10004="Pagado")*MOVIMIENTOS!$O$5:$O$10004) | H5: =SUMPRODUCT((MOVIMIENTOS!$H$5:$H$10004=$A5)*((MOVIMIENTOS!$C$5:$C$10004="Gasto")+(MOVIMIENTOS!$C$5:$C$10004="Compra"))*(YEAR(MOVIMIENTOS!$B$5:$B$10004)=$B$3)*(MONTH(MOVIMIENTOS!$B$5:$B$10004)=7)*(MOVIMIENTOS!$P$5:$P$10004="Pagado")*MOVIMIENTOS!$O$5:$O$10004) | I5: =SUMPRODUCT((MOVIMIENTOS!$H$5:$H$10004=$A5)*((MOVIMIENTOS!$C$5:$C$10004="Gasto")+(MOVIMIENTOS!$C$5:$C$10004="Compra"))*(YEAR(MOVIMIENTOS!$B$5:$B$10004)=$B$3)*(MONTH(MOVIMIENTOS!$B$5:$B$10004)=8)*(MOVIMIENTOS!$P$5:$P$10004="Pagado")*MOVIMIENTOS!$O$5:$O$10004) | J5: =SUMPRODUCT((MOVIMIENTOS!$H$5:$H$10004=$A5)*((MOVIMIENTOS!$C$5:$C$10004="Gasto")+(MOVIMIENTOS!$C$5:$C$10004="Compra"))*(YEAR(MOVIMIENTOS!$B$5:$B$10004)=$B$3)*(MONTH(MOVIMIENTOS!$B$5:$B$10004)=9)*(MOVIMIENTOS!$P$5:$P$10004="Pagado")*MOVIMIENTOS!$O$5:$O$10004) | K5: =SUMPRODUCT((MOVIMIENTOS!$H$5:$H$10004=$A5)*((MOVIMIENTOS!$C$5:$C$10004="Gasto")+(MOVIMIENTOS!$C$5:$C$10004="Compra"))*(YEAR(MOVIMIENTOS!$B$5:$B$10004)=$B$3)*(MONTH(MOVIMIENTOS!$B$5:$B$10004)=10)*(MOVIMIENTOS!$P$5:$P$10004="Pagado")*MOVIMIENTOS!$O$5:$O$10004) | L5: =SUMPRODUCT((MOVIMIENTOS!$H$5:$H$10004=$A5)*((MOVIMIENTOS!$C$5:$C$10004="Gasto")+(MOVIMIENTOS!$C$5:$C$10004="Compra"))*(YEAR(MOVIMIENTOS!$B$5:$B$10004)=$B$3)*(MONTH(MOVIMIENTOS!$B$5:$B$10004)=11)*(MOVIMIENTOS!$P$5:$P$10004="Pagado")*MOVIMIENTOS!$O$5:$O$10004) | M5: =SUMPRODUCT((MOVIMIENTOS!$H$5:$H$10004=$A5)*((MOVIMIENTOS!$C$5:$C$10004="Gasto")+(MOVIMIENTOS!$C$5:$C$10004="Compra"))*(YEAR(MOVIMIENTOS!$B$5:$B$10004)=$B$3)*(MONTH(MOVIMIENTOS!$B$5:$B$10004)=12)*(MOVIMIENTOS!$P$5:$P$10004="Pagado")*MOVIMIENTOS!$O$5:$O$10004) | N5: =SUM(B5:M5)
A6: Administracion | B6: =SUMPRODUCT((MOVIMIENTOS!$H$5:$H$10004=$A6)*((MOVIMIENTOS!$C$5:$C$10004="Gasto")+(MOVIMIENTOS!$C$5:$C$10004="Compra"))*(YEAR(MOVIMIENTOS!$B$5:$B$10004)=$B$3)*(MONTH(MOVIMIENTOS!$B$5:$B$10004)=1)*(MOVIMIENTOS!$P$5:$P$10004="Pagado")*MOVIMIENTOS!$O$5:$O$10004) | C6: =SUMPRODUCT((MOVIMIENTOS!$H$5:$H$10004=$A6)*((MOVIMIENTOS!$C$5:$C$10004="Gasto")+(MOVIMIENTOS!$C$5:$C$10004="Compra"))*(YEAR(MOVIMIENTOS!$B$5:$B$10004)=$B$3)*(MONTH(MOVIMIENTOS!$B$5:$B$10004)=2)*(MOVIMIENTOS!$P$5:$P$10004="Pagado")*MOVIMIENTOS!$O$5:$O$10004) | D6: =SUMPRODUCT((MOVIMIENTOS!$H$5:$H$10004=$A6)*((MOVIMIENTOS!$C$5:$C$10004="Gasto")+(MOVIMIENTOS!$C$5:$C$10004="Compra"))*(YEAR(MOVIMIENTOS!$B$5:$B$10004)=$B$3)*(MONTH(MOVIMIENTOS!$B$5:$B$10004)=3)*(MOVIMIENTOS!$P$5:$P$10004="Pagado")*MOVIMIENTOS!$O$5:$O$10004) | E6: =SUMPRODUCT((MOVIMIENTOS!$H$5:$H$10004=$A6)*((MOVIMIENTOS!$C$5:$C$10004="Gasto")+(MOVIMIENTOS!$C$5:$C$10004="Compra"))*(YEAR(MOVIMIENTOS!$B$5:$B$10004)=$B$3)*(MONTH(MOVIMIENTOS!$B$5:$B$10004)=4)*(MOVIMIENTOS!$P$5:$P$10004="Pagado")*MOVIMIENTOS!$O$5:$O$10004) | F6: =SUMPRODUCT((MOVIMIENTOS!$H$5:$H$10004=$A6)*((MOVIMIENTOS!$C$5:$C$10004="Gasto")+(MOVIMIENTOS!$C$5:$C$10004="Compra"))*(YEAR(MOVIMIENTOS!$B$5:$B$10004)=$B$3)*(MONTH(MOVIMIENTOS!$B$5:$B$10004)=5)*(MOVIMIENTOS!$P$5:$P$10004="Pagado")*MOVIMIENTOS!$O$5:$O$10004) | G6: =SUMPRODUCT((MOVIMIENTOS!$H$5:$H$10004=$A6)*((MOVIMIENTOS!$C$5:$C$10004="Gasto")+(MOVIMIENTOS!$C$5:$C$10004="Compra"))*(YEAR(MOVIMIENTOS!$B$5:$B$10004)=$B$3)*(MONTH(MOVIMIENTOS!$B$5:$B$10004)=6)*(MOVIMIENTOS!$P$5:$P$10004="Pagado")*MOVIMIENTOS!$O$5:$O$10004) | H6: =SUMPRODUCT((MOVIMIENTOS!$H$5:$H$10004=$A6)*((MOVIMIENTOS!$C$5:$C$10004="Gasto")+(MOVIMIENTOS!$C$5:$C$10004="Compra"))*(YEAR(MOVIMIENTOS!$B$5:$B$10004)=$B$3)*(MONTH(MOVIMIENTOS!$B$5:$B$10004)=7)*(MOVIMIENTOS!$P$5:$P$10004="Pagado")*MOVIMIENTOS!$O$5:$O$10004) | I6: =SUMPRODUCT((MOVIMIENTOS!$H$5:$H$10004=$A6)*((MOVIMIENTOS!$C$5:$C$10004="Gasto")+(MOVIMIENTOS!$C$5:$C$10004="Compra"))*(YEAR(MOVIMIENTOS!$B$5:$B$10004)=$B$3)*(MONTH(MOVIMIENTOS!$B$5:$B$10004)=8)*(MOVIMIENTOS!$P$5:$P$10004="Pagado")*MOVIMIENTOS!$O$5:$O$10004) | J6: =SUMPRODUCT((MOVIMIENTOS!$H$5:$H$10004=$A6)*((MOVIMIENTOS!$C$5:$C$10004="Gasto")+(MOVIMIENTOS!$C$5:$C$10004="Compra"))*(YEAR(MOVIMIENTOS!$B$5:$B$10004)=$B$3)*(MONTH(MOVIMIENTOS!$B$5:$B$10004)=9)*(MOVIMIENTOS!$P$5:$P$10004="Pagado")*MOVIMIENTOS!$O$5:$O$10004) | K6: =SUMPRODUCT((MOVIMIENTOS!$H$5:$H$10004=$A6)*((MOVIMIENTOS!$C$5:$C$10004="Gasto")+(MOVIMIENTOS!$C$5:$C$10004="Compra"))*(YEAR(MOVIMIENTOS!$B$5:$B$10004)=$B$3)*(MONTH(MOVIMIENTOS!$B$5:$B$10004)=10)*(MOVIMIENTOS!$P$5:$P$10004="Pagado")*MOVIMIENTOS!$O$5:$O$10004) | L6: =SUMPRODUCT((MOVIMIENTOS!$H$5:$H$10004=$A6)*((MOVIMIENTOS!$C$5:$C$10004="Gasto")+(MOVIMIENTOS!$C$5:$C$10004="Compra"))*(YEAR(MOVIMIENTOS!$B$5:$B$10004)=$B$3)*(MONTH(MOVIMIENTOS!$B$5:$B$10004)=11)*(MOVIMIENTOS!$P$5:$P$10004="Pagado")*MOVIMIENTOS!$O$5:$O$10004) | M6: =SUMPRODUCT((MOVIMIENTOS!$H$5:$H$10004=$A6)*((MOVIMIENTOS!$C$5:$C$10004="Gasto")+(MOVIMIENTOS!$C$5:$C$10004="Compra"))*(YEAR(MOVIMIENTOS!$B$5:$B$10004)=$B$3)*(MONTH(MOVIMIENTOS!$B$5:$B$10004)=12)*(MOVIMIENTOS!$P$5:$P$10004="Pagado")*MOVIMIENTOS!$O$5:$O$10004) | N6: =SUM(B6:M6)
A7: Nomina | B7: =SUMPRODUCT((MOVIMIENTOS!$H$5:$H$10004=$A7)*((MOVIMIENTOS!$C$5:$C$10004="Gasto")+(MOVIMIENTOS!$C$5:$C$10004="Compra"))*(YEAR(MOVIMIENTOS!$B$5:$B$10004)=$B$3)*(MONTH(MOVIMIENTOS!$B$5:$B$10004)=1)*(MOVIMIENTOS!$P$5:$P$10004="Pagado")*MOVIMIENTOS!$O$5:$O$10004) | C7: =SUMPRODUCT((MOVIMIENTOS!$H$5:$H$10004=$A7)*((MOVIMIENTOS!$C$5:$C$10004="Gasto")+(MOVIMIENTOS!$C$5:$C$10004="Compra"))*(YEAR(MOVIMIENTOS!$B$5:$B$10004)=$B$3)*(MONTH(MOVIMIENTOS!$B$5:$B$10004)=2)*(MOVIMIENTOS!$P$5:$P$10004="Pagado")*MOVIMIENTOS!$O$5:$O$10004) | D7: =SUMPRODUCT((MOVIMIENTOS!$H$5:$H$10004=$A7)*((MOVIMIENTOS!$C$5:$C$10004="Gasto")+(MOVIMIENTOS!$C$5:$C$10004="Compra"))*(YEAR(MOVIMIENTOS!$B$5:$B$10004)=$B$3)*(MONTH(MOVIMIENTOS!$B$5:$B$10004)=3)*(MOVIMIENTOS!$P$5:$P$10004="Pagado")*MOVIMIENTOS!$O$5:$O$10004) | E7: =SUMPRODUCT((MOVIMIENTOS!$H$5:$H$10004=$A7)*((MOVIMIENTOS!$C$5:$C$10004="Gasto")+(MOVIMIENTOS!$C$5:$C$10004="Compra"))*(YEAR(MOVIMIENTOS!$B$5:$B$10004)=$B$3)*(MONTH(MOVIMIENTOS!$B$5:$B$10004)=4)*(MOVIMIENTOS!$P$5:$P$10004="Pagado")*MOVIMIENTOS!$O$5:$O$10004) | F7: =SUMPRODUCT((MOVIMIENTOS!$H$5:$H$10004=$A7)*((MOVIMIENTOS!$C$5:$C$10004="Gasto")+(MOVIMIENTOS!$C$5:$C$10004="Compra"))*(YEAR(MOVIMIENTOS!$B$5:$B$10004)=$B$3)*(MONTH(MOVIMIENTOS!$B$5:$B$10004)=5)*(MOVIMIENTOS!$P$5:$P$10004="Pagado")*MOVIMIENTOS!$O$5:$O$10004) | G7: =SUMPRODUCT((MOVIMIENTOS!$H$5:$H$10004=$A7)*((MOVIMIENTOS!$C$5:$C$10004="Gasto")+(MOVIMIENTOS!$C$5:$C$10004="Compra"))*(YEAR(MOVIMIENTOS!$B$5:$B$10004)=$B$3)*(MONTH(MOVIMIENTOS!$B$5:$B$10004)=6)*(MOVIMIENTOS!$P$5:$P$10004="Pagado")*MOVIMIENTOS!$O$5:$O$10004) | H7: =SUMPRODUCT((MOVIMIENTOS!$H$5:$H$10004=$A7)*((MOVIMIENTOS!$C$5:$C$10004="Gasto")+(MOVIMIENTOS!$C$5:$C$10004="Compra"))*(YEAR(MOVIMIENTOS!$B$5:$B$10004)=$B$3)*(MONTH(MOVIMIENTOS!$B$5:$B$10004)=7)*(MOVIMIENTOS!$P$5:$P$10004="Pagado")*MOVIMIENTOS!$O$5:$O$10004) | I7: =SUMPRODUCT((MOVIMIENTOS!$H$5:$H$10004=$A7)*((MOVIMIENTOS!$C$5:$C$10004="Gasto")+(MOVIMIENTOS!$C$5:$C$10004="Compra"))*(YEAR(MOVIMIENTOS!$B$5:$B$10004)=$B$3)*(MONTH(MOVIMIENTOS!$B$5:$B$10004)=8)*(MOVIMIENTOS!$P$5:$P$10004="Pagado")*MOVIMIENTOS!$O$5:$O$10004) | J7: =SUMPRODUCT((MOVIMIENTOS!$H$5:$H$10004=$A7)*((MOVIMIENTOS!$C$5:$C$10004="Gasto")+(MOVIMIENTOS!$C$5:$C$10004="Compra"))*(YEAR(MOVIMIENTOS!$B$5:$B$10004)=$B$3)*(MONTH(MOVIMIENTOS!$B$5:$B$10004)=9)*(MOVIMIENTOS!$P$5:$P$10004="Pagado")*MOVIMIENTOS!$O$5:$O$10004) | K7: =SUMPRODUCT((MOVIMIENTOS!$H$5:$H$10004=$A7)*((MOVIMIENTOS!$C$5:$C$10004="Gasto")+(MOVIMIENTOS!$C$5:$C$10004="Compra"))*(YEAR(MOVIMIENTOS!$B$5:$B$10004)=$B$3)*(MONTH(MOVIMIENTOS!$B$5:$B$10004)=10)*(MOVIMIENTOS!$P$5:$P$10004="Pagado")*MOVIMIENTOS!$O$5:$O$10004) | L7: =SUMPRODUCT((MOVIMIENTOS!$H$5:$H$10004=$A7)*((MOVIMIENTOS!$C$5:$C$10004="Gasto")+(MOVIMIENTOS!$C$5:$C$10004="Compra"))*(YEAR(MOVIMIENTOS!$B$5:$B$10004)=$B$3)*(MONTH(MOVIMIENTOS!$B$5:$B$10004)=11)*(MOVIMIENTOS!$P$5:$P$10004="Pagado")*MOVIMIENTOS!$O$5:$O$10004) | M7: =SUMPRODUCT((MOVIMIENTOS!$H$5:$H$10004=$A7)*((MOVIMIENTOS!$C$5:$C$10004="Gasto")+(MOVIMIENTOS!$C$5:$C$10004="Compra"))*(YEAR(MOVIMIENTOS!$B$5:$B$10004)=$B$3)*(MONTH(MOVIMIENTOS!$B$5:$B$10004)=12)*(MOVIMIENTOS!$P$5:$P$10004="Pagado")*MOVIMIENTOS!$O$5:$O$10004) | N7: =SUM(B7:M7)
A8: Inventario | B8: =SUMPRODUCT((MOVIMIENTOS!$H$5:$H$10004=$A8)*((MOVIMIENTOS!$C$5:$C$10004="Gasto")+(MOVIMIENTOS!$C$5:$C$10004="Compra"))*(YEAR(MOVIMIENTOS!$B$5:$B$10004)=$B$3)*(MONTH(MOVIMIENTOS!$B$5:$B$10004)=1)*(MOVIMIENTOS!$P$5:$P$10004="Pagado")*MOVIMIENTOS!$O$5:$O$10004) | C8: =SUMPRODUCT((MOVIMIENTOS!$H$5:$H$10004=$A8)*((MOVIMIENTOS!$C$5:$C$10004="Gasto")+(MOVIMIENTOS!$C$5:$C$10004="Compra"))*(YEAR(MOVIMIENTOS!$B$5:$B$10004)=$B$3)*(MONTH(MOVIMIENTOS!$B$5:$B$10004)=2)*(MOVIMIENTOS!$P$5:$P$10004="Pagado")*MOVIMIENTOS!$O$5:$O$10004) | D8: =SUMPRODUCT((MOVIMIENTOS!$H$5:$H$10004=$A8)*((MOVIMIENTOS!$C$5:$C$10004="Gasto")+(MOVIMIENTOS!$C$5:$C$10004="Compra"))*(YEAR(MOVIMIENTOS!$B$5:$B$10004)=$B$3)*(MONTH(MOVIMIENTOS!$B$5:$B$10004)=3)*(MOVIMIENTOS!$P$5:$P$10004="Pagado")*MOVIMIENTOS!$O$5:$O$10004) | E8: =SUMPRODUCT((MOVIMIENTOS!$H$5:$H$10004=$A8)*((MOVIMIENTOS!$C$5:$C$10004="Gasto")+(MOVIMIENTOS!$C$5:$C$10004="Compra"))*(YEAR(MOVIMIENTOS!$B$5:$B$10004)=$B$3)*(MONTH(MOVIMIENTOS!$B$5:$B$10004)=4)*(MOVIMIENTOS!$P$5:$P$10004="Pagado")*MOVIMIENTOS!$O$5:$O$10004) | F8: =SUMPRODUCT((MOVIMIENTOS!$H$5:$H$10004=$A8)*((MOVIMIENTOS!$C$5:$C$10004="Gasto")+(MOVIMIENTOS!$C$5:$C$10004="Compra"))*(YEAR(MOVIMIENTOS!$B$5:$B$10004)=$B$3)*(MONTH(MOVIMIENTOS!$B$5:$B$10004)=5)*(MOVIMIENTOS!$P$5:$P$10004="Pagado")*MOVIMIENTOS!$O$5:$O$10004) | G8: =SUMPRODUCT((MOVIMIENTOS!$H$5:$H$10004=$A8)*((MOVIMIENTOS!$C$5:$C$10004="Gasto")+(MOVIMIENTOS!$C$5:$C$10004="Compra"))*(YEAR(MOVIMIENTOS!$B$5:$B$10004)=$B$3)*(MONTH(MOVIMIENTOS!$B$5:$B$10004)=6)*(MOVIMIENTOS!$P$5:$P$10004="Pagado")*MOVIMIENTOS!$O$5:$O$10004) | H8: =SUMPRODUCT((MOVIMIENTOS!$H$5:$H$10004=$A8)*((MOVIMIENTOS!$C$5:$C$10004="Gasto")+(MOVIMIENTOS!$C$5:$C$10004="Compra"))*(YEAR(MOVIMIENTOS!$B$5:$B$10004)=$B$3)*(MONTH(MOVIMIENTOS!$B$5:$B$10004)=7)*(MOVIMIENTOS!$P$5:$P$10004="Pagado")*MOVIMIENTOS!$O$5:$O$10004) | I8: =SUMPRODUCT((MOVIMIENTOS!$H$5:$H$10004=$A8)*((MOVIMIENTOS!$C$5:$C$10004="Gasto")+(MOVIMIENTOS!$C$5:$C$10004="Compra"))*(YEAR(MOVIMIENTOS!$B$5:$B$10004)=$B$3)*(MONTH(MOVIMIENTOS!$B$5:$B$10004)=8)*(MOVIMIENTOS!$P$5:$P$10004="Pagado")*MOVIMIENTOS!$O$5:$O$10004) | J8: =SUMPRODUCT((MOVIMIENTOS!$H$5:$H$10004=$A8)*((MOVIMIENTOS!$C$5:$C$10004="Gasto")+(MOVIMIENTOS!$C$5:$C$10004="Compra"))*(YEAR(MOVIMIENTOS!$B$5:$B$10004)=$B$3)*(MONTH(MOVIMIENTOS!$B$5:$B$10004)=9)*(MOVIMIENTOS!$P$5:$P$10004="Pagado")*MOVIMIENTOS!$O$5:$O$10004) | K8: =SUMPRODUCT((MOVIMIENTOS!$H$5:$H$10004=$A8)*((MOVIMIENTOS!$C$5:$C$10004="Gasto")+(MOVIMIENTOS!$C$5:$C$10004="Compra"))*(YEAR(MOVIMIENTOS!$B$5:$B$10004)=$B$3)*(MONTH(MOVIMIENTOS!$B$5:$B$10004)=10)*(MOVIMIENTOS!$P$5:$P$10004="Pagado")*MOVIMIENTOS!$O$5:$O$10004) | L8: =SUMPRODUCT((MOVIMIENTOS!$H$5:$H$10004=$A8)*((MOVIMIENTOS!$C$5:$C$10004="Gasto")+(MOVIMIENTOS!$C$5:$C$10004="Compra"))*(YEAR(MOVIMIENTOS!$B$5:$B$10004)=$B$3)*(MONTH(MOVIMIENTOS!$B$5:$B$10004)=11)*(MOVIMIENTOS!$P$5:$P$10004="Pagado")*MOVIMIENTOS!$O$5:$O$10004) | M8: =SUMPRODUCT((MOVIMIENTOS!$H$5:$H$10004=$A8)*((MOVIMIENTOS!$C$5:$C$10004="Gasto")+(MOVIMIENTOS!$C$5:$C$10004="Compra"))*(YEAR(MOVIMIENTOS!$B$5:$B$10004)=$B$3)*(MONTH(MOVIMIENTOS!$B$5:$B$10004)=12)*(MOVIMIENTOS!$P$5:$P$10004="Pagado")*MOVIMIENTOS!$O$5:$O$10004) | N8: =SUM(B8:M8)
A9: Activos | B9: =SUMPRODUCT((MOVIMIENTOS!$H$5:$H$10004=$A9)*((MOVIMIENTOS!$C$5:$C$10004="Gasto")+(MOVIMIENTOS!$C$5:$C$10004="Compra"))*(YEAR(MOVIMIENTOS!$B$5:$B$10004)=$B$3)*(MONTH(MOVIMIENTOS!$B$5:$B$10004)=1)*(MOVIMIENTOS!$P$5:$P$10004="Pagado")*MOVIMIENTOS!$O$5:$O$10004) | C9: =SUMPRODUCT((MOVIMIENTOS!$H$5:$H$10004=$A9)*((MOVIMIENTOS!$C$5:$C$10004="Gasto")+(MOVIMIENTOS!$C$5:$C$10004="Compra"))*(YEAR(MOVIMIENTOS!$B$5:$B$10004)=$B$3)*(MONTH(MOVIMIENTOS!$B$5:$B$10004)=2)*(MOVIMIENTOS!$P$5:$P$10004="Pagado")*MOVIMIENTOS!$O$5:$O$10004) | D9: =SUMPRODUCT((MOVIMIENTOS!$H$5:$H$10004=$A9)*((MOVIMIENTOS!$C$5:$C$10004="Gasto")+(MOVIMIENTOS!$C$5:$C$10004="Compra"))*(YEAR(MOVIMIENTOS!$B$5:$B$10004)=$B$3)*(MONTH(MOVIMIENTOS!$B$5:$B$10004)=3)*(MOVIMIENTOS!$P$5:$P$10004="Pagado")*MOVIMIENTOS!$O$5:$O$10004) | E9: =SUMPRODUCT((MOVIMIENTOS!$H$5:$H$10004=$A9)*((MOVIMIENTOS!$C$5:$C$10004="Gasto")+(MOVIMIENTOS!$C$5:$C$10004="Compra"))*(YEAR(MOVIMIENTOS!$B$5:$B$10004)=$B$3)*(MONTH(MOVIMIENTOS!$B$5:$B$10004)=4)*(MOVIMIENTOS!$P$5:$P$10004="Pagado")*MOVIMIENTOS!$O$5:$O$10004) | F9: =SUMPRODUCT((MOVIMIENTOS!$H$5:$H$10004=$A9)*((MOVIMIENTOS!$C$5:$C$10004="Gasto")+(MOVIMIENTOS!$C$5:$C$10004="Compra"))*(YEAR(MOVIMIENTOS!$B$5:$B$10004)=$B$3)*(MONTH(MOVIMIENTOS!$B$5:$B$10004)=5)*(MOVIMIENTOS!$P$5:$P$10004="Pagado")*MOVIMIENTOS!$O$5:$O$10004) | G9: =SUMPRODUCT((MOVIMIENTOS!$H$5:$H$10004=$A9)*((MOVIMIENTOS!$C$5:$C$10004="Gasto")+(MOVIMIENTOS!$C$5:$C$10004="Compra"))*(YEAR(MOVIMIENTOS!$B$5:$B$10004)=$B$3)*(MONTH(MOVIMIENTOS!$B$5:$B$10004)=6)*(MOVIMIENTOS!$P$5:$P$10004="Pagado")*MOVIMIENTOS!$O$5:$O$10004) | H9: =SUMPRODUCT((MOVIMIENTOS!$H$5:$H$10004=$A9)*((MOVIMIENTOS!$C$5:$C$10004="Gasto")+(MOVIMIENTOS!$C$5:$C$10004="Compra"))*(YEAR(MOVIMIENTOS!$B$5:$B$10004)=$B$3)*(MONTH(MOVIMIENTOS!$B$5:$B$10004)=7)*(MOVIMIENTOS!$P$5:$P$10004="Pagado")*MOVIMIENTOS!$O$5:$O$10004) | I9: =SUMPRODUCT((MOVIMIENTOS!$H$5:$H$10004=$A9)*((MOVIMIENTOS!$C$5:$C$10004="Gasto")+(MOVIMIENTOS!$C$5:$C$10004="Compra"))*(YEAR(MOVIMIENTOS!$B$5:$B$10004)=$B$3)*(MONTH(MOVIMIENTOS!$B$5:$B$10004)=8)*(MOVIMIENTOS!$P$5:$P$10004="Pagado")*MOVIMIENTOS!$O$5:$O$10004) | J9: =SUMPRODUCT((MOVIMIENTOS!$H$5:$H$10004=$A9)*((MOVIMIENTOS!$C$5:$C$10004="Gasto")+(MOVIMIENTOS!$C$5:$C$10004="Compra"))*(YEAR(MOVIMIENTOS!$B$5:$B$10004)=$B$3)*(MONTH(MOVIMIENTOS!$B$5:$B$10004)=9)*(MOVIMIENTOS!$P$5:$P$10004="Pagado")*MOVIMIENTOS!$O$5:$O$10004) | K9: =SUMPRODUCT((MOVIMIENTOS!$H$5:$H$10004=$A9)*((MOVIMIENTOS!$C$5:$C$10004="Gasto")+(MOVIMIENTOS!$C$5:$C$10004="Compra"))*(YEAR(MOVIMIENTOS!$B$5:$B$10004)=$B$3)*(MONTH(MOVIMIENTOS!$B$5:$B$10004)=10)*(MOVIMIENTOS!$P$5:$P$10004="Pagado")*MOVIMIENTOS!$O$5:$O$10004) | L9: =SUMPRODUCT((MOVIMIENTOS!$H$5:$H$10004=$A9)*((MOVIMIENTOS!$C$5:$C$10004="Gasto")+(MOVIMIENTOS!$C$5:$C$10004="Compra"))*(YEAR(MOVIMIENTOS!$B$5:$B$10004)=$B$3)*(MONTH(MOVIMIENTOS!$B$5:$B$10004)=11)*(MOVIMIENTOS!$P$5:$P$10004="Pagado")*MOVIMIENTOS!$O$5:$O$10004) | M9: =SUMPRODUCT((MOVIMIENTOS!$H$5:$H$10004=$A9)*((MOVIMIENTOS!$C$5:$C$10004="Gasto")+(MOVIMIENTOS!$C$5:$C$10004="Compra"))*(YEAR(MOVIMIENTOS!$B$5:$B$10004)=$B$3)*(MONTH(MOVIMIENTOS!$B$5:$B$10004)=12)*(MOVIMIENTOS!$P$5:$P$10004="Pagado")*MOVIMIENTOS!$O$5:$O$10004) | N9: =SUM(B9:M9)
