Workbook
Name Lst_Categoria: 'CATEGORIAS'!$C$5:$C$1004
Name Lst_Cuenta: 'CUENTAS'!$B$5:$B$504
Name Lst_EstadoDocumento: "Validado,Pendiente,Error,Revision Manual,Duplicado"
Name Lst_EstadoMovimiento: "Pendiente,Pagado,Anulado"
Name Lst_EstadoPagoCobro: "Pendiente,Aplicado,Anulado"
Name Lst_MedioPago: MEDIOS_PAGO!$B$5:$B$1004
Name Lst_MetodoExtraccion: "XML,PDF,OCR,Manual,IA"
Name Lst_TerceroNombre: TERCEROS!$C$5:$C$2004
Name Lst_TipoArchivo: "PDF,JPG,PNG,XML,CSV,Otro"
Name Lst_TipoDocumentoNombre: TIPOS_DOCUMENTOS!$B$5:$B$1004
Name Lst_TipoMovimiento: "Ingreso,Gasto,Compra,Venta,Otro"
Name Lst_TipoTercero: "Cliente,Proveedor,Empleado,Socio,Entidad publica,Otro"

Sheet INICIO
A1: SISTEMA FINANCIERO
A2: Inicio rápido | Configure la empresa, registre operaciones y revise resultados
A4: TAREAS FRECUENTES
A6: 1. CONFIGURAR EMPRESA | F6: 2. REGISTRAR MOVIMIENTO
A7: Actualice datos, moneda y parámetros. | F7: Capture ingreso, gasto, compra o venta.
A10: 3. ASISTENTE LOCAL | F10: 4. REVISAR DOCUMENTOS
A11: Reciba una sugerencia y revísela. | F11: Consulte soportes y complete datos.
A14: 5. VER INDICADORES | F14: 6. ABRIR REPORTES
A15: Filtre ingresos, gastos y pendientes. | F15: Consulte periodos mensual y anual.
A18: PRIMEROS PASOS
A19: 1. Configure empresa, categorías, cuentas y terceros.
A20: 2. Registre una operación o use el asistente para clasificar el concepto.
A21: 3. Revise los indicadores y conserve el soporte relacionado.
A23: El libro XLSX permite captura, fórmulas y sugerencias locales. La importación de archivos, lectura XML y altas automáticas requieren la copia XLSM con los módulos VBA instalados.
A26: Ver todos los módulos | F26: Editar reglas del asistente

Sheet DASHBOARD
A1: DASHBOARD
A2: Indicadores financieros - se actualiza automaticamente desde MOVIMIENTOS y DOCUMENTOS
A4: FILTROS
A5: Anio (vacio = todos)
A6: Mes (1-12, vacio = todos)
A7: Tipo (vacio = todos)
A8: Categoria (vacio = todos)
A9: Tercero (vacio = todos)
A10: Cuenta (vacio = todos)
A11: Estado (vacio = todos)
A13: INDICADORES
A14: Ingresos | B14: =SUMPRODUCT(((MOVIMIENTOS!$C$5:$C$10004="Ingreso")+(MOVIMIENTOS!$C$5:$C$10004="Venta"))*((($B$11="")*(MOVIMIENTOS!$P$5:$P$10004="Pagado"))+(($B$11<>"")*(MOVIMIENTOS!$P$5:$P$10004=$B$11)))*(($B$5="")+(YEAR(MOVIMIENTOS!$B$5:$B$10004)=$B$5))*(($B$6="")+(MONTH(MOVIMIENTOS!$B$5:$B$10004)=$B$6))*(($B$7="")+(MOVIMIENTOS!$C$5:$C$10004=$B$7))*(($B$8="")+(MOVIMIENTOS!$H$5:$H$10004=$B$8))*(($B$9="")+(MOVIMIENTOS!$E$5:$E$10004=$B$9))*(($B$10="")+(MOVIMIENTOS!$K$5:$K$10004=$B$10))*MOVIMIENTOS!$O$5:$O$10004) -> 0
A15: Gastos | B15: =SUMPRODUCT(((MOVIMIENTOS!$C$5:$C$10004="Gasto")+(MOVIMIENTOS!$C$5:$C$10004="Compra"))*((($B$11="")*(MOVIMIENTOS!$P$5:$P$10004="Pagado"))+(($B$11<>"")*(MOVIMIENTOS!$P$5:$P$10004=$B$11)))*(($B$5="")+(YEAR(MOVIMIENTOS!$B$5:$B$10004)=$B$5))*(($B$6="")+(MONTH(MOVIMIENTOS!$B$5:$B$10004)=$B$6))*(($B$7="")+(MOVIMIENTOS!$C$5:$C$10004=$B$7))*(($B$8="")+(MOVIMIENTOS!$H$5:$H$10004=$B$8))*(($B$9="")+(MOVIMIENTOS!$E$5:$E$10004=$B$9))*(($B$10="")+(MOVIMIENTOS!$K$5:$K$10004=$B$10))*MOVIMIENTOS!$O$5:$O$10004) -> 0
A16: Flujo Neto | B16: =B14-B15 -> 0
A17: Cuentas por Cobrar | B17: =SUMPRODUCT(((MOVIMIENTOS!$C$5:$C$10004="Ingreso")+(MOVIMIENTOS!$C$5:$C$10004="Venta"))*(($B$5="")+(YEAR(MOVIMIENTOS!$B$5:$B$10004)=$B$5))*(($B$6="")+(MONTH(MOVIMIENTOS!$B$5:$B$10004)=$B$6))*(($B$7="")+(MOVIMIENTOS!$C$5:$C$10004=$B$7))*(($B$8="")+(MOVIMIENTOS!$H$5:$H$10004=$B$8))*(($B$9="")+(MOVIMIENTOS!$E$5:$E$10004=$B$9))*(($B$10="")+(MOVIMIENTOS!$K$5:$K$10004=$B$10))*((($B$11="")+($B$11="Pendiente"))*(MOVIMIENTOS!$P$5:$P$10004="Pendiente"))*MOVIMIENTOS!$O$5:$O$10004) -> 0
A18: Cuentas por Pagar | B18: =SUMPRODUCT(((MOVIMIENTOS!$C$5:$C$10004="Gasto")+(MOVIMIENTOS!$C$5:$C$10004="Compra"))*(($B$5="")+(YEAR(MOVIMIENTOS!$B$5:$B$10004)=$B$5))*(($B$6="")+(MONTH(MOVIMIENTOS!$B$5:$B$10004)=$B$6))*(($B$7="")+(MOVIMIENTOS!$C$5:$C$10004=$B$7))*(($B$8="")+(MOVIMIENTOS!$H$5:$H$10004=$B$8))*(($B$9="")+(MOVIMIENTOS!$E$5:$E$10004=$B$9))*(($B$10="")+(MOVIMIENTOS!$K$5:$K$10004=$B$10))*((($B$11="")+($B$11="Pendiente"))*(MOVIMIENTOS!$P$5:$P$10004="Pendiente"))*MOVIMIENTOS!$O$5:$O$10004) -> 0
A19: Impuestos Recaudados/Pagados | B19: =SUMPRODUCT(((($B$11="")*(MOVIMIENTOS!$P$5:$P$10004="Pagado"))+(($B$11<>"")*(MOVIMIENTOS!$P$5:$P$10004=$B$11)))*(($B$5="")+(YEAR(MOVIMIENTOS!$B$5:$B$10004)=$B$5))*(($B$6="")+(MONTH(MOVIMIENTOS!$B$5:$B$10004)=$B$6))*(($B$7="")+(MOVIMIENTOS!$C$5:$C$10004=$B$7))*(($B$8="")+(MOVIMIENTOS!$H$5:$H$10004=$B$8))*(($B$9="")+(MOVIMIENTOS!$E$5:$E$10004=$B$9))*(($B$10="")+(MOVIMIENTOS!$K$5:$K$10004=$B$10))*MOVIMIENTOS!$M$5:$M$10004) -> 0
A20: Documentos Registrados | B20: =SUMPRODUCT((($B$5="")+(YEAR(DOCUMENTOS!$B$5:$B$10004)=$B$5))*(($B$6="")+(MONTH(DOCUMENTOS!$B$5:$B$10004)=$B$6))*(($B$9="")+(DOCUMENTOS!$E$5:$E$10004=$B$9))*(DOCUMENTOS!$L$5:$L$10004="Validado")) -> 0
A21: Documentos Pendientes | B21: =SUMPRODUCT((($B$5="")+(YEAR(DOCUMENTOS!$B$5:$B$10004)=$B$5))*(($B$6="")+(MONTH(DOCUMENTOS!$B$5:$B$10004)=$B$6))*(($B$9="")+(DOCUMENTOS!$E$5:$E$10004=$B$9))*(((DOCUMENTOS!$L$5:$L$10004="Pendiente")+(DOCUMENTOS!$L$5:$L$10004="Revision Manual")))) -> 0
A22: Documentos con Error | B22: =SUMPRODUCT((($B$5="")+(YEAR(DOCUMENTOS!$B$5:$B$10004)=$B$5))*(($B$6="")+(MONTH(DOCUMENTOS!$B$5:$B$10004)=$B$6))*(($B$9="")+(DOCUMENTOS!$E$5:$E$10004=$B$9))*(((DOCUMENTOS!$L$5:$L$10004="Error")+(DOCUMENTOS!$L$5:$L$10004="Duplicado")))) -> 0
A24: Tipo/Categoria/Cuenta filtran movimientos; los conteos de documentos usan Año, Mes y Tercero.
A25: Para Anio/Mes vacios se muestran todos los periodos.

Sheet MENU
A1: SISTEMA FINANCIERO EMPRESARIAL
A2: Plataforma configurable de gestion financiera - Colombia
A4: Navegacion rapida (Ctrl+clic en Excel Desktop, o clic simple segun version):
A6: INICIO
A7: CONFIGURAR EMPRESA
A8: PARAMETROS
A9: CATEGORIAS
A10: IMPUESTOS
A11: CUENTAS
A12: TIPOS DE DOCUMENTO
A13: TERCEROS
A14: ASISTENTE DE CLASIFICACION
... A27: Ejecutar con Alt+F8, o asignar a un boton: Insertar > Formularios > Boton, dibujar, elegir el macro y pulsar Aceptar.
A29: Macro | B29: Que hace
A30: Menu_ImportarDocumento | B30: Copia el soporte y extrae campos estructurados si es XML UBL
A31: Menu_ExtraerXMLDocumentoActivo | B31: Relee el XML UBL de la fila DOCUMENTOS seleccionada
A32: Menu_ConfirmarRevisionXMLDocumentoActivo | B32: Confirma la revisión humana del XML seleccionado
A33: Menu_RenombrarArchivoDocumentoActivo | B33: Renombra en disco el archivo de la fila DOCUMENTOS donde este el cursor
A34: Menu_NuevoMovimiento | B34: Inserta una fila nueva en MOVIMIENTOS con ID y fecha automaticos
A35: Menu_NuevoDocumento | B35: Inserta una fila nueva en DOCUMENTOS con ID automatico
A36: Menu_NuevoTercero | B36: Inserta una fila nueva en TERCEROS con ID automatico
A37: Menu_NuevoPago | B37: Inserta una fila nueva en PAGOS con ID automatico
A38: Menu_NuevoCobro | B38: Inserta una fila nueva en COBROS con ID automatico
A39: Menu_ValidarTodo | B39: Valida MOVIMIENTOS, DOCUMENTOS (incl. duplicados) y TERCEROS (NIT duplicado)
A40: Menu_ActualizarReportes | B40: Recalcula el libro y repuebla CXC/CXP desde MOVIMIENTOS pendientes

Sheet EMPRESA
A1: EMPRESA
A2: Datos de la empresa - editar libremente, no usar en formulas de otras hojas
A4: Campo | B4: Valor
A5: NombreEmpresa | B5: Empresa Ejemplo S.A.S.
A6: NIT | B6: 900000000-1
A7: RegimenTributario | B7: Configurar (Comun / No responsable de IVA / Simple / etc.)
A8: ActividadEconomica | B8: Configurar codigo CIIU
A9: ResponsableIVA | B9: No
A10: DireccionPrincipal
A11: Ciudad
A12: Telefono
A13: Email
A14: MonedaPrincipal | B14: COP
A15: AnioFiscalInicioMes | B15: Enero
A16: RutaRaizArchivos
A17: LogoRuta

Sheet PARAMETROS
A1: PARAMETROS
A2: Parametros generales del sistema - configurables sin tocar formulas
A4: Codigo | B4: Parametro | C4: Valor | D4: Tipo | E4: Descripcion
A5: PAR-001 | B5: DECIMALES_MONEDA | C5: 0 | D5: Numero | E5: Decimales para valores monetarios
A6: PAR-002 | B6: FORMATO_FECHA | C6: dd/mm/aaaa | D6: Texto | E6: Formato de fecha estandar
A7: PAR-003 | B7: PREFIJO_MOVIMIENTO | C7: MOV- | D7: Texto | E7: Prefijo para ID de movimientos
A8: PAR-004 | B8: PREFIJO_DOCUMENTO | C8: DOC- | D8: Texto | E8: Prefijo para ID de documentos
A9: PAR-005 | B9: UMBRAL_DIAS_DUPLICADO | C9: 5 | D9: Numero | E9: Dias de tolerancia para sugerir posible duplicado
A10: PAR-006 | B10: RUTA_DOCUMENTOS | C10: Documentos | D10: Texto | E10: Ruta relativa a la carpeta del libro o ruta absoluta de soportes
A11: PAR-007 | B11: MODO_COMPATIBILIDAD | C11: COMPATIBLE | D11: Texto | E11: COMPATIBLE (Excel 2019) o MODERNO

Sheet CATEGORIAS
A1: CATEGORIAS
A2: Clasificacion financiera - editable, no ligada a formulas ni VBA
A4: Codigo | B4: Tipo | C4: Categoria | D4: Subcategoria | E4: Activa | F4: Descripcion
A5: ING-001 | B5: Ingreso | C5: Ventas | D5: Productos | E5: Si
A6: ING-002 | B6: Ingreso | C6: Ventas | D6: Servicios | E6: Si
A7: ING-003 | B7: Ingreso | C7: Financiero | D7: Rendimientos | E7: Si
A8: GAS-001 | B8: Gasto | C8: Operacion | D8: Servicios publicos | E8: Si
A9: GAS-002 | B9: Gasto | C9: Operacion | D9: Suministros | E9: Si
A10: GAS-003 | B10: Gasto | C10: Administracion | D10: Software | E10: Si
A11: GAS-004 | B11: Gasto | C11: Administracion | D11: Arriendo | E11: Si
A12: GAS-005 | B12: Gasto | C12: Nomina | D12: Salarios | E12: Si
A13: COM-001 | B13: Compra | C13: Inventario | D13: Mercancia | E13: Si
A14: COM-002 | B14: Compra | C14: Activos | D14: Tecnologia | E14: Si
A15: VEN-001 | B15: Venta | C15: Productos | D15: General | E15: Si
A16: OTR-001 | B16: Otro | C16: Sin clasificar | D16: Sin clasificar | E16: Si | F16: Usar temporalmente y reclasificar

Sheet IMPUESTOS
A1: IMPUESTOS
A2: Impuestos y retenciones - VERIFICAR PORCENTAJES VIGENTES ANTES DE USAR
A4: Codigo | B4: Impuesto | C4: Porcentaje | D4: Tipo | E4: Base | F4: CuentaAsociada | G4: Activo | H4: Observaciones
A5: IVA-001 | B5: IVA general | C5: 0 | D5: Impuesto | E5: Subtotal | G5: Si | H5: Configurar segun normativa DIAN/municipal vigente
A6: RET-001 | B6: Retencion en la fuente - Servicios | C6: 0 | D6: Retencion | E6: Subtotal | G6: Si | H6: Configurar segun normativa DIAN/municipal vigente
A7: RET-002 | B7: Retencion en la fuente - Compras | C7: 0 | D7: Retencion | E7: Subtotal | G7: Si | H7: Configurar segun normativa DIAN/municipal vigente
A8: RET-003 | B8: ReteICA | C8: 0 | D8: Retencion | E8: Subtotal | G8: Si | H8: Configurar segun normativa DIAN/municipal vigente
A9: IC-001 | B9: Impuesto de Industria y Comercio (ICA) | C9: 0 | D9: Impuesto | E9: Ingresos | G9: Si | H9: Configurar segun normativa DIAN/municipal vigente

Sheet TIPOS_DOCUMENTOS
A1: TIPOS_DOCUMENTOS
A2: Tipos de documento soportados - ampliable
A4: Codigo | B4: TipoDocumento | C4: Prefijo | D4: RequiereCUFE | E4: Activo | F4: Descripcion
A5: TD-01 | B5: Factura electronica | C5: FE | D5: Si | E5: Si
A6: TD-02 | B6: Documento equivalente | C6: DE | D6: No | E6: Si
A7: TD-03 | B7: Documento soporte | C7: DS | D7: No | E7: Si | F7: Compras a no obligados a facturar
A8: TD-04 | B8: Nota credito | C8: NC | D8: Si | E8: Si
A9: TD-05 | B9: Nota debito | C9: ND | D9: Si | E9: Si
A10: TD-06 | B10: Recibo | C10: RC | D10: No | E10: Si
A11: TD-07 | B11: Comprobante | C11: CO | D11: No | E11: Si
A12: TD-08 | B12: Extracto bancario | C12: EB | D12: No | E12: Si
A13: TD-09 | B13: Nomina | C13: NM | D13: No | E13: Si
A14: TD-10 | B14: Contrato | C14: CT | D14: No | E14: Si
A15: TD-11 | B15: Otro | C15: OT | D15: No | E15: Si

Sheet ESTADOS
A1: ESTADOS
A2: Catalogo de estados por ambito - referencia; los desplegables usan listas fijas por ambito
A4: Codigo | B4: Estado | C4: Ambito | D4: Activo | E4: Descripcion
A5: EST-01 | B5: Pendiente | C5: Movimiento | D5: Si
A6: EST-02 | B6: Pagado | C6: Movimiento | D6: Si
A7: EST-03 | B7: Anulado | C7: Movimiento | D7: Si
A8: EST-04 | B8: Validado | C8: Documento | D8: Si
A9: EST-05 | B9: Pendiente | C9: Documento | D9: Si
A10: EST-06 | B10: Error | C10: Documento | D10: Si
A11: EST-07 | B11: Revision Manual | C11: Documento | D11: Si
A12: EST-08 | B12: Duplicado | C12: Documento | D12: Si
A13: EST-09 | B13: Pendiente | C13: Pago/Cobro | D13: Si
A14: EST-10 | B14: Aplicado | C14: Pago/Cobro | D14: Si
A15: EST-11 | B15: Anulado | C15: Pago/Cobro | D15: Si

Sheet MEDIOS_PAGO
A1: MEDIOS_PAGO
A4: Codigo | B4: MedioPago | C4: Activo | D4: Descripcion
A5: MP-01 | B5: Efectivo | C5: Si
A6: MP-02 | B6: Transferencia bancaria | C6: Si
A7: MP-03 | B7: Tarjeta debito | C7: Si
A8: MP-04 | B8: Tarjeta credito | C8: Si
A9: MP-05 | B9: Cheque | C9: Si
A10: MP-06 | B10: Billetera digital | C10: Si
A11: MP-07 | B11: Otro | C11: Si

Sheet USUARIOS_ROLES
A1: USUARIOS_ROLES
A2: Administracion de usuarios - control de acceso logico (no reemplaza proteccion de Excel)
A4: ID | B4: Usuario | C4: Rol | D4: Email | E4: Activo | F4: Observaciones
A5: USR-001 | B5: Administrador | C5: Administrador | E5: Si | F5: Acceso total
A6: USR-002 | B6: Contador | C6: Contador | E6: Si | F6: Registro y validacion contable
A7: USR-003 | B7: Auxiliar | C7: Auxiliar | E7: Si | F7: Digitacion y digitalizacion
A8: USR-004 | B8: Consulta | C8: Consulta | E8: Si | F8: Solo lectura de reportes

Sheet TERCEROS
A1: TERCEROS
A2: Base unica de clientes, proveedores, empleados, socios y entidades
A4: ID | B4: Tipo | C4: NombreRazonSocial | D4: NIT_ID | E4: Contacto | F4: Email | G4: Telefono | H4: Direccion | I4: Ciudad | J4: Estado | K4: Observaciones | L4: ClaveDuplicado
J5: Activo | L5: =IF(D5="","",TRIM(UPPER(D5)))
J6: Activo | L6: =IF(D6="","",TRIM(UPPER(D6)))
J7: Activo | L7: =IF(D7="","",TRIM(UPPER(D7)))
J8: Activo | L8: =IF(D8="","",TRIM(UPPER(D8)))
J9: Activo | L9: =IF(D9="","",TRIM(UPPER(D9)))
J10: Activo | L10: =IF(D10="","",TRIM(UPPER(D10)))
J11: Activo | L11: =IF(D11="","",TRIM(UPPER(D11)))
J12: Activo | L12: =IF(D12="","",TRIM(UPPER(D12)))
J13: Activo | L13: =IF(D13="","",TRIM(UPPER(D13)))
J14: Activo | L14: =IF(D14="","",TRIM(UPPER(D14)))
J15: Activo | L15: =IF(D15="","",TRIM(UPPER(D15)))
J16: Activo | L16: =IF(D16="","",TRIM(UPPER(D16)))
... J34: Activo | L34: =IF(D34="","",TRIM(UPPER(D34)))

Sheet DOCUMENTOS
A1: DOCUMENTOS
A2: Soportes digitalizados: facturas, recibos, extractos y demas documentos
A4: ID | B4: Fecha | C4: TipoDocumento | D4: Numero | E4: Tercero | F4: Identificacion | G4: Subtotal | H4: Impuestos | I4: Retenciones | J4: Total | K4: CUFE_Referencia | L4: Estado | M4: RutaArchivo | N4: NombreArchivo | O4: TipoArchivo | P4: FechaExtraccion | Q4: MetodoExtraccion | R4: Confianza | S4: Observaciones

Sheet MOVIMIENTOS
A1: MOVIMIENTOS
A2: Tabla principal: ingresos, gastos, compras, ventas y otros movimientos
A4: ID | B4: Fecha | C4: Tipo | D4: Documento | E4: Tercero | F4: NIT_ID | G4: Concepto | H4: Categoria | I4: Subcategoria | J4: MedioPago | K4: Cuenta | L4: Subtotal | M4: Impuestos | N4: Retenciones | O4: Total | P4: Estado | Q4: SoporteID | R4: Observaciones
O5: =IF(L5="",0,L5+M5-N5) -> 0
O6: =IF(L6="",0,L6+M6-N6) -> 0
O7: =IF(L7="",0,L7+M7-N7) -> 0
O8: =IF(L8="",0,L8+M8-N8) -> 0
O9: =IF(L9="",0,L9+M9-N9) -> 0
O10: =IF(L10="",0,L10+M10-N10) -> 0
O11: =IF(L11="",0,L11+M11-N11) -> 0
O12: =IF(L12="",0,L12+M12-N12) -> 0
O13: =IF(L13="",0,L13+M13-N13) -> 0
O14: =IF(L14="",0,L14+M14-N14) -> 0
O15: =IF(L15="",0,L15+M15-N15) -> 0
O16: =IF(L16="",0,L16+M16-N16) -> 0
... O64: =IF(L64="",0,L64+M64-N64) -> 0

Sheet PAGOS
A1: PAGOS
A2: Salidas de caja aplicadas contra movimientos de Gasto/Compra (permite pagos parciales)
A4: ID | B4: Fecha | C4: MovimientoID | D4: Tercero | E4: Cuenta | F4: MedioPago | G4: ValorPagado | H4: Estado | I4: Observaciones

Sheet COBROS
A1: COBROS
A2: Entradas de caja aplicadas contra movimientos de Ingreso/Venta (permite cobros parciales)
A4: ID | B4: Fecha | C4: MovimientoID | D4: Tercero | E4: Cuenta | F4: MedioPago | G4: ValorCobrado | H4: Estado | I4: Observaciones

Sheet CUENTAS
A1: CUENTAS
A2: Cuentas de la empresa - el saldo actual se calcula automaticamente
A4: ID | B4: Cuenta | C4: Tipo | D4: Entidad | E4: NumeroReferencia | F4: SaldoInicial | G4: SaldoActual | H4: Activa | I4: Observaciones
A5: CTA-001 | B5: Caja General | C5: Caja | F5: 0 | G5: =$F5+SUMIFS(MOVIMIENTOS!$O$5:$O$10004,MOVIMIENTOS!$K$5:$K$10004,$B5,MOVIMIENTOS!$C$5:$C$10004,"Ingreso",MOVIMIENTOS!$P$5:$P$10004,"Pagado")+SUMIFS(MOVIMIENTOS!$O$5:$O$10004,MOVIMIENTOS!$K$5:$K$10004,$B5,MOVIMIENTOS!$C$5:$C$10004,"Venta",MOVIMIENTOS!$P$5:$P$10004,"Pagado")-SUMIFS(MOVIMIENTOS!$O$5:$O$10004,MOVIMIENTOS!$K$5:$K$10004,$B5,MOVIMIENTOS!$C$5:$C$10004,"Gasto",MOVIMIENTOS!$P$5:$P$10004,"Pagado")-SUMIFS(MOVIMIENTOS!$O$5:$O$10004,MOVIMIENTOS!$K$5:$K$10004,$B5,MOVIMIENTOS!$C$5:$C$10004,"Compra",MOVIMIENTOS!$P$5:$P$10004,"Pagado") -> 0 | H5: Si
A6: CTA-002 | B6: Banco Principal | C6: Banco | D6: Configurar entidad | F6: 0 | G6: =$F6+SUMIFS(MOVIMIENTOS!$O$5:$O$10004,MOVIMIENTOS!$K$5:$K$10004,$B6,MOVIMIENTOS!$C$5:$C$10004,"Ingreso",MOVIMIENTOS!$P$5:$P$10004,"Pagado")+SUMIFS(MOVIMIENTOS!$O$5:$O$10004,MOVIMIENTOS!$K$5:$K$10004,$B6,MOVIMIENTOS!$C$5:$C$10004,"Venta",MOVIMIENTOS!$P$5:$P$10004,"Pagado")-SUMIFS(MOVIMIENTOS!$O$5:$O$10004,MOVIMIENTOS!$K$5:$K$10004,$B6,MOVIMIENTOS!$C$5:$C$10004,"Gasto",MOVIMIENTOS!$P$5:$P$10004,"Pagado")-SUMIFS(MOVIMIENTOS!$O$5:$O$10004,MOVIMIENTOS!$K$5:$K$10004,$B6,MOVIMIENTOS!$C$5:$C$10004,"Compra",MOVIMIENTOS!$P$5:$P$10004,"Pagado") -> 0 | H6: Si
A7: CTA-003 | B7: Cuentas por Cobrar | C7: Cuenta por cobrar | F7: 0 | G7: =$F7+SUMIFS(MOVIMIENTOS!$O$5:$O$10004,MOVIMIENTOS!$K$5:$K$10004,$B7,MOVIMIENTOS!$C$5:$C$10004,"Ingreso",MOVIMIENTOS!$P$5:$P$10004,"Pagado")+SUMIFS(MOVIMIENTOS!$O$5:$O$10004,MOVIMIENTOS!$K$5:$K$10004,$B7,MOVIMIENTOS!$C$5:$C$10004,"Venta",MOVIMIENTOS!$P$5:$P$10004,"Pagado")-SUMIFS(MOVIMIENTOS!$O$5:$O$10004,MOVIMIENTOS!$K$5:$K$10004,$B7,MOVIMIENTOS!$C$5:$C$10004,"Gasto",MOVIMIENTOS!$P$5:$P$10004,"Pagado")-SUMIFS(MOVIMIENTOS!$O$5:$O$10004,MOVIMIENTOS!$K$5:$K$10004,$B7,MOVIMIENTOS!$C$5:$C$10004,"Compra",MOVIMIENTOS!$P$5:$P$10004,"Pagado") -> 0 | H7: Si
A8: CTA-004 | B8: Cuentas por Pagar | C8: Cuenta por pagar | F8: 0 | G8: =$F8+SUMIFS(MOVIMIENTOS!$O$5:$O$10004,MOVIMIENTOS!$K$5:$K$10004,$B8,MOVIMIENTOS!$C$5:$C$10004,"Ingreso",MOVIMIENTOS!$P$5:$P$10004,"Pagado")+SUMIFS(MOVIMIENTOS!$O$5:$O$10004,MOVIMIENTOS!$K$5:$K$10004,$B8,MOVIMIENTOS!$C$5:$C$10004,"Venta",MOVIMIENTOS!$P$5:$P$10004,"Pagado")-SUMIFS(MOVIMIENTOS!$O$5:$O$10004,MOVIMIENTOS!$K$5:$K$10004,$B8,MOVIMIENTOS!$C$5:$C$10004,"Gasto",MOVIMIENTOS!$P$5:$P$10004,"Pagado")-SUMIFS(MOVIMIENTOS!$O$5:$O$10004,MOVIMIENTOS!$K$5:$K$10004,$B8,MOVIMIENTOS!$C$5:$C$10004,"Compra",MOVIMIENTOS!$P$5:$P$10004,"Pagado") -> 0 | H8: Si

Sheet ASISTENTE
A1: ASISTENTE LOCAL
A2: Sugerencias por reglas editables; revise cada resultado antes de registrarlo
A4: DATOS DE LA OPERACIÓN
A5: Tercero o proveedor
A6: Concepto o descripción
A8: SUGERENCIA
A9: Estado | B9: =IF($B$6="","Escriba un concepto",IF(MAX('REGLAS_IA'!$K$5:$K$104)=0,"Sin coincidencia",IF(COUNTIF('REGLAS_IA'!$K$5:$K$104,MAX('REGLAS_IA'!$K$5:$K$104))>1,"Conflicto: ajuste prioridad","Sugerencia lista para revisar"))) -> Escriba un concepto
A10: Tipo | B10: =IF($B$9<>"Sugerencia lista para revisar","",IFERROR(INDEX('REGLAS_IA'!$D$5:$D$104,MATCH(MAX('REGLAS_IA'!$K$5:$K$104),'REGLAS_IA'!$K$5:$K$104,0)),""))
A11: Categoría | B11: =IF($B$9<>"Sugerencia lista para revisar","",IFERROR(INDEX('REGLAS_IA'!$E$5:$E$104,MATCH(MAX('REGLAS_IA'!$K$5:$K$104),'REGLAS_IA'!$K$5:$K$104,0)),""))
A12: Subcategoría | B12: =IF($B$9<>"Sugerencia lista para revisar","",IFERROR(INDEX('REGLAS_IA'!$F$5:$F$104,MATCH(MAX('REGLAS_IA'!$K$5:$K$104),'REGLAS_IA'!$K$5:$K$104,0)),""))
A13: Medio de pago | B13: =IF($B$9<>"Sugerencia lista para revisar","",IFERROR(INDEX('REGLAS_IA'!$G$5:$G$104,MATCH(MAX('REGLAS_IA'!$K$5:$K$104),'REGLAS_IA'!$K$5:$K$104,0)),""))
A14: Cuenta | B14: =IF($B$9<>"Sugerencia lista para revisar","",IFERROR(INDEX('REGLAS_IA'!$H$5:$H$104,MATCH(MAX('REGLAS_IA'!$K$5:$K$104),'REGLAS_IA'!$K$5:$K$104,0)),""))
A15: Regla coincidente | B15: =IF($B$9<>"Sugerencia lista para revisar","",IFERROR(INDEX('REGLAS_IA'!$C$5:$C$104,MATCH(MAX('REGLAS_IA'!$K$5:$K$104),'REGLAS_IA'!$K$5:$K$104,0)),""))
A16: Prioridad de regla | B16: =IF($B$9<>"Sugerencia lista para revisar","",IFERROR(INDEX('REGLAS_IA'!$J$5:$J$104,MATCH(MAX('REGLAS_IA'!$K$5:$K$104),'REGLAS_IA'!$K$5:$K$104,0)),""))
A18: CÓMO USARLO
A19: 1. Escriba el tercero y el concepto. El tercero es opcional.
A20: 2. Revise la regla, el tipo y la categoría sugeridos.
A21: 3. Confirme los datos y regístrelos en MOVIMIENTOS.
A23: Funciona sin internet ni servicios pagos. La prioridad ordena reglas, no es una probabilidad de acierto. No calcula impuestos ni registra datos automáticamente.
A26: Editar las reglas y crear patrones propios
A27: Volver al inicio

Sheet REGLAS_IA
A1: REGLAS DEL ASISTENTE
A2: Catálogo editable de patrones; agregue reglas aprobadas por su empresa
A3: Las reglas solo proponen clasificación. Prioridad mayor gana; si hay empate, el asistente muestra conflicto. Ajuste palabras y prioridad según sus operaciones.
A4: ID | B4: Activa | C4: PalabraClave | D4: Tipo | E4: Categoria | F4: Subcategoria | G4: MedioPago | H4: Cuenta | I4: TerceroOpcional | J4: Prioridad | K4: Coincidencia | L4: Observaciones
A5: IA-001 | B5: Sí | C5: arriendo | D5: Gasto | E5: Administracion | F5: Arriendo | J5: 20 | K5: =IF(OR(B5<>"Sí",C5="",ASISTENTE!$B$6=""),0,IFERROR(IF(AND(OR(I5="",ISNUMBER(SEARCH(I5,ASISTENTE!$B$5))),ISNUMBER(SEARCH(C5,ASISTENTE!$B$5&" "&ASISTENTE!$B$6))),J5,0),0)) -> 0 | L5: Ejemplo editable
A6: IA-002 | B6: Sí | C6: servicios publicos | D6: Gasto | E6: Operacion | F6: Servicios publicos | J6: 20 | K6: =IF(OR(B6<>"Sí",C6="",ASISTENTE!$B$6=""),0,IFERROR(IF(AND(OR(I6="",ISNUMBER(SEARCH(I6,ASISTENTE!$B$5))),ISNUMBER(SEARCH(C6,ASISTENTE!$B$5&" "&ASISTENTE!$B$6))),J6,0),0)) -> 0 | L6: Ejemplo sin tilde
A7: IA-003 | B7: Sí | C7: servicios públicos | D7: Gasto | E7: Operacion | F7: Servicios publicos | J7: 20 | K7: =IF(OR(B7<>"Sí",C7="",ASISTENTE!$B$6=""),0,IFERROR(IF(AND(OR(I7="",ISNUMBER(SEARCH(I7,ASISTENTE!$B$5))),ISNUMBER(SEARCH(C7,ASISTENTE!$B$5&" "&ASISTENTE!$B$6))),J7,0),0)) -> 0 | L7: Variante con tilde
A8: IA-004 | B8: Sí | C8: suministros | D8: Gasto | E8: Operacion | F8: Suministros | J8: 20 | K8: =IF(OR(B8<>"Sí",C8="",ASISTENTE!$B$6=""),0,IFERROR(IF(AND(OR(I8="",ISNUMBER(SEARCH(I8,ASISTENTE!$B$5))),ISNUMBER(SEARCH(C8,ASISTENTE!$B$5&" "&ASISTENTE!$B$6))),J8,0),0)) -> 0 | L8: Ejemplo editable
A9: IA-005 | B9: Sí | C9: software | D9: Gasto | E9: Administracion | F9: Software | J9: 20 | K9: =IF(OR(B9<>"Sí",C9="",ASISTENTE!$B$6=""),0,IFERROR(IF(AND(OR(I9="",ISNUMBER(SEARCH(I9,ASISTENTE!$B$5))),ISNUMBER(SEARCH(C9,ASISTENTE!$B$5&" "&ASISTENTE!$B$6))),J9,0),0)) -> 0 | L9: Ejemplo editable
A10: IA-006 | B10: Sí | C10: nomina | D10: Gasto | E10: Nomina | F10: Salarios | J10: 20 | K10: =IF(OR(B10<>"Sí",C10="",ASISTENTE!$B$6=""),0,IFERROR(IF(AND(OR(I10="",ISNUMBER(SEARCH(I10,ASISTENTE!$B$5))),ISNUMBER(SEARCH(C10,ASISTENTE!$B$5&" "&ASISTENTE!$B$6))),J10,0),0)) -> 0 | L10: Ejemplo sin tilde
A11: IA-007 | B11: Sí | C11: nómina | D11: Gasto | E11: Nomina | F11: Salarios | J11: 20 | K11: =IF(OR(B11<>"Sí",C11="",ASISTENTE!$B$6=""),0,IFERROR(IF(AND(OR(I11="",ISNUMBER(SEARCH(I11,ASISTENTE!$B$5))),ISNUMBER(SEARCH(C11,ASISTENTE!$B$5&" "&ASISTENTE!$B$6))),J11,0),0)) -> 0 | L11: Variante con tilde
A12: IA-008 | B12: Sí | C12: venta de productos | D12: Ingreso | E12: Ventas | F12: Productos | J12: 30 | K12: =IF(OR(B12<>"Sí",C12="",ASISTENTE!$B$6=""),0,IFERROR(IF(AND(OR(I12="",ISNUMBER(SEARCH(I12,ASISTENTE!$B$5))),ISNUMBER(SEARCH(C12,ASISTENTE!$B$5&" "&ASISTENTE!$B$6))),J12,0),0)) -> 0 | L12: Frase específica
A13: IA-009 | B13: Sí | C13: venta productos | D13: Ingreso | E13: Ventas | F13: Productos | J13: 25 | K13: =IF(OR(B13<>"Sí",C13="",ASISTENTE!$B$6=""),0,IFERROR(IF(AND(OR(I13="",ISNUMBER(SEARCH(I13,ASISTENTE!$B$5))),ISNUMBER(SEARCH(C13,ASISTENTE!$B$5&" "&ASISTENTE!$B$6))),J13,0),0)) -> 0 | L13: Frase breve
A14: IA-010 | B14: Sí | C14: venta de servicios | D14: Ingreso | E14: Ventas | F14: Servicios | J14: 30 | K14: =IF(OR(B14<>"Sí",C14="",ASISTENTE!$B$6=""),0,IFERROR(IF(AND(OR(I14="",ISNUMBER(SEARCH(I14,ASISTENTE!$B$5))),ISNUMBER(SEARCH(C14,ASISTENTE!$B$5&" "&ASISTENTE!$B$6))),J14,0),0)) -> 0 | L14: Frase específica
A15: IA-011 | B15: Sí | C15: venta servicios | D15: Ingreso | E15: Ventas | F15: Servicios | J15: 25 | K15: =IF(OR(B15<>"Sí",C15="",ASISTENTE!$B$6=""),0,IFERROR(IF(AND(OR(I15="",ISNUMBER(SEARCH(I15,ASISTENTE!$B$5))),ISNUMBER(SEARCH(C15,ASISTENTE!$B$5&" "&ASISTENTE!$B$6))),J15,0),0)) -> 0 | L15: Frase breve
A16: IA-012 | B16: Sí | C16: rendimientos | D16: Ingreso | E16: Financiero | F16: Rendimientos | J16: 20 | K16: =IF(OR(B16<>"Sí",C16="",ASISTENTE!$B$6=""),0,IFERROR(IF(AND(OR(I16="",ISNUMBER(SEARCH(I16,ASISTENTE!$B$5))),ISNUMBER(SEARCH(C16,ASISTENTE!$B$5&" "&ASISTENTE!$B$6))),J16,0),0)) -> 0 | L16: Ejemplo editable
... A20: IA-016 | B20: Sí | C20: tecnología | D20: Compra | E20: Activos | F20: Tecnologia | J20: 20 | K20: =IF(OR(B20<>"Sí",C20="",ASISTENTE!$B$6=""),0,IFERROR(IF(AND(OR(I20="",ISNUMBER(SEARCH(I20,ASISTENTE!$B$5))),ISNUMBER(SEARCH(C20,ASISTENTE!$B$5&" "&ASISTENTE!$B$6))),J20,0),0)) -> 0 | L20: Variante con tilde
K21: =IF(OR(B21<>"Sí",C21="",ASISTENTE!$B$6=""),0,IFERROR(IF(AND(OR(I21="",ISNUMBER(SEARCH(I21,ASISTENTE!$B$5))),ISNUMBER(SEARCH(C21,ASISTENTE!$B$5&" "&ASISTENTE!$B$6))),J21,0),0)) -> 0
K22: =IF(OR(B22<>"Sí",C22="",ASISTENTE!$B$6=""),0,IFERROR(IF(AND(OR(I22="",ISNUMBER(SEARCH(I22,ASISTENTE!$B$5))),ISNUMBER(SEARCH(C22,ASISTENTE!$B$5&" "&ASISTENTE!$B$6))),J22,0),0)) -> 0
K23: =IF(OR(B23<>"Sí",C23="",ASISTENTE!$B$6=""),0,IFERROR(IF(AND(OR(I23="",ISNUMBER(SEARCH(I23,ASISTENTE!$B$5))),ISNUMBER(SEARCH(C23,ASISTENTE!$B$5&" "&ASISTENTE!$B$6))),J23,0),0)) -> 0
K24: =IF(OR(B24<>"Sí",C24="",ASISTENTE!$B$6=""),0,IFERROR(IF(AND(OR(I24="",ISNUMBER(SEARCH(I24,ASISTENTE!$B$5))),ISNUMBER(SEARCH(C24,ASISTENTE!$B$5&" "&ASISTENTE!$B$6))),J24,0),0)) -> 0
K25: =IF(OR(B25<>"Sí",C25="",ASISTENTE!$B$6=""),0,IFERROR(IF(AND(OR(I25="",ISNUMBER(SEARCH(I25,ASISTENTE!$B$5))),ISNUMBER(SEARCH(C25,ASISTENTE!$B$5&" "&ASISTENTE!$B$6))),J25,0),0)) -> 0
K26: =IF(OR(B26<>"Sí",C26="",ASISTENTE!$B$6=""),0,IFERROR(IF(AND(OR(I26="",ISNUMBER(SEARCH(I26,ASISTENTE!$B$5))),ISNUMBER(SEARCH(C26,ASISTENTE!$B$5&" "&ASISTENTE!$B$6))),J26,0),0)) -> 0
K27: =IF(OR(B27<>"Sí",C27="",ASISTENTE!$B$6=""),0,IFERROR(IF(AND(OR(I27="",ISNUMBER(SEARCH(I27,ASISTENTE!$B$5))),ISNUMBER(SEARCH(C27,ASISTENTE!$B$5&" "&ASISTENTE!$B$6))),J27,0),0)) -> 0
K28: =IF(OR(B28<>"Sí",C28="",ASISTENTE!$B$6=""),0,IFERROR(IF(AND(OR(I28="",ISNUMBER(SEARCH(I28,ASISTENTE!$B$5))),ISNUMBER(SEARCH(C28,ASISTENTE!$B$5&" "&ASISTENTE!$B$6))),J28,0),0)) -> 0
K29: =IF(OR(B29<>"Sí",C29="",ASISTENTE!$B$6=""),0,IFERROR(IF(AND(OR(I29="",ISNUMBER(SEARCH(I29,ASISTENTE!$B$5))),ISNUMBER(SEARCH(C29,ASISTENTE!$B$5&" "&ASISTENTE!$B$6))),J29,0),0)) -> 0
K30: =IF(OR(B30<>"Sí",C30="",ASISTENTE!$B$6=""),0,IFERROR(IF(AND(OR(I30="",ISNUMBER(SEARCH(I30,ASISTENTE!$B$5))),ISNUMBER(SEARCH(C30,ASISTENTE!$B$5&" "&ASISTENTE!$B$6))),J30,0),0)) -> 0
K31: =IF(OR(B31<>"Sí",C31="",ASISTENTE!$B$6=""),0,IFERROR(IF(AND(OR(I31="",ISNUMBER(SEARCH(I31,ASISTENTE!$B$5))),ISNUMBER(SEARCH(C31,ASISTENTE!$B$5&" "&ASISTENTE!$B$6))),J31,0),0)) -> 0
K32: =IF(OR(B32<>"Sí",C32="",ASISTENTE!$B$6=""),0,IFERROR(IF(AND(OR(I32="",ISNUMBER(SEARCH(I32,ASISTENTE!$B$5))),ISNUMBER(SEARCH(C32,ASISTENTE!$B$5&" "&ASISTENTE!$B$6))),J32,0),0)) -> 0
... K104: =IF(OR(B104<>"Sí",C104="",ASISTENTE!$B$6=""),0,IFERROR(IF(AND(OR(I104="",ISNUMBER(SEARCH(I104,ASISTENTE!$B$5))),ISNUMBER(SEARCH(C104,ASISTENTE!$B$5&" "&ASISTENTE!$B$6))),J104,0),0)) -> 0

Sheet INGRESOS
A1: INGRESOS
A2: Detalle de Ingreso/Venta agrupado por categoria y mes
A3: Año del reporte | B3: 2026
A4: Categoria | B4: Ene | C4: Feb | D4: Mar | E4: Abr | F4: May | G4: Jun | H4: Jul | I4: Ago | J4: Sep | K4: Oct | L4: Nov | M4: Dic | N4: Total
A5: Ventas | B5: =SUMPRODUCT((MOVIMIENTOS!$H$5:$H$10004=$A5)*((MOVIMIENTOS!$C$5:$C$10004="Ingreso")+(MOVIMIENTOS!$C$5:$C$10004="Venta"))*(YEAR(MOVIMIENTOS!$B$5:$B$10004)=$B$3)*(MONTH(MOVIMIENTOS!$B$5:$B$10004)=1)*(MOVIMIENTOS!$P$5:$P$10004="Pagado")*MOVIMIENTOS!$O$5:$O$10004) -> 0 | C5: =SUMPRODUCT((MOVIMIENTOS!$H$5:$H$10004=$A5)*((MOVIMIENTOS!$C$5:$C$10004="Ingreso")+(MOVIMIENTOS!$C$5:$C$10004="Venta"))*(YEAR(MOVIMIENTOS!$B$5:$B$10004)=$B$3)*(MONTH(MOVIMIENTOS!$B$5:$B$10004)=2)*(MOVIMIENTOS!$P$5:$P$10004="Pagado")*MOVIMIENTOS!$O$5:$O$10004) -> 0 | D5: =SUMPRODUCT((MOVIMIENTOS!$H$5:$H$10004=$A5)*((MOVIMIENTOS!$C$5:$C$10004="Ingreso")+(MOVIMIENTOS!$C$5:$C$10004="Venta"))*(YEAR(MOVIMIENTOS!$B$5:$B$10004)=$B$3)*(MONTH(MOVIMIENTOS!$B$5:$B$10004)=3)*(MOVIMIENTOS!$P$5:$P$10004="Pagado")*MOVIMIENTOS!$O$5:$O$10004) -> 0 | E5: =SUMPRODUCT((MOVIMIENTOS!$H$5:$H$10004=$A5)*((MOVIMIENTOS!$C$5:$C$10004="Ingreso")+(MOVIMIENTOS!$C$5:$C$10004="Venta"))*(YEAR(MOVIMIENTOS!$B$5:$B$10004)=$B$3)*(MONTH(MOVIMIENTOS!$B$5:$B$10004)=4)*(MOVIMIENTOS!$P$5:$P$10004="Pagado")*MOVIMIENTOS!$O$5:$O$10004) -> 0 | F5: =SUMPRODUCT((MOVIMIENTOS!$H$5:$H$10004=$A5)*((MOVIMIENTOS!$C$5:$C$10004="Ingreso")+(MOVIMIENTOS!$C$5:$C$10004="Venta"))*(YEAR(MOVIMIENTOS!$B$5:$B$10004)=$B$3)*(MONTH(MOVIMIENTOS!$B$5:$B$10004)=5)*(MOVIMIENTOS!$P$5:$P$10004="Pagado")*MOVIMIENTOS!$O$5:$O$10004) -> 0 | G5: =SUMPRODUCT((MOVIMIENTOS!$H$5:$H$10004=$A5)*((MOVIMIENTOS!$C$5:$C$10004="Ingreso")+(MOVIMIENTOS!$C$5:$C$10004="Venta"))*(YEAR(MOVIMIENTOS!$B$5:$B$10004)=$B$3)*(MONTH(MOVIMIENTOS!$B$5:$B$10004)=6)*(MOVIMIENTOS!$P$5:$P$10004="Pagado")*MOVIMIENTOS!$O$5:$O$10004) -> 0 | H5: =SUMPRODUCT((MOVIMIENTOS!$H$5:$H$10004=$A5)*((MOVIMIENTOS!$C$5:$C$10004="Ingreso")+(MOVIMIENTOS!$C$5:$C$10004="Venta"))*(YEAR(MOVIMIENTOS!$B$5:$B$10004)=$B$3)*(MONTH(MOVIMIENTOS!$B$5:$B$10004)=7)*(MOVIMIENTOS!$P$5:$P$10004="Pagado")*MOVIMIENTOS!$O$5:$O$10004) -> 0 | I5: =SUMPRODUCT((MOVIMIENTOS!$H$5:$H$10004=$A5)*((MOVIMIENTOS!$C$5:$C$10004="Ingreso")+(MOVIMIENTOS!$C$5:$C$10004="Venta"))*(YEAR(MOVIMIENTOS!$B$5:$B$10004)=$B$3)*(MONTH(MOVIMIENTOS!$B$5:$B$10004)=8)*(MOVIMIENTOS!$P$5:$P$10004="Pagado")*MOVIMIENTOS!$O$5:$O$10004) -> 0 | J5: =SUMPRODUCT((MOVIMIENTOS!$H$5:$H$10004=$A5)*((MOVIMIENTOS!$C$5:$C$10004="Ingreso")+(MOVIMIENTOS!$C$5:$C$10004="Venta"))*(YEAR(MOVIMIENTOS!$B$5:$B$10004)=$B$3)*(MONTH(MOVIMIENTOS!$B$5:$B$10004)=9)*(MOVIMIENTOS!$P$5:$P$10004="Pagado")*MOVIMIENTOS!$O$5:$O$10004) -> 0 | K5: =SUMPRODUCT((MOVIMIENTOS!$H$5:$H$10004=$A5)*((MOVIMIENTOS!$C$5:$C$10004="Ingreso")+(MOVIMIENTOS!$C$5:$C$10004="Venta"))*(YEAR(MOVIMIENTOS!$B$5:$B$10004)=$B$3)*(MONTH(MOVIMIENTOS!$B$5:$B$10004)=10)*(MOVIMIENTOS!$P$5:$P$10004="Pagado")*MOVIMIENTOS!$O$5:$O$10004) -> 0 | L5: =SUMPRODUCT((MOVIMIENTOS!$H$5:$H$10004=$A5)*((MOVIMIENTOS!$C$5:$C$10004="Ingreso")+(MOVIMIENTOS!$C$5:$C$10004="Venta"))*(YEAR(MOVIMIENTOS!$B$5:$B$10004)=$B$3)*(MONTH(MOVIMIENTOS!$B$5:$B$10004)=11)*(MOVIMIENTOS!$P$5:$P$10004="Pagado")*MOVIMIENTOS!$O$5:$O$10004) -> 0 | M5: =SUMPRODUCT((MOVIMIENTOS!$H$5:$H$10004=$A5)*((MOVIMIENTOS!$C$5:$C$10004="Ingreso")+(MOVIMIENTOS!$C$5:$C$10004="Venta"))*(YEAR(MOVIMIENTOS!$B$5:$B$10004)=$B$3)*(MONTH(MOVIMIENTOS!$B$5:$B$10004)=12)*(MOVIMIENTOS!$P$5:$P$10004="Pagado")*MOVIMIENTOS!$O$5:$O$10004) -> 0 | N5: =SUM(B5:M5) -> 0
A6: Financiero | B6: =SUMPRODUCT((MOVIMIENTOS!$H$5:$H$10004=$A6)*((MOVIMIENTOS!$C$5:$C$10004="Ingreso")+(MOVIMIENTOS!$C$5:$C$10004="Venta"))*(YEAR(MOVIMIENTOS!$B$5:$B$10004)=$B$3)*(MONTH(MOVIMIENTOS!$B$5:$B$10004)=1)*(MOVIMIENTOS!$P$5:$P$10004="Pagado")*MOVIMIENTOS!$O$5:$O$10004) -> 0 | C6: =SUMPRODUCT((MOVIMIENTOS!$H$5:$H$10004=$A6)*((MOVIMIENTOS!$C$5:$C$10004="Ingreso")+(MOVIMIENTOS!$C$5:$C$10004="Venta"))*(YEAR(MOVIMIENTOS!$B$5:$B$10004)=$B$3)*(MONTH(MOVIMIENTOS!$B$5:$B$10004)=2)*(MOVIMIENTOS!$P$5:$P$10004="Pagado")*MOVIMIENTOS!$O$5:$O$10004) -> 0 | D6: =SUMPRODUCT((MOVIMIENTOS!$H$5:$H$10004=$A6)*((MOVIMIENTOS!$C$5:$C$10004="Ingreso")+(MOVIMIENTOS!$C$5:$C$10004="Venta"))*(YEAR(MOVIMIENTOS!$B$5:$B$10004)=$B$3)*(MONTH(MOVIMIENTOS!$B$5:$B$10004)=3)*(MOVIMIENTOS!$P$5:$P$10004="Pagado")*MOVIMIENTOS!$O$5:$O$10004) -> 0 | E6: =SUMPRODUCT((MOVIMIENTOS!$H$5:$H$10004=$A6)*((MOVIMIENTOS!$C$5:$C$10004="Ingreso")+(MOVIMIENTOS!$C$5:$C$10004="Venta"))*(YEAR(MOVIMIENTOS!$B$5:$B$10004)=$B$3)*(MONTH(MOVIMIENTOS!$B$5:$B$10004)=4)*(MOVIMIENTOS!$P$5:$P$10004="Pagado")*MOVIMIENTOS!$O$5:$O$10004) -> 0 | F6: =SUMPRODUCT((MOVIMIENTOS!$H$5:$H$10004=$A6)*((MOVIMIENTOS!$C$5:$C$10004="Ingreso")+(MOVIMIENTOS!$C$5:$C$10004="Venta"))*(YEAR(MOVIMIENTOS!$B$5:$B$10004)=$B$3)*(MONTH(MOVIMIENTOS!$B$5:$B$10004)=5)*(MOVIMIENTOS!$P$5:$P$10004="Pagado")*MOVIMIENTOS!$O$5:$O$10004) -> 0 | G6: =SUMPRODUCT((MOVIMIENTOS!$H$5:$H$10004=$A6)*((MOVIMIENTOS!$C$5:$C$10004="Ingreso")+(MOVIMIENTOS!$C$5:$C$10004="Venta"))*(YEAR(MOVIMIENTOS!$B$5:$B$10004)=$B$3)*(MONTH(MOVIMIENTOS!$B$5:$B$10004)=6)*(MOVIMIENTOS!$P$5:$P$10004="Pagado")*MOVIMIENTOS!$O$5:$O$10004) -> 0 | H6: =SUMPRODUCT((MOVIMIENTOS!$H$5:$H$10004=$A6)*((MOVIMIENTOS!$C$5:$C$10004="Ingreso")+(MOVIMIENTOS!$C$5:$C$10004="Venta"))*(YEAR(MOVIMIENTOS!$B$5:$B$10004)=$B$3)*(MONTH(MOVIMIENTOS!$B$5:$B$10004)=7)*(MOVIMIENTOS!$P$5:$P$10004="Pagado")*MOVIMIENTOS!$O$5:$O$10004) -> 0 | I6: =SUMPRODUCT((MOVIMIENTOS!$H$5:$H$10004=$A6)*((MOVIMIENTOS!$C$5:$C$10004="Ingreso")+(MOVIMIENTOS!$C$5:$C$10004="Venta"))*(YEAR(MOVIMIENTOS!$B$5:$B$10004)=$B$3)*(MONTH(MOVIMIENTOS!$B$5:$B$10004)=8)*(MOVIMIENTOS!$P$5:$P$10004="Pagado")*MOVIMIENTOS!$O$5:$O$10004) -> 0 | J6: =SUMPRODUCT((MOVIMIENTOS!$H$5:$H$10004=$A6)*((MOVIMIENTOS!$C$5:$C$10004="Ingreso")+(MOVIMIENTOS!$C$5:$C$10004="Venta"))*(YEAR(MOVIMIENTOS!$B$5:$B$10004)=$B$3)*(MONTH(MOVIMIENTOS!$B$5:$B$10004)=9)*(MOVIMIENTOS!$P$5:$P$10004="Pagado")*MOVIMIENTOS!$O$5:$O$10004) -> 0 | K6: =SUMPRODUCT((MOVIMIENTOS!$H$5:$H$10004=$A6)*((MOVIMIENTOS!$C$5:$C$10004="Ingreso")+(MOVIMIENTOS!$C$5:$C$10004="Venta"))*(YEAR(MOVIMIENTOS!$B$5:$B$10004)=$B$3)*(MONTH(MOVIMIENTOS!$B$5:$B$10004)=10)*(MOVIMIENTOS!$P$5:$P$10004="Pagado")*MOVIMIENTOS!$O$5:$O$10004) -> 0 | L6: =SUMPRODUCT((MOVIMIENTOS!$H$5:$H$10004=$A6)*((MOVIMIENTOS!$C$5:$C$10004="Ingreso")+(MOVIMIENTOS!$C$5:$C$10004="Venta"))*(YEAR(MOVIMIENTOS!$B$5:$B$10004)=$B$3)*(MONTH(MOVIMIENTOS!$B$5:$B$10004)=11)*(MOVIMIENTOS!$P$5:$P$10004="Pagado")*MOVIMIENTOS!$O$5:$O$10004) -> 0 | M6: =SUMPRODUCT((MOVIMIENTOS!$H$5:$H$10004=$A6)*((MOVIMIENTOS!$C$5:$C$10004="Ingreso")+(MOVIMIENTOS!$C$5:$C$10004="Venta"))*(YEAR(MOVIMIENTOS!$B$5:$B$10004)=$B$3)*(MONTH(MOVIMIENTOS!$B$5:$B$10004)=12)*(MOVIMIENTOS!$P$5:$P$10004="Pagado")*MOVIMIENTOS!$O$5:$O$10004) -> 0 | N6: =SUM(B6:M6) -> 0
A7: Productos | B7: =SUMPRODUCT((MOVIMIENTOS!$H$5:$H$10004=$A7)*((MOVIMIENTOS!$C$5:$C$10004="Ingreso")+(MOVIMIENTOS!$C$5:$C$10004="Venta"))*(YEAR(MOVIMIENTOS!$B$5:$B$10004)=$B$3)*(MONTH(MOVIMIENTOS!$B$5:$B$10004)=1)*(MOVIMIENTOS!$P$5:$P$10004="Pagado")*MOVIMIENTOS!$O$5:$O$10004) -> 0 | C7: =SUMPRODUCT((MOVIMIENTOS!$H$5:$H$10004=$A7)*((MOVIMIENTOS!$C$5:$C$10004="Ingreso")+(MOVIMIENTOS!$C$5:$C$10004="Venta"))*(YEAR(MOVIMIENTOS!$B$5:$B$10004)=$B$3)*(MONTH(MOVIMIENTOS!$B$5:$B$10004)=2)*(MOVIMIENTOS!$P$5:$P$10004="Pagado")*MOVIMIENTOS!$O$5:$O$10004) -> 0 | D7: =SUMPRODUCT((MOVIMIENTOS!$H$5:$H$10004=$A7)*((MOVIMIENTOS!$C$5:$C$10004="Ingreso")+(MOVIMIENTOS!$C$5:$C$10004="Venta"))*(YEAR(MOVIMIENTOS!$B$5:$B$10004)=$B$3)*(MONTH(MOVIMIENTOS!$B$5:$B$10004)=3)*(MOVIMIENTOS!$P$5:$P$10004="Pagado")*MOVIMIENTOS!$O$5:$O$10004) -> 0 | E7: =SUMPRODUCT((MOVIMIENTOS!$H$5:$H$10004=$A7)*((MOVIMIENTOS!$C$5:$C$10004="Ingreso")+(MOVIMIENTOS!$C$5:$C$10004="Venta"))*(YEAR(MOVIMIENTOS!$B$5:$B$10004)=$B$3)*(MONTH(MOVIMIENTOS!$B$5:$B$10004)=4)*(MOVIMIENTOS!$P$5:$P$10004="Pagado")*MOVIMIENTOS!$O$5:$O$10004) -> 0 | F7: =SUMPRODUCT((MOVIMIENTOS!$H$5:$H$10004=$A7)*((MOVIMIENTOS!$C$5:$C$10004="Ingreso")+(MOVIMIENTOS!$C$5:$C$10004="Venta"))*(YEAR(MOVIMIENTOS!$B$5:$B$10004)=$B$3)*(MONTH(MOVIMIENTOS!$B$5:$B$10004)=5)*(MOVIMIENTOS!$P$5:$P$10004="Pagado")*MOVIMIENTOS!$O$5:$O$10004) -> 0 | G7: =SUMPRODUCT((MOVIMIENTOS!$H$5:$H$10004=$A7)*((MOVIMIENTOS!$C$5:$C$10004="Ingreso")+(MOVIMIENTOS!$C$5:$C$10004="Venta"))*(YEAR(MOVIMIENTOS!$B$5:$B$10004)=$B$3)*(MONTH(MOVIMIENTOS!$B$5:$B$10004)=6)*(MOVIMIENTOS!$P$5:$P$10004="Pagado")*MOVIMIENTOS!$O$5:$O$10004) -> 0 | H7: =SUMPRODUCT((MOVIMIENTOS!$H$5:$H$10004=$A7)*((MOVIMIENTOS!$C$5:$C$10004="Ingreso")+(MOVIMIENTOS!$C$5:$C$10004="Venta"))*(YEAR(MOVIMIENTOS!$B$5:$B$10004)=$B$3)*(MONTH(MOVIMIENTOS!$B$5:$B$10004)=7)*(MOVIMIENTOS!$P$5:$P$10004="Pagado")*MOVIMIENTOS!$O$5:$O$10004) -> 0 | I7: =SUMPRODUCT((MOVIMIENTOS!$H$5:$H$10004=$A7)*((MOVIMIENTOS!$C$5:$C$10004="Ingreso")+(MOVIMIENTOS!$C$5:$C$10004="Venta"))*(YEAR(MOVIMIENTOS!$B$5:$B$10004)=$B$3)*(MONTH(MOVIMIENTOS!$B$5:$B$10004)=8)*(MOVIMIENTOS!$P$5:$P$10004="Pagado")*MOVIMIENTOS!$O$5:$O$10004) -> 0 | J7: =SUMPRODUCT((MOVIMIENTOS!$H$5:$H$10004=$A7)*((MOVIMIENTOS!$C$5:$C$10004="Ingreso")+(MOVIMIENTOS!$C$5:$C$10004="Venta"))*(YEAR(MOVIMIENTOS!$B$5:$B$10004)=$B$3)*(MONTH(MOVIMIENTOS!$B$5:$B$10004)=9)*(MOVIMIENTOS!$P$5:$P$10004="Pagado")*MOVIMIENTOS!$O$5:$O$10004) -> 0 | K7: =SUMPRODUCT((MOVIMIENTOS!$H$5:$H$10004=$A7)*((MOVIMIENTOS!$C$5:$C$10004="Ingreso")+(MOVIMIENTOS!$C$5:$C$10004="Venta"))*(YEAR(MOVIMIENTOS!$B$5:$B$10004)=$B$3)*(MONTH(MOVIMIENTOS!$B$5:$B$10004)=10)*(MOVIMIENTOS!$P$5:$P$10004="Pagado")*MOVIMIENTOS!$O$5:$O$10004) -> 0 | L7: =SUMPRODUCT((MOVIMIENTOS!$H$5:$H$10004=$A7)*((MOVIMIENTOS!$C$5:$C$10004="Ingreso")+(MOVIMIENTOS!$C$5:$C$10004="Venta"))*(YEAR(MOVIMIENTOS!$B$5:$B$10004)=$B$3)*(MONTH(MOVIMIENTOS!$B$5:$B$10004)=11)*(MOVIMIENTOS!$P$5:$P$10004="Pagado")*MOVIMIENTOS!$O$5:$O$10004) -> 0 | M7: =SUMPRODUCT((MOVIMIENTOS!$H$5:$H$10004=$A7)*((MOVIMIENTOS!$C$5:$C$10004="Ingreso")+(MOVIMIENTOS!$C$5:$C$10004="Venta"))*(YEAR(MOVIMIENTOS!$B$5:$B$10004)=$B$3)*(MONTH(MOVIMIENTOS!$B$5:$B$10004)=12)*(MOVIMIENTOS!$P$5:$P$10004="Pagado")*MOVIMIENTOS!$O$5:$O$10004) -> 0 | N7: =SUM(B7:M7) -> 0
A8: TOTAL | B8: =SUM(B5:B7) -> 0 | C8: =SUM(C5:C7) -> 0 | D8: =SUM(D5:D7) -> 0 | E8: =SUM(E5:E7) -> 0 | F8: =SUM(F5:F7) -> 0 | G8: =SUM(G5:G7) -> 0 | H8: =SUM(H5:H7) -> 0 | I8: =SUM(I5:I7) -> 0 | ... N8: =SUM(N5:N7) -> 0

Sheet GASTOS
A1: GASTOS
A2: Detalle de Gasto/Compra agrupado por categoria y mes
A3: Año del reporte | B3: 2026
A4: Categoria | B4: Ene | C4: Feb | D4: Mar | E4: Abr | F4: May | G4: Jun | H4: Jul | I4: Ago | J4: Sep | K4: Oct | L4: Nov | M4: Dic | N4: Total
A5: Operacion | B5: =SUMPRODUCT((MOVIMIENTOS!$H$5:$H$10004=$A5)*((MOVIMIENTOS!$C$5:$C$10004="Gasto")+(MOVIMIENTOS!$C$5:$C$10004="Compra"))*(YEAR(MOVIMIENTOS!$B$5:$B$10004)=$B$3)*(MONTH(MOVIMIENTOS!$B$5:$B$10004)=1)*(MOVIMIENTOS!$P$5:$P$10004="Pagado")*MOVIMIENTOS!$O$5:$O$10004) -> 0 | C5: =SUMPRODUCT((MOVIMIENTOS!$H$5:$H$10004=$A5)*((MOVIMIENTOS!$C$5:$C$10004="Gasto")+(MOVIMIENTOS!$C$5:$C$10004="Compra"))*(YEAR(MOVIMIENTOS!$B$5:$B$10004)=$B$3)*(MONTH(MOVIMIENTOS!$B$5:$B$10004)=2)*(MOVIMIENTOS!$P$5:$P$10004="Pagado")*MOVIMIENTOS!$O$5:$O$10004) -> 0 | D5: =SUMPRODUCT((MOVIMIENTOS!$H$5:$H$10004=$A5)*((MOVIMIENTOS!$C$5:$C$10004="Gasto")+(MOVIMIENTOS!$C$5:$C$10004="Compra"))*(YEAR(MOVIMIENTOS!$B$5:$B$10004)=$B$3)*(MONTH(MOVIMIENTOS!$B$5:$B$10004)=3)*(MOVIMIENTOS!$P$5:$P$10004="Pagado")*MOVIMIENTOS!$O$5:$O$10004) -> 0 | E5: =SUMPRODUCT((MOVIMIENTOS!$H$5:$H$10004=$A5)*((MOVIMIENTOS!$C$5:$C$10004="Gasto")+(MOVIMIENTOS!$C$5:$C$10004="Compra"))*(YEAR(MOVIMIENTOS!$B$5:$B$10004)=$B$3)*(MONTH(MOVIMIENTOS!$B$5:$B$10004)=4)*(MOVIMIENTOS!$P$5:$P$10004="Pagado")*MOVIMIENTOS!$O$5:$O$10004) -> 0 | F5: =SUMPRODUCT((MOVIMIENTOS!$H$5:$H$10004=$A5)*((MOVIMIENTOS!$C$5:$C$10004="Gasto")+(MOVIMIENTOS!$C$5:$C$10004="Compra"))*(YEAR(MOVIMIENTOS!$B$5:$B$10004)=$B$3)*(MONTH(MOVIMIENTOS!$B$5:$B$10004)=5)*(MOVIMIENTOS!$P$5:$P$10004="Pagado")*MOVIMIENTOS!$O$5:$O$10004) -> 0 | G5: =SUMPRODUCT((MOVIMIENTOS!$H$5:$H$10004=$A5)*((MOVIMIENTOS!$C$5:$C$10004="Gasto")+(MOVIMIENTOS!$C$5:$C$10004="Compra"))*(YEAR(MOVIMIENTOS!$B$5:$B$10004)=$B$3)*(MONTH(MOVIMIENTOS!$B$5:$B$10004)=6)*(MOVIMIENTOS!$P$5:$P$10004="Pagado")*MOVIMIENTOS!$O$5:$O$10004) -> 0 | H5: =SUMPRODUCT((MOVIMIENTOS!$H$5:$H$10004=$A5)*((MOVIMIENTOS!$C$5:$C$10004="Gasto")+(MOVIMIENTOS!$C$5:$C$10004="Compra"))*(YEAR(MOVIMIENTOS!$B$5:$B$10004)=$B$3)*(MONTH(MOVIMIENTOS!$B$5:$B$10004)=7)*(MOVIMIENTOS!$P$5:$P$10004="Pagado")*MOVIMIENTOS!$O$5:$O$10004) -> 0 | I5: =SUMPRODUCT((MOVIMIENTOS!$H$5:$H$10004=$A5)*((MOVIMIENTOS!$C$5:$C$10004="Gasto")+(MOVIMIENTOS!$C$5:$C$10004="Compra"))*(YEAR(MOVIMIENTOS!$B$5:$B$10004)=$B$3)*(MONTH(MOVIMIENTOS!$B$5:$B$10004)=8)*(MOVIMIENTOS!$P$5:$P$10004="Pagado")*MOVIMIENTOS!$O$5:$O$10004) -> 0 | J5: =SUMPRODUCT((MOVIMIENTOS!$H$5:$H$10004=$A5)*((MOVIMIENTOS!$C$5:$C$10004="Gasto")+(MOVIMIENTOS!$C$5:$C$10004="Compra"))*(YEAR(MOVIMIENTOS!$B$5:$B$10004)=$B$3)*(MONTH(MOVIMIENTOS!$B$5:$B$10004)=9)*(MOVIMIENTOS!$P$5:$P$10004="Pagado")*MOVIMIENTOS!$O$5:$O$10004) -> 0 | K5: =SUMPRODUCT((MOVIMIENTOS!$H$5:$H$10004=$A5)*((MOVIMIENTOS!$C$5:$C$10004="Gasto")+(MOVIMIENTOS!$C$5:$C$10004="Compra"))*(YEAR(MOVIMIENTOS!$B$5:$B$10004)=$B$3)*(MONTH(MOVIMIENTOS!$B$5:$B$10004)=10)*(MOVIMIENTOS!$P$5:$P$10004="Pagado")*MOVIMIENTOS!$O$5:$O$10004) -> 0 | L5: =SUMPRODUCT((MOVIMIENTOS!$H$5:$H$10004=$A5)*((MOVIMIENTOS!$C$5:$C$10004="Gasto")+(MOVIMIENTOS!$C$5:$C$10004="Compra"))*(YEAR(MOVIMIENTOS!$B$5:$B$10004)=$B$3)*(MONTH(MOVIMIENTOS!$B$5:$B$10004)=11)*(MOVIMIENTOS!$P$5:$P$10004="Pagado")*MOVIMIENTOS!$O$5:$O$10004) -> 0 | M5: =SUMPRODUCT((MOVIMIENTOS!$H$5:$H$10004=$A5)*((MOVIMIENTOS!$C$5:$C$10004="Gasto")+(MOVIMIENTOS!$C$5:$C$10004="Compra"))*(YEAR(MOVIMIENTOS!$B$5:$B$10004)=$B$3)*(MONTH(MOVIMIENTOS!$B$5:$B$10004)=12)*(MOVIMIENTOS!$P$5:$P$10004="Pagado")*MOVIMIENTOS!$O$5:$O$10004) -> 0 | N5: =SUM(B5:M5) -> 0
A6: Administracion | B6: =SUMPRODUCT((MOVIMIENTOS!$H$5:$H$10004=$A6)*((MOVIMIENTOS!$C$5:$C$10004="Gasto")+(MOVIMIENTOS!$C$5:$C$10004="Compra"))*(YEAR(MOVIMIENTOS!$B$5:$B$10004)=$B$3)*(MONTH(MOVIMIENTOS!$B$5:$B$10004)=1)*(MOVIMIENTOS!$P$5:$P$10004="Pagado")*MOVIMIENTOS!$O$5:$O$10004) -> 0 | C6: =SUMPRODUCT((MOVIMIENTOS!$H$5:$H$10004=$A6)*((MOVIMIENTOS!$C$5:$C$10004="Gasto")+(MOVIMIENTOS!$C$5:$C$10004="Compra"))*(YEAR(MOVIMIENTOS!$B$5:$B$10004)=$B$3)*(MONTH(MOVIMIENTOS!$B$5:$B$10004)=2)*(MOVIMIENTOS!$P$5:$P$10004="Pagado")*MOVIMIENTOS!$O$5:$O$10004) -> 0 | D6: =SUMPRODUCT((MOVIMIENTOS!$H$5:$H$10004=$A6)*((MOVIMIENTOS!$C$5:$C$10004="Gasto")+(MOVIMIENTOS!$C$5:$C$10004="Compra"))*(YEAR(MOVIMIENTOS!$B$5:$B$10004)=$B$3)*(MONTH(MOVIMIENTOS!$B$5:$B$10004)=3)*(MOVIMIENTOS!$P$5:$P$10004="Pagado")*MOVIMIENTOS!$O$5:$O$10004) -> 0 | E6: =SUMPRODUCT((MOVIMIENTOS!$H$5:$H$10004=$A6)*((MOVIMIENTOS!$C$5:$C$10004="Gasto")+(MOVIMIENTOS!$C$5:$C$10004="Compra"))*(YEAR(MOVIMIENTOS!$B$5:$B$10004)=$B$3)*(MONTH(MOVIMIENTOS!$B$5:$B$10004)=4)*(MOVIMIENTOS!$P$5:$P$10004="Pagado")*MOVIMIENTOS!$O$5:$O$10004) -> 0 | F6: =SUMPRODUCT((MOVIMIENTOS!$H$5:$H$10004=$A6)*((MOVIMIENTOS!$C$5:$C$10004="Gasto")+(MOVIMIENTOS!$C$5:$C$10004="Compra"))*(YEAR(MOVIMIENTOS!$B$5:$B$10004)=$B$3)*(MONTH(MOVIMIENTOS!$B$5:$B$10004)=5)*(MOVIMIENTOS!$P$5:$P$10004="Pagado")*MOVIMIENTOS!$O$5:$O$10004) -> 0 | G6: =SUMPRODUCT((MOVIMIENTOS!$H$5:$H$10004=$A6)*((MOVIMIENTOS!$C$5:$C$10004="Gasto")+(MOVIMIENTOS!$C$5:$C$10004="Compra"))*(YEAR(MOVIMIENTOS!$B$5:$B$10004)=$B$3)*(MONTH(MOVIMIENTOS!$B$5:$B$10004)=6)*(MOVIMIENTOS!$P$5:$P$10004="Pagado")*MOVIMIENTOS!$O$5:$O$10004) -> 0 | H6: =SUMPRODUCT((MOVIMIENTOS!$H$5:$H$10004=$A6)*((MOVIMIENTOS!$C$5:$C$10004="Gasto")+(MOVIMIENTOS!$C$5:$C$10004="Compra"))*(YEAR(MOVIMIENTOS!$B$5:$B$10004)=$B$3)*(MONTH(MOVIMIENTOS!$B$5:$B$10004)=7)*(MOVIMIENTOS!$P$5:$P$10004="Pagado")*MOVIMIENTOS!$O$5:$O$10004) -> 0 | I6: =SUMPRODUCT((MOVIMIENTOS!$H$5:$H$10004=$A6)*((MOVIMIENTOS!$C$5:$C$10004="Gasto")+(MOVIMIENTOS!$C$5:$C$10004="Compra"))*(YEAR(MOVIMIENTOS!$B$5:$B$10004)=$B$3)*(MONTH(MOVIMIENTOS!$B$5:$B$10004)=8)*(MOVIMIENTOS!$P$5:$P$10004="Pagado")*MOVIMIENTOS!$O$5:$O$10004) -> 0 | J6: =SUMPRODUCT((MOVIMIENTOS!$H$5:$H$10004=$A6)*((MOVIMIENTOS!$C$5:$C$10004="Gasto")+(MOVIMIENTOS!$C$5:$C$10004="Compra"))*(YEAR(MOVIMIENTOS!$B$5:$B$10004)=$B$3)*(MONTH(MOVIMIENTOS!$B$5:$B$10004)=9)*(MOVIMIENTOS!$P$5:$P$10004="Pagado")*MOVIMIENTOS!$O$5:$O$10004) -> 0 | K6: =SUMPRODUCT((MOVIMIENTOS!$H$5:$H$10004=$A6)*((MOVIMIENTOS!$C$5:$C$10004="Gasto")+(MOVIMIENTOS!$C$5:$C$10004="Compra"))*(YEAR(MOVIMIENTOS!$B$5:$B$10004)=$B$3)*(MONTH(MOVIMIENTOS!$B$5:$B$10004)=10)*(MOVIMIENTOS!$P$5:$P$10004="Pagado")*MOVIMIENTOS!$O$5:$O$10004) -> 0 | L6: =SUMPRODUCT((MOVIMIENTOS!$H$5:$H$10004=$A6)*((MOVIMIENTOS!$C$5:$C$10004="Gasto")+(MOVIMIENTOS!$C$5:$C$10004="Compra"))*(YEAR(MOVIMIENTOS!$B$5:$B$10004)=$B$3)*(MONTH(MOVIMIENTOS!$B$5:$B$10004)=11)*(MOVIMIENTOS!$P$5:$P$10004="Pagado")*MOVIMIENTOS!$O$5:$O$10004) -> 0 | M6: =SUMPRODUCT((MOVIMIENTOS!$H$5:$H$10004=$A6)*((MOVIMIENTOS!$C$5:$C$10004="Gasto")+(MOVIMIENTOS!$C$5:$C$10004="Compra"))*(YEAR(MOVIMIENTOS!$B$5:$B$10004)=$B$3)*(MONTH(MOVIMIENTOS!$B$5:$B$10004)=12)*(MOVIMIENTOS!$P$5:$P$10004="Pagado")*MOVIMIENTOS!$O$5:$O$10004) -> 0 | N6: =SUM(B6:M6) -> 0
A7: Nomina | B7: =SUMPRODUCT((MOVIMIENTOS!$H$5:$H$10004=$A7)*((MOVIMIENTOS!$C$5:$C$10004="Gasto")+(MOVIMIENTOS!$C$5:$C$10004="Compra"))*(YEAR(MOVIMIENTOS!$B$5:$B$10004)=$B$3)*(MONTH(MOVIMIENTOS!$B$5:$B$10004)=1)*(MOVIMIENTOS!$P$5:$P$10004="Pagado")*MOVIMIENTOS!$O$5:$O$10004) -> 0 | C7: =SUMPRODUCT((MOVIMIENTOS!$H$5:$H$10004=$A7)*((MOVIMIENTOS!$C$5:$C$10004="Gasto")+(MOVIMIENTOS!$C$5:$C$10004="Compra"))*(YEAR(MOVIMIENTOS!$B$5:$B$10004)=$B$3)*(MONTH(MOVIMIENTOS!$B$5:$B$10004)=2)*(MOVIMIENTOS!$P$5:$P$10004="Pagado")*MOVIMIENTOS!$O$5:$O$10004) -> 0 | D7: =SUMPRODUCT((MOVIMIENTOS!$H$5:$H$10004=$A7)*((MOVIMIENTOS!$C$5:$C$10004="Gasto")+(MOVIMIENTOS!$C$5:$C$10004="Compra"))*(YEAR(MOVIMIENTOS!$B$5:$B$10004)=$B$3)*(MONTH(MOVIMIENTOS!$B$5:$B$10004)=3)*(MOVIMIENTOS!$P$5:$P$10004="Pagado")*MOVIMIENTOS!$O$5:$O$10004) -> 0 | E7: =SUMPRODUCT((MOVIMIENTOS!$H$5:$H$10004=$A7)*((MOVIMIENTOS!$C$5:$C$10004="Gasto")+(MOVIMIENTOS!$C$5:$C$10004="Compra"))*(YEAR(MOVIMIENTOS!$B$5:$B$10004)=$B$3)*(MONTH(MOVIMIENTOS!$B$5:$B$10004)=4)*(MOVIMIENTOS!$P$5:$P$10004="Pagado")*MOVIMIENTOS!$O$5:$O$10004) -> 0 | F7: =SUMPRODUCT((MOVIMIENTOS!$H$5:$H$10004=$A7)*((MOVIMIENTOS!$C$5:$C$10004="Gasto")+(MOVIMIENTOS!$C$5:$C$10004="Compra"))*(YEAR(MOVIMIENTOS!$B$5:$B$10004)=$B$3)*(MONTH(MOVIMIENTOS!$B$5:$B$10004)=5)*(MOVIMIENTOS!$P$5:$P$10004="Pagado")*MOVIMIENTOS!$O$5:$O$10004) -> 0 | G7: =SUMPRODUCT((MOVIMIENTOS!$H$5:$H$10004=$A7)*((MOVIMIENTOS!$C$5:$C$10004="Gasto")+(MOVIMIENTOS!$C$5:$C$10004="Compra"))*(YEAR(MOVIMIENTOS!$B$5:$B$10004)=$B$3)*(MONTH(MOVIMIENTOS!$B$5:$B$10004)=6)*(MOVIMIENTOS!$P$5:$P$10004="Pagado")*MOVIMIENTOS!$O$5:$O$10004) -> 0 | H7: =SUMPRODUCT((MOVIMIENTOS!$H$5:$H$10004=$A7)*((MOVIMIENTOS!$C$5:$C$10004="Gasto")+(MOVIMIENTOS!$C$5:$C$10004="Compra"))*(YEAR(MOVIMIENTOS!$B$5:$B$10004)=$B$3)*(MONTH(MOVIMIENTOS!$B$5:$B$10004)=7)*(MOVIMIENTOS!$P$5:$P$10004="Pagado")*MOVIMIENTOS!$O$5:$O$10004) -> 0 | I7: =SUMPRODUCT((MOVIMIENTOS!$H$5:$H$10004=$A7)*((MOVIMIENTOS!$C$5:$C$10004="Gasto")+(MOVIMIENTOS!$C$5:$C$10004="Compra"))*(YEAR(MOVIMIENTOS!$B$5:$B$10004)=$B$3)*(MONTH(MOVIMIENTOS!$B$5:$B$10004)=8)*(MOVIMIENTOS!$P$5:$P$10004="Pagado")*MOVIMIENTOS!$O$5:$O$10004) -> 0 | J7: =SUMPRODUCT((MOVIMIENTOS!$H$5:$H$10004=$A7)*((MOVIMIENTOS!$C$5:$C$10004="Gasto")+(MOVIMIENTOS!$C$5:$C$10004="Compra"))*(YEAR(MOVIMIENTOS!$B$5:$B$10004)=$B$3)*(MONTH(MOVIMIENTOS!$B$5:$B$10004)=9)*(MOVIMIENTOS!$P$5:$P$10004="Pagado")*MOVIMIENTOS!$O$5:$O$10004) -> 0 | K7: =SUMPRODUCT((MOVIMIENTOS!$H$5:$H$10004=$A7)*((MOVIMIENTOS!$C$5:$C$10004="Gasto")+(MOVIMIENTOS!$C$5:$C$10004="Compra"))*(YEAR(MOVIMIENTOS!$B$5:$B$10004)=$B$3)*(MONTH(MOVIMIENTOS!$B$5:$B$10004)=10)*(MOVIMIENTOS!$P$5:$P$10004="Pagado")*MOVIMIENTOS!$O$5:$O$10004) -> 0 | L7: =SUMPRODUCT((MOVIMIENTOS!$H$5:$H$10004=$A7)*((MOVIMIENTOS!$C$5:$C$10004="Gasto")+(MOVIMIENTOS!$C$5:$C$10004="Compra"))*(YEAR(MOVIMIENTOS!$B$5:$B$10004)=$B$3)*(MONTH(MOVIMIENTOS!$B$5:$B$10004)=11)*(MOVIMIENTOS!$P$5:$P$10004="Pagado")*MOVIMIENTOS!$O$5:$O$10004) -> 0 | M7: =SUMPRODUCT((MOVIMIENTOS!$H$5:$H$10004=$A7)*((MOVIMIENTOS!$C$5:$C$10004="Gasto")+(MOVIMIENTOS!$C$5:$C$10004="Compra"))*(YEAR(MOVIMIENTOS!$B$5:$B$10004)=$B$3)*(MONTH(MOVIMIENTOS!$B$5:$B$10004)=12)*(MOVIMIENTOS!$P$5:$P$10004="Pagado")*MOVIMIENTOS!$O$5:$O$10004) -> 0 | N7: =SUM(B7:M7) -> 0
A8: Inventario | B8: =SUMPRODUCT((MOVIMIENTOS!$H$5:$H$10004=$A8)*((MOVIMIENTOS!$C$5:$C$10004="Gasto")+(MOVIMIENTOS!$C$5:$C$10004="Compra"))*(YEAR(MOVIMIENTOS!$B$5:$B$10004)=$B$3)*(MONTH(MOVIMIENTOS!$B$5:$B$10004)=1)*(MOVIMIENTOS!$P$5:$P$10004="Pagado")*MOVIMIENTOS!$O$5:$O$10004) -> 0 | C8: =SUMPRODUCT((MOVIMIENTOS!$H$5:$H$10004=$A8)*((MOVIMIENTOS!$C$5:$C$10004="Gasto")+(MOVIMIENTOS!$C$5:$C$10004="Compra"))*(YEAR(MOVIMIENTOS!$B$5:$B$10004)=$B$3)*(MONTH(MOVIMIENTOS!$B$5:$B$10004)=2)*(MOVIMIENTOS!$P$5:$P$10004="Pagado")*MOVIMIENTOS!$O$5:$O$10004) -> 0 | D8: =SUMPRODUCT((MOVIMIENTOS!$H$5:$H$10004=$A8)*((MOVIMIENTOS!$C$5:$C$10004="Gasto")+(MOVIMIENTOS!$C$5:$C$10004="Compra"))*(YEAR(MOVIMIENTOS!$B$5:$B$10004)=$B$3)*(MONTH(MOVIMIENTOS!$B$5:$B$10004)=3)*(MOVIMIENTOS!$P$5:$P$10004="Pagado")*MOVIMIENTOS!$O$5:$O$10004) -> 0 | E8: =SUMPRODUCT((MOVIMIENTOS!$H$5:$H$10004=$A8)*((MOVIMIENTOS!$C$5:$C$10004="Gasto")+(MOVIMIENTOS!$C$5:$C$10004="Compra"))*(YEAR(MOVIMIENTOS!$B$5:$B$10004)=$B$3)*(MONTH(MOVIMIENTOS!$B$5:$B$10004)=4)*(MOVIMIENTOS!$P$5:$P$10004="Pagado")*MOVIMIENTOS!$O$5:$O$10004) -> 0 | F8: =SUMPRODUCT((MOVIMIENTOS!$H$5:$H$10004=$A8)*((MOVIMIENTOS!$C$5:$C$10004="Gasto")+(MOVIMIENTOS!$C$5:$C$10004="Compra"))*(YEAR(MOVIMIENTOS!$B$5:$B$10004)=$B$3)*(MONTH(MOVIMIENTOS!$B$5:$B$10004)=5)*(MOVIMIENTOS!$P$5:$P$10004="Pagado")*MOVIMIENTOS!$O$5:$O$10004) -> 0 | G8: =SUMPRODUCT((MOVIMIENTOS!$H$5:$H$10004=$A8)*((MOVIMIENTOS!$C$5:$C$10004="Gasto")+(MOVIMIENTOS!$C$5:$C$10004="Compra"))*(YEAR(MOVIMIENTOS!$B$5:$B$10004)=$B$3)*(MONTH(MOVIMIENTOS!$B$5:$B$10004)=6)*(MOVIMIENTOS!$P$5:$P$10004="Pagado")*MOVIMIENTOS!$O$5:$O$10004) -> 0 | H8: =SUMPRODUCT((MOVIMIENTOS!$H$5:$H$10004=$A8)*((MOVIMIENTOS!$C$5:$C$10004="Gasto")+(MOVIMIENTOS!$C$5:$C$10004="Compra"))*(YEAR(MOVIMIENTOS!$B$5:$B$10004)=$B$3)*(MONTH(MOVIMIENTOS!$B$5:$B$10004)=7)*(MOVIMIENTOS!$P$5:$P$10004="Pagado")*MOVIMIENTOS!$O$5:$O$10004) -> 0 | I8: =SUMPRODUCT((MOVIMIENTOS!$H$5:$H$10004=$A8)*((MOVIMIENTOS!$C$5:$C$10004="Gasto")+(MOVIMIENTOS!$C$5:$C$10004="Compra"))*(YEAR(MOVIMIENTOS!$B$5:$B$10004)=$B$3)*(MONTH(MOVIMIENTOS!$B$5:$B$10004)=8)*(MOVIMIENTOS!$P$5:$P$10004="Pagado")*MOVIMIENTOS!$O$5:$O$10004) -> 0 | J8: =SUMPRODUCT((MOVIMIENTOS!$H$5:$H$10004=$A8)*((MOVIMIENTOS!$C$5:$C$10004="Gasto")+(MOVIMIENTOS!$C$5:$C$10004="Compra"))*(YEAR(MOVIMIENTOS!$B$5:$B$10004)=$B$3)*(MONTH(MOVIMIENTOS!$B$5:$B$10004)=9)*(MOVIMIENTOS!$P$5:$P$10004="Pagado")*MOVIMIENTOS!$O$5:$O$10004) -> 0 | K8: =SUMPRODUCT((MOVIMIENTOS!$H$5:$H$10004=$A8)*((MOVIMIENTOS!$C$5:$C$10004="Gasto")+(MOVIMIENTOS!$C$5:$C$10004="Compra"))*(YEAR(MOVIMIENTOS!$B$5:$B$10004)=$B$3)*(MONTH(MOVIMIENTOS!$B$5:$B$10004)=10)*(MOVIMIENTOS!$P$5:$P$10004="Pagado")*MOVIMIENTOS!$O$5:$O$10004) -> 0 | L8: =SUMPRODUCT((MOVIMIENTOS!$H$5:$H$10004=$A8)*((MOVIMIENTOS!$C$5:$C$10004="Gasto")+(MOVIMIENTOS!$C$5:$C$10004="Compra"))*(YEAR(MOVIMIENTOS!$B$5:$B$10004)=$B$3)*(MONTH(MOVIMIENTOS!$B$5:$B$10004)=11)*(MOVIMIENTOS!$P$5:$P$10004="Pagado")*MOVIMIENTOS!$O$5:$O$10004) -> 0 | M8: =SUMPRODUCT((MOVIMIENTOS!$H$5:$H$10004=$A8)*((MOVIMIENTOS!$C$5:$C$10004="Gasto")+(MOVIMIENTOS!$C$5:$C$10004="Compra"))*(YEAR(MOVIMIENTOS!$B$5:$B$10004)=$B$3)*(MONTH(MOVIMIENTOS!$B$5:$B$10004)=12)*(MOVIMIENTOS!$P$5:$P$10004="Pagado")*MOVIMIENTOS!$O$5:$O$10004) -> 0 | N8: =SUM(B8:M8) -> 0
A9: Activos | B9: =SUMPRODUCT((MOVIMIENTOS!$H$5:$H$10004=$A9)*((MOVIMIENTOS!$C$5:$C$10004="Gasto")+(MOVIMIENTOS!$C$5:$C$10004="Compra"))*(YEAR(MOVIMIENTOS!$B$5:$B$10004)=$B$3)*(MONTH(MOVIMIENTOS!$B$5:$B$10004)=1)*(MOVIMIENTOS!$P$5:$P$10004="Pagado")*MOVIMIENTOS!$O$5:$O$10004) -> 0 | C9: =SUMPRODUCT((MOVIMIENTOS!$H$5:$H$10004=$A9)*((MOVIMIENTOS!$C$5:$C$10004="Gasto")+(MOVIMIENTOS!$C$5:$C$10004="Compra"))*(YEAR(MOVIMIENTOS!$B$5:$B$10004)=$B$3)*(MONTH(MOVIMIENTOS!$B$5:$B$10004)=2)*(MOVIMIENTOS!$P$5:$P$10004="Pagado")*MOVIMIENTOS!$O$5:$O$10004) -> 0 | D9: =SUMPRODUCT((MOVIMIENTOS!$H$5:$H$10004=$A9)*((MOVIMIENTOS!$C$5:$C$10004="Gasto")+(MOVIMIENTOS!$C$5:$C$10004="Compra"))*(YEAR(MOVIMIENTOS!$B$5:$B$10004)=$B$3)*(MONTH(MOVIMIENTOS!$B$5:$B$10004)=3)*(MOVIMIENTOS!$P$5:$P$10004="Pagado")*MOVIMIENTOS!$O$5:$O$10004) -> 0 | E9: =SUMPRODUCT((MOVIMIENTOS!$H$5:$H$10004=$A9)*((MOVIMIENTOS!$C$5:$C$10004="Gasto")+(MOVIMIENTOS!$C$5:$C$10004="Compra"))*(YEAR(MOVIMIENTOS!$B$5:$B$10004)=$B$3)*(MONTH(MOVIMIENTOS!$B$5:$B$10004)=4)*(MOVIMIENTOS!$P$5:$P$10004="Pagado")*MOVIMIENTOS!$O$5:$O$10004) -> 0 | F9: =SUMPRODUCT((MOVIMIENTOS!$H$5:$H$10004=$A9)*((MOVIMIENTOS!$C$5:$C$10004="Gasto")+(MOVIMIENTOS!$C$5:$C$10004="Compra"))*(YEAR(MOVIMIENTOS!$B$5:$B$10004)=$B$3)*(MONTH(MOVIMIENTOS!$B$5:$B$10004)=5)*(MOVIMIENTOS!$P$5:$P$10004="Pagado")*MOVIMIENTOS!$O$5:$O$10004) -> 0 | G9: =SUMPRODUCT((MOVIMIENTOS!$H$5:$H$10004=$A9)*((MOVIMIENTOS!$C$5:$C$10004="Gasto")+(MOVIMIENTOS!$C$5:$C$10004="Compra"))*(YEAR(MOVIMIENTOS!$B$5:$B$10004)=$B$3)*(MONTH(MOVIMIENTOS!$B$5:$B$10004)=6)*(MOVIMIENTOS!$P$5:$P$10004="Pagado")*MOVIMIENTOS!$O$5:$O$10004) -> 0 | H9: =SUMPRODUCT((MOVIMIENTOS!$H$5:$H$10004=$A9)*((MOVIMIENTOS!$C$5:$C$10004="Gasto")+(MOVIMIENTOS!$C$5:$C$10004="Compra"))*(YEAR(MOVIMIENTOS!$B$5:$B$10004)=$B$3)*(MONTH(MOVIMIENTOS!$B$5:$B$10004)=7)*(MOVIMIENTOS!$P$5:$P$10004="Pagado")*MOVIMIENTOS!$O$5:$O$10004) -> 0 | I9: =SUMPRODUCT((MOVIMIENTOS!$H$5:$H$10004=$A9)*((MOVIMIENTOS!$C$5:$C$10004="Gasto")+(MOVIMIENTOS!$C$5:$C$10004="Compra"))*(YEAR(MOVIMIENTOS!$B$5:$B$10004)=$B$3)*(MONTH(MOVIMIENTOS!$B$5:$B$10004)=8)*(MOVIMIENTOS!$P$5:$P$10004="Pagado")*MOVIMIENTOS!$O$5:$O$10004) -> 0 | J9: =SUMPRODUCT((MOVIMIENTOS!$H$5:$H$10004=$A9)*((MOVIMIENTOS!$C$5:$C$10004="Gasto")+(MOVIMIENTOS!$C$5:$C$10004="Compra"))*(YEAR(MOVIMIENTOS!$B$5:$B$10004)=$B$3)*(MONTH(MOVIMIENTOS!$B$5:$B$10004)=9)*(MOVIMIENTOS!$P$5:$P$10004="Pagado")*MOVIMIENTOS!$O$5:$O$10004) -> 0 | K9: =SUMPRODUCT((MOVIMIENTOS!$H$5:$H$10004=$A9)*((MOVIMIENTOS!$C$5:$C$10004="Gasto")+(MOVIMIENTOS!$C$5:$C$10004="Compra"))*(YEAR(MOVIMIENTOS!$B$5:$B$10004)=$B$3)*(MONTH(MOVIMIENTOS!$B$5:$B$10004)=10)*(MOVIMIENTOS!$P$5:$P$10004="Pagado")*MOVIMIENTOS!$O$5:$O$10004) -> 0 | L9: =SUMPRODUCT((MOVIMIENTOS!$H$5:$H$10004=$A9)*((MOVIMIENTOS!$C$5:$C$10004="Gasto")+(MOVIMIENTOS!$C$5:$C$10004="Compra"))*(YEAR(MOVIMIENTOS!$B$5:$B$10004)=$B$3)*(MONTH(MOVIMIENTOS!$B$5:$B$10004)=11)*(MOVIMIENTOS!$P$5:$P$10004="Pagado")*MOVIMIENTOS!$O$5:$O$10004) -> 0 | M9: =SUMPRODUCT((MOVIMIENTOS!$H$5:$H$10004=$A9)*((MOVIMIENTOS!$C$5:$C$10004="Gasto")+(MOVIMIENTOS!$C$5:$C$10004="Compra"))*(YEAR(MOVIMIENTOS!$B$5:$B$10004)=$B$3)*(MONTH(MOVIMIENTOS!$B$5:$B$10004)=12)*(MOVIMIENTOS!$P$5:$P$10004="Pagado")*MOVIMIENTOS!$O$5:$O$10004) -> 0 | N9: =SUM(B9:M9) -> 0
A10: TOTAL | B10: =SUM(B5:B9) -> 0 | C10: =SUM(C5:C9) -> 0 | D10: =SUM(D5:D9) -> 0 | E10: =SUM(E5:E9) -> 0 | F10: =SUM(F5:F9) -> 0 | G10: =SUM(G5:G9) -> 0 | H10: =SUM(H5:H9) -> 0 | I10: =SUM(I5:I9) -> 0 | ... N10: =SUM(N5:N9) -> 0

Sheet FLUJO_CAJA
A1: FLUJO_CAJA
A2: Entradas y salidas de caja por mes (base: PAGOS y COBROS aplicados)
A3: Año del reporte | B3: 2026
A4: Mes | B4: Cobros | C4: Pagos | D4: Flujo Neto Mensual | E4: Flujo Acumulado
A5: Enero | B5: =SUMPRODUCT((YEAR('COBROS'!$B$5:$B$10004)=$B$3)*(MONTH('COBROS'!$B$5:$B$10004)=1)*('COBROS'!$H$5:$H$10004="Aplicado")*'COBROS'!$G$5:$G$10004) -> 0 | C5: =SUMPRODUCT((YEAR(PAGOS!$B$5:$B$10004)=$B$3)*(MONTH(PAGOS!$B$5:$B$10004)=1)*(PAGOS!$H$5:$H$10004="Aplicado")*PAGOS!$G$5:$G$10004) -> 0 | D5: =B5-C5 -> 0 | E5: =D5 -> 0
A6: Febrero | B6: =SUMPRODUCT((YEAR('COBROS'!$B$5:$B$10004)=$B$3)*(MONTH('COBROS'!$B$5:$B$10004)=2)*('COBROS'!$H$5:$H$10004="Aplicado")*'COBROS'!$G$5:$G$10004) -> 0 | C6: =SUMPRODUCT((YEAR(PAGOS!$B$5:$B$10004)=$B$3)*(MONTH(PAGOS!$B$5:$B$10004)=2)*(PAGOS!$H$5:$H$10004="Aplicado")*PAGOS!$G$5:$G$10004) -> 0 | D6: =B6-C6 -> 0 | E6: =E5+D6 -> 0
A7: Marzo | B7: =SUMPRODUCT((YEAR('COBROS'!$B$5:$B$10004)=$B$3)*(MONTH('COBROS'!$B$5:$B$10004)=3)*('COBROS'!$H$5:$H$10004="Aplicado")*'COBROS'!$G$5:$G$10004) -> 0 | C7: =SUMPRODUCT((YEAR(PAGOS!$B$5:$B$10004)=$B$3)*(MONTH(PAGOS!$B$5:$B$10004)=3)*(PAGOS!$H$5:$H$10004="Aplicado")*PAGOS!$G$5:$G$10004) -> 0 | D7: =B7-C7 -> 0 | E7: =E6+D7 -> 0
A8: Abril | B8: =SUMPRODUCT((YEAR('COBROS'!$B$5:$B$10004)=$B$3)*(MONTH('COBROS'!$B$5:$B$10004)=4)*('COBROS'!$H$5:$H$10004="Aplicado")*'COBROS'!$G$5:$G$10004) -> 0 | C8: =SUMPRODUCT((YEAR(PAGOS!$B$5:$B$10004)=$B$3)*(MONTH(PAGOS!$B$5:$B$10004)=4)*(PAGOS!$H$5:$H$10004="Aplicado")*PAGOS!$G$5:$G$10004) -> 0 | D8: =B8-C8 -> 0 | E8: =E7+D8 -> 0
A9: Mayo | B9: =SUMPRODUCT((YEAR('COBROS'!$B$5:$B$10004)=$B$3)*(MONTH('COBROS'!$B$5:$B$10004)=5)*('COBROS'!$H$5:$H$10004="Aplicado")*'COBROS'!$G$5:$G$10004) -> 0 | C9: =SUMPRODUCT((YEAR(PAGOS!$B$5:$B$10004)=$B$3)*(MONTH(PAGOS!$B$5:$B$10004)=5)*(PAGOS!$H$5:$H$10004="Aplicado")*PAGOS!$G$5:$G$10004) -> 0 | D9: =B9-C9 -> 0 | E9: =E8+D9 -> 0
A10: Junio | B10: =SUMPRODUCT((YEAR('COBROS'!$B$5:$B$10004)=$B$3)*(MONTH('COBROS'!$B$5:$B$10004)=6)*('COBROS'!$H$5:$H$10004="Aplicado")*'COBROS'!$G$5:$G$10004) -> 0 | C10: =SUMPRODUCT((YEAR(PAGOS!$B$5:$B$10004)=$B$3)*(MONTH(PAGOS!$B$5:$B$10004)=6)*(PAGOS!$H$5:$H$10004="Aplicado")*PAGOS!$G$5:$G$10004) -> 0 | D10: =B10-C10 -> 0 | E10: =E9+D10 -> 0
A11: Julio | B11: =SUMPRODUCT((YEAR('COBROS'!$B$5:$B$10004)=$B$3)*(MONTH('COBROS'!$B$5:$B$10004)=7)*('COBROS'!$H$5:$H$10004="Aplicado")*'COBROS'!$G$5:$G$10004) -> 0 | C11: =SUMPRODUCT((YEAR(PAGOS!$B$5:$B$10004)=$B$3)*(MONTH(PAGOS!$B$5:$B$10004)=7)*(PAGOS!$H$5:$H$10004="Aplicado")*PAGOS!$G$5:$G$10004) -> 0 | D11: =B11-C11 -> 0 | E11: =E10+D11 -> 0
A12: Agosto | B12: =SUMPRODUCT((YEAR('COBROS'!$B$5:$B$10004)=$B$3)*(MONTH('COBROS'!$B$5:$B$10004)=8)*('COBROS'!$H$5:$H$10004="Aplicado")*'COBROS'!$G$5:$G$10004) -> 0 | C12: =SUMPRODUCT((YEAR(PAGOS!$B$5:$B$10004)=$B$3)*(MONTH(PAGOS!$B$5:$B$10004)=8)*(PAGOS!$H$5:$H$10004="Aplicado")*PAGOS!$G$5:$G$10004) -> 0 | D12: =B12-C12 -> 0 | E12: =E11+D12 -> 0
A13: Septiembre | B13: =SUMPRODUCT((YEAR('COBROS'!$B$5:$B$10004)=$B$3)*(MONTH('COBROS'!$B$5:$B$10004)=9)*('COBROS'!$H$5:$H$10004="Aplicado")*'COBROS'!$G$5:$G$10004) -> 0 | C13: =SUMPRODUCT((YEAR(PAGOS!$B$5:$B$10004)=$B$3)*(MONTH(PAGOS!$B$5:$B$10004)=9)*(PAGOS!$H$5:$H$10004="Aplicado")*PAGOS!$G$5:$G$10004) -> 0 | D13: =B13-C13 -> 0 | E13: =E12+D13 -> 0
A14: Octubre | B14: =SUMPRODUCT((YEAR('COBROS'!$B$5:$B$10004)=$B$3)*(MONTH('COBROS'!$B$5:$B$10004)=10)*('COBROS'!$H$5:$H$10004="Aplicado")*'COBROS'!$G$5:$G$10004) -> 0 | C14: =SUMPRODUCT((YEAR(PAGOS!$B$5:$B$10004)=$B$3)*(MONTH(PAGOS!$B$5:$B$10004)=10)*(PAGOS!$H$5:$H$10004="Aplicado")*PAGOS!$G$5:$G$10004) -> 0 | D14: =B14-C14 -> 0 | E14: =E13+D14 -> 0
A15: Noviembre | B15: =SUMPRODUCT((YEAR('COBROS'!$B$5:$B$10004)=$B$3)*(MONTH('COBROS'!$B$5:$B$10004)=11)*('COBROS'!$H$5:$H$10004="Aplicado")*'COBROS'!$G$5:$G$10004) -> 0 | C15: =SUMPRODUCT((YEAR(PAGOS!$B$5:$B$10004)=$B$3)*(MONTH(PAGOS!$B$5:$B$10004)=11)*(PAGOS!$H$5:$H$10004="Aplicado")*PAGOS!$G$5:$G$10004) -> 0 | D15: =B15-C15 -> 0 | E15: =E14+D15 -> 0
A16: Diciembre | B16: =SUMPRODUCT((YEAR('COBROS'!$B$5:$B$10004)=$B$3)*(MONTH('COBROS'!$B$5:$B$10004)=12)*('COBROS'!$H$5:$H$10004="Aplicado")*'COBROS'!$G$5:$G$10004) -> 0 | C16: =SUMPRODUCT((YEAR(PAGOS!$B$5:$B$10004)=$B$3)*(MONTH(PAGOS!$B$5:$B$10004)=12)*(PAGOS!$H$5:$H$10004="Aplicado")*PAGOS!$G$5:$G$10004) -> 0 | D16: =B16-C16 -> 0 | E16: =E15+D16 -> 0

Sheet CXC
A1: CXC
A2: Movimientos pendientes de cobrar (Ingreso/Venta con Estado=Pendiente)
A4: ID | B4: Fecha | C4: Tercero | D4: Documento | E4: Total | F4: DiasVencido | G4: Estado
A5: Ejecute Menu_ActualizarReportes después de importar los módulos VBA; mientras tanto, filtre MOVIMIENTOS por Estado=Pendiente (Datos > Filtro).

Sheet CXP
A1: CXP
A2: Movimientos pendientes de pagar (Gasto/Compra con Estado=Pendiente)
A4: ID | B4: Fecha | C4: Tercero | D4: Documento | E4: Total | F4: DiasVencido | G4: Estado
A5: Ejecute Menu_ActualizarReportes después de importar los módulos VBA; mientras tanto, filtre MOVIMIENTOS por Estado=Pendiente (Datos > Filtro).

Sheet IMPUESTOS_REPORTE
A1: IMPUESTOS_REPORTE
